Workbook

Sheet Parameters
A1: Parameter | B1: Value | C1: Source
A2: Median Age sample, years | B2: 35 | C2: 7
A3: Risk of TB transmission (cases per year) | B3: 5 | C3: 33
A4: Days of delay in treatment for undiagnosed TB case | B4: 105
A5: Days of delayed treatment in timely delivery of results (Health system delay) | B5: 62
A7: Prevalence
A8: TB among HIV patients, % | B8: 0.101 | C8: 7
A9: Patients affected by HIV only (no TB infection) | B9: =1-B8 -> 0.899 | C9: Calculated
A10: HIV+ patients with CD4 <200 /mm3, % | B10: 0.362 | C10: DREAM data
A11: HIV/TB co-infected patients with CD4<200 /mm3, % | B11: 0.68 | C11: DREAM data
A12: Mortality
A13: In care (early treatment), % | B13: 0.05 | C13: Calculated
A14: Among false negative (delayed treatment), % | B14: 0.2 | C14: Calculated
A15: Disability weights
A16: TB patients | B16: 0.399 | C16: 8
A17: AIDS (in care) | B17: 0.053 | C17: 8
A18: Life Expectancy
A19: Population in Mozambique, years | B19: 57.609 | C19: 12
A20: Survival
A21: HIV+ and TB patient not treated for TB, years | B21: =(0.5+0.83)/2 -> 0.665 | C21: 19
A22: HIV and TB after treatment, years | B22: 12.9 | C22: 10,19-21
A23: HIV and TB not treated for TB | B23: =B2+B21 -> 35.665 | C23: calculated
A26: Costs summary (details on Costs sheet)
A27: Discount rate | B27: 0.03 | C27: assumption
A28: 4SS (per test) | B28: ='Costs details'!B7 -> 4 | C28: Calculated (see "cost details")
A29: SMEAR (per test) | B29: ='Costs details'!B22 -> 3.125 | C29: Calculated (see "cost details")
A30: MTB/RIF (per test) | B30: ='Costs details'!B36 -> 14.717045 | C30: Calculated (see "cost details")
A31: LF-LAM (per test) | B31: ='Costs details'!B43 -> 3.985 | C31: Calculated (see "cost details")
A32: TB therapy | B32: ='Costs details'!B50 -> 9.8441667 | C32: Calculated (see "cost details")
A33: Economic burden of a new TB case due delayed diagnosis and treatment | B33: 847 | C33: 38
A35: Sensitivity and specificity of the screening methods
A36: 4SS Sensitivity | B36: 0.775 | C36: 7
A37: 4SS Specificity | B37: 0.704 | C37: 7
A38: SMEAR Sensitivity | B38: 0.43 | C38: 16
A39: SMEAR Specificity | B39: 1 | C39: 16
A40: GenMTB/RIF Sensitivity | B40: 0.976 | C40: 17
A41: GenXper Specificity | B41: 0.992 | C41: 17
A42: LF-LAM Sensitivity con CD4<200 | B42: 0.49 | C42: 18
A43: LF-LAM Specificity con CD4<200 | B43: 0.9 | C43: 18

Sheet Costs details
A1: Parameter | B1: Value
A2: Discount rate | B2: =Parameters!B27 -> 0.03
A4: 4SS during first visit after HIV test
A5: Hourly cost medical doctor (DREAM) | B5: 16
A6: Number of tests per hour | B6: 4
A7: Total per test | B7: =B5/B6 -> 4
A9: SMEAR
A10: Hourly cost laboratory technician | B10: 6.25
A11: Time needed for one test, hour | B11: 0.25
A12: Total cost laboratory technician (per test) | B12: =B10*B11 -> 1.5625
A13: Microscopy total cost | B13: 1500
A14: Microscopy life span, years | B14: 5
A15: Microscopy (annualized cost) | B15: =($B$2*(1+$B$2)^B14)/((1+$B$2)^B14-1)*B13 -> 327.53186
A16: Microscopy maintenance (total cost entire life)) | B16: =17.54*5 -> 87.7
A17: Microscopy maintenance cost (per year) | B17: =($B$2*(1+$B$2)^B14)/((1+$B$2)^B14-1)*B16 -> 19.149696
A18: Microscopy number of test per day | B18: =8/B11 -> 32
A19: Microscopy number of test per year | B19: =B18*5*52 -> 8320
A20: Cost Microscopy (per test) | B20: =(B15+B17)/B19 -> 0.041668456
A21: Consummables (per test) | B21: 2
A22: Total cost per test | B22: =B12*B21 -> 3.125
A24: MTB/RIF
A25: Hourly cost laboratory technician | B25: 11
A26: Time needed for test, hours | B26: 0.1
A27: Total cost laboratory technician per test | B27: =B25*B26 -> 1.1
A28: GeneMTB/RIF total cost | B28: 17000
A29: GeneMTB/RIF life span, years | B29: 10
A30: GeneMTB/RIF (annualized cost) | B30: =($B$2*(1+$B$2)^B29)/((1+$B$2)^B29-1)*B28 -> 1992.9186
A31: GeneMTB/RIF maintenance cost (per year) | B31: 1800
A32: GeneMTB/RIF number of test per day | B32: 4
A33: GeneMTB/RIF number of test per year | B33: =B32*5*(365/7) -> 1042.8571
A34: Cost GeneMTB/RIF (per test) | B34: =(B30+B31)/B33 -> 3.6370452
A35: Consummables (per test) | B35: 9.98
A36: Tot per test | B36: =B27+B34+B35 -> 14.717045
A38: LF-LAM
A39: Hourly cost nurse | B39: 4.85
A40: Time needed for test, hours | B40: 0.1
A41: Total cost nurse per test | B41: =B39*B40 -> 0.485
A42: Cost for one test (all inclusive) | B42: 3.5
A43: Tot per test | B43: =B42+B41 -> 3.985
A45: TB treatment
...

Sheet Results
C1: Protocols
C2: Standard | D2: MTB/RIF | E2: LF-LAM / MTB/RIF
B3: Sample Size | C3: 1000 | D3: =C3 -> 1000 | E3: =D3 -> 1000
B4: Expected positive | C4: =C3*Parameters!$B8 -> 101 | D4: =D3*Parameters!$B8 -> 101 | E4: =D4 -> 101
B5: Expected negative | C5: =C3-C4 -> 899 | D5: =D3-D4 -> 899
B6: HIV+ patients with CD4 <200 /mm3 | E6: =E3*Parameters!B10 -> 362
B7: Patients undergoing 4SS | C7: 1
A8: 4SS | B8: 4SS Sample | C8: =C3*C7 -> 1000
B9: Expected positive | C9: =C4 -> 101
B10: Expected negative | C10: =C5 -> 899
B11: Posistive | C11: =(Parameters!$B36*C9)+C10*(1-Parameters!$B37) -> 344.379
B12: Negative | C12: =C8-C11 -> 655.621
B13: PPV | C13: =Parameters!$B36*C9/C11 -> 0.22729319
B14: NPV | C14: =(Parameters!B37*C10)/C12 -> 0.96533821
B15: True Positive | C15: =C11*C13 -> 78.275
B16: False Positive | C16: =C11-C15 -> 266.104
B17: True Negative | C17: =C12*C14 -> 632.896
B18: False Negative | C18: =C12-C17 -> 22.725
A19: SMEAR | B19: SMEAR microscopy sample | C19: =C11 -> 344.379
B20: Expected positive | C20: =C15 -> 78.275
B21: Expected negative | C21: =C16 -> 266.104
B22: Posistive | C22: =(Parameters!B38*C20)+C21*(1-Parameters!B39) -> 33.65825
B23: Negative | C23: =C19-C22 -> 310.72075
B24: PPV | C24: =Parameters!B38*C20/C22 -> 1
B25: NPV | C25: =(Parameters!B39*C21)/C23 -> 0.85640885
B26: True Positive | C26: =C22*C24 -> 33.65825
B27: False Positive | C27: =C22-C26 -> 0
B28: True Negative | C28: =C23*C25 -> 266.104
B29: False Negative | C29: =C23-C28 -> 44.61675
A30: MTB/RIF | B30: MTB/RIF Sample | D30: =D3 -> 1000 | E30: =E3-E44 -> 937.0148
B31: Expected positive | D31: =D4 -> 101 | E31: =(E51)+(E4*(1-Parameters!B11)) -> 67.3468
B32: Expected negative | D32: =D5 -> 899 | E32: =E30-E31 -> 869.668
B33: Posistive | D33: =(Parameters!$B40*D31)+D32*(1-Parameters!$B41) -> 105.768 | E33: =(Parameters!$B40*E31)+E32*(1-Parameters!$B41) -> 72.687821
B34: Negative | D34: =D30-D33 -> 894.232 | E34: =E30-E33 -> 864.32698
B35: PPV | D35: =Parameters!$B40*D31/D33 -> 0.93200212 | E35: =Parameters!$B40*E31/E33 -> 0.9042846
B36: NPV | D36: =(Parameters!$B41*D32)/D34 -> 0.99728929 | E36: =(Parameters!$B41*E32)/E34 -> 0.99812996
B37: True Positive | D37: =D33*D35 -> 98.576 | E37: =E33*E35 -> 65.730477
B38: False Positive | D38: =D33-D37 -> 7.192 | E38: =E33-E37 -> 6.957344
B39: True Negative | D39: =D34*D36 -> 891.808 | E39: =E34*E36 -> 862.71066
B40: False Negative | D40: =D34-D39 -> 2.424 | E40: =E34-E39 -> 1.6163232
...

Sheet Sensitivity
L4: =Results!C2 -> Standard | M4: =Results!D2 -> MTB/RIF | N4: =Results!E2 -> LF-LAM / MTB/RIF | O4: ICER
B5: Parametri da testare | C5: Base | D5: Min | E5: Max | K5: Base | L5: =Results!C83 -> 79.059191 | M5: =Results!D83 -> 14.182334 | N5: =Results!E83 -> 15.118677 | O5: =Results!D85 -> 56.53876
B6: =CONCATENATE("Survival for ",Parameters!A21) -> Survival for HIV+ and TB patient not treated for TB, years | C6: =Parameters!B21 -> 0.665 | D6: 0.5 | E6: 2 | F6: FALSE | G6: =IF(F6=TRUE,D6,C6) -> 0.665 | H6: =IF(F6=TRUE,E6,C6) -> 0.665 | K6: Interval | L6: =CONCATENATE(TEXT(L11,"$ #,#0")," - ",TEXT(P11,"$ #,#0")) -> $ 79,06 - $ 79,06 | M6: =CONCATENATE(TEXT(M11,"$ #,#0")," - ",TEXT(Q11,"$ #,#0")) -> $ 14,18 - $ 19,93 | N6: =CONCATENATE(TEXT(N11,"$ #,#0")," - ",TEXT(R11,"$ #,#0")) -> $ 15,12 - $ 20,62 | O6: =CONCATENATE(TEXT(T11,"$ #,#0")," - ",TEXT(U11,"$ #,#0")) -> $ 56,54 - $ 98,83
B7: =Parameters!A3 -> Risk of TB transmission (cases per year) | C7: =Parameters!B3 -> 5 | D7: 2 | E7: 10 | F7: FALSE | G7: =IF(F7=TRUE,D7,C7) -> 5 | H7: =IF(F7=TRUE,E7,C7) -> 5
B8: =CONCATENATE("Prevalence of ",Parameters!A8) -> Prevalence of TB among HIV patients, % | C8: =Parameters!B8 -> 0.101 | D8: =C8-C8*0.5 -> 0.0505 | E8: =C8+C8*0.5 -> 0.1515 | F8: FALSE | G8: =IF(F8=TRUE,D8,C8) -> 0.101 | H8: =IF(F8=TRUE,E8,C8) -> 0.101
B9: =CONCATENATE("Mortality ",Parameters!A13) -> Mortality In care (early treatment), % | C9: =Parameters!B13 -> 0.05 | D9: =C9-C9*0.5 -> 0.025 | E9: =C9+C9*0.5 -> 0.075 | F9: FALSE | G9: =IF(F9=TRUE,D9,C9) -> 0.05 | H9: =IF(F9=TRUE,E9,C9) -> 0.05 | L9: Min | P9: Max
B10: =CONCATENATE("Mortality ",Parameters!A14) -> Mortality Among false negative (delayed treatment), % | C10: =Parameters!B14 -> 0.2 | D10: =C10-C10*0.5 -> 0.1 | E10: =C10+C10*0.5 -> 0.3 | F10: FALSE | G10: =IF(F10=TRUE,D10,C10) -> 0.2 | H10: =IF(F10=TRUE,E10,C10) -> 0.2 | L10: =L4 -> Standard | M10: =M4 -> MTB/RIF | N10: =N4 -> LF-LAM / MTB/RIF | P10: =L10 -> Standard | Q10: =M10 -> MTB/RIF | R10: =N10 -> LF-LAM / MTB/RIF | T10: ICER MIN | U10: ICER MAX
B11: =Parameters!A27 -> Discount rate | C11: =Parameters!B27 -> 0.03 | D11: 1e-08 | E11: =C11*2 -> 0.06 | F11: FALSE | G11: =IF(F11=TRUE,D11,C11) -> 0.03 | H11: =IF(F11=TRUE,E11,C11) -> 0.03 | L11: =[1]Results!$C$83 -> 79.059191 | M11: =[1]Results!$D$83 -> 14.182334 | N11: =[1]Results!$E$83 -> 15.118677 | P11: =[2]Results!$C$83 -> 79.059191 | Q11: =[2]Results!$D$83 -> 19.926692 | R11: =[2]Results!$E$83 -> 20.617117 | T11: =[1]Results!$D$85 -> 56.53876 | U11: =[2]Results!$D$85 -> 98.82912
B12: =CONCATENATE("Survival for ",Parameters!A22) -> Survival for HIV and TB after treatment, years | C12: =Parameters!B22 -> 12.9 | D12: =C12-C12*0.5 -> 6.45 | E12: =C12+C12*0.5 -> 19.35 | F12: FALSE | G12: =IF(F12=TRUE,D12,C12) -> 12.9 | H12: =IF(F12=TRUE,E12,C12) -> 12.9
B13: Cost 4SS | C13: =Parameters!B28 -> 4 | D13: =C13*0.5 -> 2 | E13: =C13*1.5 -> 6 | F13: FALSE | G13: =IF(F13=TRUE,D13,C13) -> 4 | H13: =IF(F13=TRUE,E13,C13) -> 4
B14: =CONCATENATE("Cost ",Parameters!A29) -> Cost SMEAR (per test) | C14: =Parameters!B29 -> 3.125 | D14: =C14*0.5 -> 1.5625 | E14: =C14*1.5 -> 4.6875 | F14: FALSE | G14: =IF(F14=TRUE,D14,C14) -> 3.125 | H14: =IF(F14=TRUE,E14,C14) -> 3.125
B15: =CONCATENATE("Cost ",Parameters!A30) -> Cost MTB/RIF (per test) | C15: =Parameters!B30 -> 14.717045 | D15: =C15*0.5 -> 7.3585226 | E15: =C15*1.5 -> 22.075568 | F15: FALSE | G15: =IF(F15=TRUE,D15,C15) -> 14.717045 | H15: =IF(F15=TRUE,E15,C15) -> 14.717045
B16: =CONCATENATE("Cost ",Parameters!A31) -> Cost LF-LAM (per test) | C16: =Parameters!B31 -> 3.985 | D16: =C16*0.5 -> 1.9925 | E16: =C16*1.5 -> 5.9775 | F16: FALSE | G16: =IF(F16=TRUE,D16,C16) -> 3.985 | H16: =IF(F16=TRUE,E16,C16) -> 3.985
B17: =CONCATENATE("Cost ",Parameters!A32) -> Cost TB therapy | C17: =Parameters!B32 -> 9.8441667 | D17: =C17*0.5 -> 4.9220833 | E17: =C17*1.5 -> 14.76625 | F17: FALSE | G17: =IF(F17=TRUE,D17,C17) -> 9.8441667 | H17: =IF(F17=TRUE,E17,C17) -> 9.8441667
B18: =Parameters!A33 -> Economic burden of a new TB case due delayed diagnosis and treatment | C18: =Parameters!B33 -> 847 | D18: =C18*0.5 -> 423.5 | E18: =C18*1.5 -> 1270.5 | F18: FALSE | G18: =IF(F18=TRUE,D18,C18) -> 847 | H18: =IF(F18=TRUE,E18,C18) -> 847
B19: =Parameters!A4 -> Days of delay in treatment for undiagnosed TB case | C19: =Parameters!B4 -> 105 | D19: =C19*0.5 -> 52.5 | E19: =C19*1.5 -> 157.5 | F19: FALSE | G19: =IF(F19=TRUE,D19,C19) -> 105 | H19: =IF(F19=TRUE,E19,C19) -> 105
B20: =Parameters!A5 -> Days of delayed treatment in timely delivery of results (Health system delay) | C20: =Parameters!B5 -> 62 | D20: =C20*0.5 -> 31 | E20: =C20*1.5 -> 93 | F20: FALSE | G20: =IF(F20=TRUE,D20,C20) -> 62 | H20: =IF(F20=TRUE,E20,C20) -> 62
F24: =L4 -> Standard | G24: =M4 -> MTB/RIF | H24: =N4 -> LF-LAM / MTB/RIF | I24: ICER B vs A
C25: Base | D25: Min | E25: Max | F25: =L5 -> 79.059191 | G25: =M5 -> 14.182334 | H25: =N5 -> 15.118677 | I25: =O5 -> 56.53876 | K25: =L4 -> Standard | L25: =M4 -> MTB/RIF | M25: =N4 -> LF-LAM / MTB/RIF | O25: =K25 -> Standard | P25: =L25 -> MTB/RIF | Q25: =M25 -> LF-LAM / MTB/RIF | S25: ICER | T25: ICER
B26: =B6 -> Survival for HIV+ and TB patient not treated for TB, years | C26: =C6 -> 0.665 | D26: =D6 -> 0.5 | E26: =E6 -> 2 | F26: $ 79,42 - $ 76,04 | G26: $ 14,26 - $ 13,65 | H26: $ 15,19 - $ 14,54 | I26: $ 57,20 - $ 54,65 | K26: 79.417899 | L26: 14.260259 | M26: 15.191362 | O26: 76.036945 | P26: 13.649564 | Q26: 14.538973 | S26: 57.196187 | T26: 54.654134
B27: =B7 -> Risk of TB transmission (cases per year) | C27: =C7 -> 5 | D27: =D7 -> 2 | E27: =E7 -> 10 | F27: $ 34,82 - $ 152,79 | G27: $ 13,04 - $ 16,08 | H27: $ 13,95 - $ 17,06 | I27: $ 56,54 - $ 56,54 | K27: 34.81785 | L27: 13.041081 | M27: 13.952851 | O27: 152.79476 | P27: 16.084422 | Q27: 17.061719 | S27: 56.53876 | T27: 56.53876
B28: =B8 -> Prevalence of TB among HIV patients, % | C28: =C8 -> 0.101 | D28: =D8 -> 0.0505 | E28: =E8 -> 0.1515 | F28: $ 85,61 - $ 78,86 | G28: $ 26,28 - $ 11,04 | H28: $ 28,49 - $ 10,13 | I28: $ 123,18 - $ 36,82 | K28: 85.605089 | L28: 26.278727 | M28: 28.492907 | O28: 78.860246 | P28: 11.041311 | Q28: 10.134564 | S28: 123.17839 | T28: 36.820454
B29: =B9 -> Mortality In care (early treatment), % | C29: =C9 -> 0.05 | D29: =D9 -> 0.025 | E29: =E9 -> 0.075 | F29: $ 77,19 - $ 82,0 | G29: $ 13,92 - $ 14,62 | H29: $ 14,54 - $ 15,59 | I29: $ 56,87 - $ 56,54 | K29: 77.194191 | L29: 13.91527 | M29: 14.535728 | O29: 81.995306 | P29: 14.615663 | Q29: 15.592494 | S29: 56.865573 | T29: 56.53876
B30: =B10 -> Mortality Among false negative (delayed treatment), % | C30: =C10 -> 0.2 | D30: =D10 -> 0.1 | E30: =E10 -> 0.3 | F30: $ 73,78 - $ 86,24 | G30: $ 14,18 - $ 14,33 | H30: $ 15,12 - $ 15,27 | I30: $ 104,03 - $ 39,12 | K30: 73.780614 | L30: 14.182334 | M30: 15.118677 | O30: 86.242224 | P30: 14.331275 | Q30: 15.269119 | S30: 104.0285 | T30: 39.117823
B31: =B11 -> Discount rate | C31: =C11 -> 0.03 | D31: =D11 -> 1e-08 | E31: =E11 -> 0.06 | F31: $ 66,40 - $ 93,01 | G31: $ 11,91 - $ 16,68 | H31: $ 12,70 - $ 17,79 | I31: $ 47,53 - $ 66,47 | K31: 66.402522 | L31: 11.91316 | M31: 12.698473 | O31: 93.005871 | P31: 16.682801 | Q31: 17.78501 | S31: 47.525334 | T31: 66.471245
B32: =B12 -> Survival for HIV and TB after treatment, years | C32: =C12 -> 12.9 | D32: =D12 -> 6.45 | E32: =E12 -> 19.35 | F32: $ 66,40 - $ 93,01 | G32: $ 11,91 - $ 16,68 | H32: $ 12,70 - $ 17,79 | I32: $ 47,53 - $ 66,47 | K32: 66.402522 | L32: 11.91316 | M32: 12.698473 | O32: 93.005871 | P32: 16.682801 | Q32: 17.78501 | S32: 47.525334 | T32: 66.471245
B33: =B13 -> Cost 4SS | C33: =C13 -> 4 | D33: =D13 -> 2 | E33: =E13 -> 6 | F33: $ 134,64 - $ 60,73 | G33: $ 24,19 - $ 10,90 | H33: $ 25,76 - $ 11,62 | I33: $ 97,40 - $ 43,53 | K33: 134.64388 | L33: 24.191171 | M33: 25.759267 | O33: 60.734576 | P33: 10.898362 | Q33: 11.616924 | S33: 97.403408 | T33: 43.529842
B34: =B14 -> Cost SMEAR (per test) | C34: =C14 -> 3.125 | D34: =D14 -> 1.5625 | E34: =E14 -> 4.6875 | F34: $ 77,25 - $ 80,87 | G34: $ 14,18 - $ 14,18 | H34: $ 15,12 - $ 15,12 | I34: $ 68,03 - $ 45,04 | K34: 77.252506 | L34: 14.182334 | M34: 15.118677 | O34: 80.865876 | P34: 14.182334 | Q34: 15.118677 | S34: 68.033013 | T34: 45.044507
B35: =B15 -> Cost MTB/RIF (per test) | C35: =C15 -> 14.717045 | D35: =D15 -> 7.3585226 | E35: =E15 -> 22.075568 | F35: $ 79,06 - $ 79,06 | G35: $ 8,44 - $ 19,93 | H35: $ 9,62 - $ 20,62 | I35: $ 14,25 - $ 98,83 | K35: 79.059191 | L35: 8.4379759 | M35: 9.6202359 | O35: 79.059191 | P35: 19.926692 | Q35: 20.617117 | S35: 14.2484 | T35: 98.82912
B36: =B16 -> Cost LF-LAM (per test) | C36: =C16 -> 3.985 | D36: =D16 -> 1.9925 | E36: =E16 -> 5.9775 | F36: $ 79,06 - $ 79,06 | G36: $ 14,18 - $ 14,18 | H36: $ 14,54 - $ 15,69 | I36: $ 56,54 - $ 56,54 | K36: 79.059191 | L36: 14.182334 | M36: 14.543489 | O36: 79.059191 | P36: 14.182334 | Q36: 15.693864 | S36: 56.53876 | T36: 56.53876
B37: =B17 -> Cost TB therapy | C37: =C17 -> 9.8441667 | D37: =D17 -> 4.9220833 | E37: =E17 -> 14.76625 | F37: $ 78,69 - $ 79,43 | G37: $ 13,79 - $ 14,58 | H37: $ 14,60 - $ 15,63 | I37: $ 55,97 - $ 57,10 | K37: 78.690146 | L37: 13.786569 | M37: 14.604488 | O37: 79.428236 | P37: 14.578099 | Q37: 15.632865 | S37: 55.973003 | T37: 57.104516
... B39: =B19 -> Days of delay in treatment for undiagnosed TB case | C39: =C19 -> 105 | D39: =D19 -> 52.5 | E39: =E19 -> 157.5 | F39: $ 42,19 - $ 115,93 | G39: $ 13,23 - $ 15,13 | H39: $ 14,15 - $ 16,09 | I39: $ 56,54 - $ 56,54 | K39: 42.191407 | L39: 13.23129 | M39: 14.147155 | O39: 115.92697 | P39: 15.133378 | Q39: 16.090198 | S39: 56.53876 | T39: 56.53876

Sheet figure
A1: Tabella 5- Total costs
A7: Diagnosis and treatment | B7: 5893.2502 | C7: 15730.994 | D7: 16522.245
A8: Delayed therapy | B8: 81625.274 | C8: 2436.5753 | D8: 2436.5753
A9: Health system delay | B9: 59707.699 | C9: 74095.096 | D9: 94237.452

Sheet Tornado
G1: Protocol A (Traditional) | H1: Protocol B (GenXpert) | I1: Protocol C (LAM + GenXpert)
A2: Parametri da testare | B2: min | C2: max: rosso
A7: Cost per DALY
A8: Mortality in care (early treatment) | B8: 13.92 | C8: 14.62
A9: Mortality among false negatives (delayed treatment) | B9: 14.18 | C9: 14.33
A10: Survival of HIV/TB patient not treated for TB | B10: 14.26 | C10: 13.65
A11: Cost TB Therapy | B11: 13.79 | C11: 14.58
A12: Days of delay in treatment for undiagnosed TB case | B12: 13.23 | C12: 15.13
A13: Cost of newly trasmitted TB infection | B13: 13.23 | C13: 15.13
A14: Risk of trasmission of TB (cases per year) | B14: 13.04 | C14: 16.08
A15: Discount rate | B15: 11.91 | C15: 16.68
A16: Cost MTB/RIF | B16: 8.44 | C16: 19.93
A17: Survival of HIV/TB patient post-treatment | B17: 11.91 | C17: 16.68
A18: Cost 4SS | B18: 24.19 | C18: 10.9
A19: Prevalence of TB in HIV+ patients | B19: 26.28 | C19: 11.04
A22: Base case | B22: 14.18
A24: ICER
A26: Survival of HIV/TB patient not treated for TB | B26: 57.2 | C26: 54.65
A27: Cost 4SS | B27: 97.4 | C27: 43.53
A28: Mortality among false negatives (delayed treatment) | B28: 104.03 | C28: 39.12
A29: Survival of HIV/TB patient post-treatment | B29: 47.53 | C29: 66.47
A30: Discount rate | B30: 47.53 | C30: 66.47
A31: Cost SMEAR | B31: 68.03 | C31: 45.04
A32: Cost MTB/RIF | B32: 14.25 | C32: 98.83
A33: Prevalence of TB in HIV+ patients | B33: 123.17839 | C33: 36.820454
A36: Base case | B36: 56.54
