Workbook

Sheet PB_&_MAR 30
A1: Reference height MA15_11: | F1: 1649.478 | K1: Foto | L1: 434.3
A2: Pitch Blade 15 minutes + Marine Impeller 30 minutes | K2: realiteit | L2: 1500
A3: Tests 1, 2 and 3
E4: 8321051 | F4: =E4*1300/2076*10^(-4)-$L$1+$L$2 -> 1586.7677 | K4: 8168054 | L4: =K4*1300/2076*10^(-4)-$L$1+$L$2 -> 1577.187 | Q4: 7852682 | R4: =Q4*1300/2076*10^(-4)-$L$1+$L$2 -> 1557.4383 | W4: 8497852 | X4: =W4*1300/2076*10^(-4)-$L$1+$L$2 -> 1597.8391 | AC4: 7941049 | AD4: =AC4*1300/2076*10^(-4)-$L$1+$L$2 -> 1562.9719 | AI4: 8332298 | AJ4: =AI4*1300/2076*10^(-4)-$L$1+$L$2 -> 1587.472 | AO4: 8566222 | AP4: =AO4*1300/2076*10^(-4)-$L$1+$L$2 -> 1602.1205 | AU4: 8680720 | AV4: =AU4*1300/2076*10^(-4)-$L$1+$L$2 -> 1609.2904 | BA4: 8278075 | BB4: =BA4*1300/2076*10^(-4)-$L$1+$L$2 -> 1584.0766 | BG4: 8388458 | BH4: =BG4*1300/2076*10^(-4)-$L$1+$L$2 -> 1590.9888 | BM4: 8454047 | BN4: =BM4*1300/2076*10^(-4)-$L$1+$L$2 -> 1595.096 | BS4: 8411617 | BT4: =BS4*1300/2076*10^(-4)-$L$1+$L$2 -> 1592.439 | CK4: =AVERAGE(F4,L4,R4,X4,AD4,AJ4,AP4,AV4,BB4,BH4,BN4,BT4) -> 1586.9739 | CP4: =AVERAGE(F4,L4,R4) -> 1573.7977 | CT4: =AVERAGE(X4,AD4,AJ4) -> 1582.761 | CX4: =AVERAGE(AP4,AV4,BB4) -> 1598.4958 | DB4: =AVERAGE(BH4,BN4,BT4) -> 1592.8413
A6: Time | B6: Δ time | E6: PB_MAR 30-11 | K6: PB_MAR 30-12 | Q6: PB_MAR 30-13 | W6: PB_MAR 30-21 | AC6: PB_MAR 30-22 | AI6: PB_MAR 30-23 | AO6: PB_MAR 30-31 | AU6: PB_MAR 30-32 | BA6: PB_MAR 30-33 | BG6: PB_MAR 30-41 | BM6: PB_MAR 30-42 | BS6: PB_MAR 30-43 | CJ6: Over series
A7: [hours] | B7: [hours] | E7: [mm] | F7: [%] | G7: time [hrs] | H7: [%] | K7: [mm] | L7: [%] | M7: time [hrs] | N7: [%] | Q7: [mm] | R7: [%] | S7: time [hrs] | T7: [%] | W7: [mm] | X7: [%] | Y7: time [hrs] | Z7: [%] | AC7: [mm] | AD7: [%] | AE7: time [hrs] | AF7: [%] | AI7: [mm] | AJ7: [%] | AK7: time [hrs] | AL7: [%] | AO7: [mm] | AP7: [%] | AQ7: time [hrs] | AR7: [%] | AU7: [mm] | AV7: [%] | AW7: time [hrs] | AX7: [%] | BA7: [mm] | BB7: [%] | BC7: time [hrs] | BD7: [%] | BG7: [mm] | BH7: [%] | BI7: time [hrs] | BJ7: [%] | BM7: [mm] | BN7: [%] | BO7: time [hrs] | BP7: [%] | BS7: [mm] | BT7: [%] | BU7: time [hrs] | BV7: [%] | CI7: ave | CK7: stdev | CO7: Series 1 | CS7: Series 2 | CW7: Series 3 | DA7: Series 4
CN8: ave | CP8: stdev | CR8: ave | CT8: stdev | CV8: ave | CX8: stdev | CZ8: ave | DB8: stdev
A9: 0.25 | B9: 0.25 | D9: =$A9*F$4/$F$1 -> 0.24049544 | E9: -16.802124 | F9: =(F$4+E9)/F$4 -> 0.9894111 | G9: {=INDEX(D$9:D$400,MATCH(MIN(ABS($A9-D$9:D$400)),ABS($A9-D$9:D$400),0))} -> 0.24049544 | H9: =VLOOKUP(G9,D$9:F$400,3) -> 0.9894111 | J9: =$A9*L$4/$F$1 -> 0.23904336 | K9: -15.180381 | L9: =(L$4+K9)/L$4 -> 0.99037503 | M9: {=INDEX(J$9:J$400,MATCH(MIN(ABS($A9-J$9:J$400)),ABS($A9-J$9:J$400),0))} -> 0.23904336 | N9: =VLOOKUP(M9,J$9:L$400,3) -> 0.99037503 | P9: =$A9*R$4/$F$1 -> 0.23605018 | Q9: -14.27683 | R9: =(R$4+Q9)/R$4 -> 0.99083313 | S9: {=INDEX(P$9:P$400,MATCH(MIN(ABS($A9-P$9:P$400)),ABS($A9-P$9:P$400),0))} -> 0.23605018 | T9: =VLOOKUP(S9,P$9:R$400,3) -> 0.99083313 | V9: =$A9*X$4/$F$1 -> 0.24217345 | W9: -10.828637 | X9: =(X$4+W9)/X$4 -> 0.99322295 | Y9: {=INDEX(V$9:V$400,MATCH(MIN(ABS($A9-V$9:V$400)),ABS($A9-V$9:V$400),0))} -> 0.24217345 | Z9: =VLOOKUP(Y9,V$9:X$400,3) -> 0.99322295 | AB9: =$A9*AD$4/$F$1 -> 0.23688887 | AC9: -12.790597 | AD9: =(AD$4+AC9)/AD$4 -> 0.99181649 | AE9: {=INDEX(AB$9:AB$400,MATCH(MIN(ABS($A9-AB$9:AB$400)),ABS($A9-AB$9:AB$400),0))} -> 0.23688887 | AF9: =VLOOKUP(AE9,AB$9:AD$400,3) -> 0.99181649 | AH9: =$A9*AJ$4/$F$1 -> 0.24060219 | AI9: -10.989571 | AJ9: =(AJ$4+AI9)/AJ$4 -> 0.99307731 | AK9: {=INDEX(AH$9:AH$400,MATCH(MIN(ABS($A9-AH$9:AH$400)),ABS($A9-AH$9:AH$400),0))} -> 0.24060219 | AL9: =VLOOKUP(AK9,AH$9:AJ$400,3) -> 0.99307731 | AN9: =$A9*AP$4/$F$1 -> 0.24282235 | AO9: -13.910438 | AP9: =(AP$4+AO9)/AP$4 -> 0.99131748 | AQ9: {=INDEX(AN$9:AN$400,MATCH(MIN(ABS($A9-AN$9:AN$400)),ABS($A9-AN$9:AN$400),0))} -> 0.24282235 | AR9: =VLOOKUP(AQ9,AN$9:AP$400,3) -> 0.99131748 | AT9: =$A9*AV$4/$F$1 -> 0.24390904 | AU9: -12.251185 | AV9: =(AV$4+AU9)/AV$4 -> 0.99238721 | AW9: {=INDEX(AT$9:AT$400,MATCH(MIN(ABS($A9-AT$9:AT$400)),ABS($A9-AT$9:AT$400),0))} -> 0.24390904 | AX9: =VLOOKUP(AW9,AT$9:AV$400,3) -> 0.99238721 | AZ9: =$A9*BB$4/$F$1 -> 0.24008756 | BA9: -13.598088 | BB9: =(BB$4+BA9)/BB$4 -> 0.99141576 | BC9: {=INDEX(AZ$9:AZ$400,MATCH(MIN(ABS($A9-AZ$9:AZ$400)),ABS($A9-AZ$9:AZ$400),0))} -> 0.24008756 | BD9: =VLOOKUP(BC9,AZ$9:BB$400,3) -> 0.99141576 | BF9: =$A9*BH$4/$F$1 -> 0.2411352 | BG9: -9.2826638 | BH9: =(BH$4+BG9)/BH$4 -> 0.99416548 | BI9: {=INDEX(BF$9:BF$400,MATCH(MIN(ABS($A9-BF$9:BF$400)),ABS($A9-BF$9:BF$400),0))} -> 0.2411352 | BJ9: =VLOOKUP(BI9,BF$9:BH$400,3) -> 0.99416548 | BL9: =$A9*BN$4/$F$1 -> 0.2417577 | BM9: -6.5489692 | BN9: =(BN$4+BM9)/BN$4 -> 0.99589431 | BO9: {=INDEX(BL$9:BL$400,MATCH(MIN(ABS($A9-BL$9:BL$400)),ABS($A9-BL$9:BL$400),0))} -> 0.2417577 | BP9: =VLOOKUP(BO9,BL$9:BN$400,3) -> 0.99589431 | BR9: =$A9*BT$4/$F$1 -> 0.241355 | BS9: -12.244422 | BT9: =(BT$4+BS9)/BT$4 -> 0.9923109 | BU9: {=INDEX(BR$9:BR$400,MATCH(MIN(ABS($A9-BR$9:BR$400)),ABS($A9-BR$9:BR$400),0))} -> 0.241355 | BV9: =VLOOKUP(BU9,BR$9:BT$400,3) -> 0.9923109 | CI9: =AVERAGE(G9,M9,S9,Y9,AE9,AK9,AQ9,AW9,BC9,BI9,BO9,BU9) -> 0.2405267 | CJ9: =AVERAGE(H9,N9,T9,Z9,AF9,AL9,AR9,AX9,BD9,BJ9,BP9,BV9) -> 0.9921856 | CK9: =_xlfn.STDEV.P(H9,N9,T9,Z9,AF9,AL9,AR9,AX9,BD9,BJ9,BP9,BV9) -> 0.0016805192 | CN9: =AVERAGE(G9,M9,S9) -> 0.23852966 | CO9: =AVERAGE(H9,N9,T9) -> 0.99020642 | CP9: =_xlfn.STDEV.P(H9,N9,T9) -> 0.00059265797 | CR9: =AVERAGE(Y9,AE9,AK9) -> 0.23988817 | CS9: =AVERAGE(Z9,AF9,AL9) -> 0.99270558 | CT9: =_xlfn.STDEV.P(Z9,AF9,AL9) -> 0.00063149012 | CV9: =AVERAGE(AQ9,AW9,BC9) -> 0.24227298 | CW9: =AVERAGE(AR9,AX9,BD9) -> 0.99170682 | CX9: =_xlfn.STDEV.P(AR9,AX9,BD9) -> 0.00048278074 | CZ9: =AVERAGE(BI9,BO9,BU9) -> 0.24141597 | DA9: =AVERAGE(BJ9,BP9,BV9) -> 0.99412356 | DB9: =_xlfn.STDEV.P(BJ9,BP9,BV9) -> 0.0014632211
A10: 0.5 | B10: 0.25 | D10: =A10*$F$4/$F$1 -> 0.48099089 | E10: -36.063353 | F10: =(F$4+E10)/F$4 -> 0.97727244 | G10: {=INDEX(D$9:D$400,MATCH(MIN(ABS($A10-D$9:D$400)),ABS($A10-D$9:D$400),0))} -> 0.48099089 | H10: =VLOOKUP(G10,D$9:F$400,3) -> 0.97727244 | J10: =$A10*L$4/$F$1 -> 0.47808672 | K10: -32.217206 | L10: =(L$4+K10)/L$4 -> 0.979573 | M10: {=INDEX(J$9:J$400,MATCH(MIN(ABS($A10-J$9:J$400)),ABS($A10-J$9:J$400),0))} -> 0.47808672 | N10: =VLOOKUP(M10,J$9:L$400,3) -> 0.979573 | P10: =$A10*R$4/$F$1 -> 0.47210036 | Q10: -31.853632 | R10: =(R$4+Q10)/R$4 -> 0.97954742 | S10: {=INDEX(P$9:P$400,MATCH(MIN(ABS($A10-P$9:P$400)),ABS($A10-P$9:P$400),0))} -> 0.47210036 | T10: =VLOOKUP(S10,P$9:R$400,3) -> 0.97954742 | V10: =$A10*X$4/$F$1 -> 0.48434691 | W10: -25.482442 | X10: =(X$4+W10)/X$4 -> 0.98405193 | Y10: {=INDEX(V$9:V$400,MATCH(MIN(ABS($A10-V$9:V$400)),ABS($A10-V$9:V$400),0))} -> 0.48434691 | Z10: =VLOOKUP(Y10,V$9:X$400,3) -> 0.98405193 | AB10: =$A10*AD$4/$F$1 -> 0.47377773 | AC10: -25.697042 | AD10: =(AD$4+AC10)/AD$4 -> 0.98355886 | AE10: {=INDEX(AB$9:AB$400,MATCH(MIN(ABS($A10-AB$9:AB$400)),ABS($A10-AB$9:AB$400),0))} -> 0.47377773 | AF10: =VLOOKUP(AE10,AB$9:AD$400,3) -> 0.98355886 | AH10: =$A10*AJ$4/$F$1 -> 0.48120438 | AI10: -23.753618 | AJ10: =(AJ$4+AI10)/AJ$4 -> 0.98503683 | AK10: {=INDEX(AH$9:AH$400,MATCH(MIN(ABS($A10-AH$9:AH$400)),ABS($A10-AH$9:AH$400),0))} -> 0.48120438 | AL10: =VLOOKUP(AK10,AH$9:AJ$400,3) -> 0.98503683 | AN10: =$A10*AP$4/$F$1 -> 0.4856447 | AO10: -30.83317 | AP10: =(AP$4+AO10)/AP$4 -> 0.98075477 | AQ10: {=INDEX(AN$9:AN$400,MATCH(MIN(ABS($A10-AN$9:AN$400)),ABS($A10-AN$9:AN$400),0))} -> 0.4856447 | AR10: =VLOOKUP(AQ10,AN$9:AP$400,3) -> 0.98075477 | AT10: =$A10*AV$4/$F$1 -> 0.48781809 | AU10: -28.136922 | AV10: =(AV$4+AU10)/AV$4 -> 0.98251594 | AW10: {=INDEX(AT$9:AT$400,MATCH(MIN(ABS($A10-AT$9:AT$400)),ABS($A10-AT$9:AT$400),0))} -> 0.48781809 | AX10: =VLOOKUP(AW10,AT$9:AV$400,3) -> 0.98251594 | AZ10: =$A10*BB$4/$F$1 -> 0.48017512 | BA10: -30.23552 | BB10: =(BB$4+BA10)/BB$4 -> 0.98091284 | BC10: {=INDEX(AZ$9:AZ$400,MATCH(MIN(ABS($A10-AZ$9:AZ$400)),ABS($A10-AZ$9:AZ$400),0))} -> 0.48017512 | BD10: =VLOOKUP(BC10,AZ$9:BB$400,3) -> 0.98091284 | BF10: =$A10*BH$4/$F$1 -> 0.4822704 | BG10: -20.833377 | BH10: =(BH$4+BG10)/BH$4 -> 0.98690539 | BI10: {=INDEX(BF$9:BF$400,MATCH(MIN(ABS($A10-BF$9:BF$400)),ABS($A10-BF$9:BF$400),0))} -> 0.4822704 | BJ10: =VLOOKUP(BI10,BF$9:BH$400,3) -> 0.98690539 | BL10: =$A10*BN$4/$F$1 -> 0.4835154 | BM10: -18.004186 | BN10: =(BN$4+BM10)/BN$4 -> 0.98871279 | BO10: {=INDEX(BL$9:BL$400,MATCH(MIN(ABS($A10-BL$9:BL$400)),ABS($A10-BL$9:BL$400),0))} -> 0.4835154 | BP10: =VLOOKUP(BO10,BL$9:BN$400,3) -> 0.98871279 | BR10: =$A10*BT$4/$F$1 -> 0.48271 | BS10: -27.245145 | BT10: =(BT$4+BS10)/BT$4 -> 0.98289093 | BU10: {=INDEX(BR$9:BR$400,MATCH(MIN(ABS($A10-BR$9:BR$400)),ABS($A10-BR$9:BR$400),0))} -> 0.48271 | BV10: =VLOOKUP(BU10,BR$9:BT$400,3) -> 0.98289093 | CI10: =AVERAGE(G10,M10,S10,Y10,AE10,AK10,AQ10,AW10,BC10,BI10,BO10,BU10) -> 0.48105339 | CJ10: =AVERAGE(H10,N10,T10,Z10,AF10,AL10,AR10,AX10,BD10,BJ10,BP10,BV10) -> 0.98264443 | CK10: =_xlfn.STDEV.P(H10,N10,T10,Z10,AF10,AL10,AR10,AX10,BD10,BJ10,BP10,BV10) -> 0.0031364984 | CN10: =AVERAGE(G10,M10,S10) -> 0.47705932 | CO10: =AVERAGE(H10,N10,T10) -> 0.97879762 | CP10: =_xlfn.STDEV.P(H10,N10,T10) -> 0.0010785125 | CR10: =AVERAGE(Y10,AE10,AK10) -> 0.47977634 | CS10: =AVERAGE(Z10,AF10,AL10) -> 0.98421587 | CT10: =_xlfn.STDEV.P(Z10,AF10,AL10) -> 0.00061441334 | CV10: =AVERAGE(AQ10,AW10,BC10) -> 0.48454597 | CW10: =AVERAGE(AR10,AX10,BD10) -> 0.98139452 | CX10: =_xlfn.STDEV.P(AR10,AX10,BD10) -> 0.00079558815 | CZ10: =AVERAGE(BI10,BO10,BU10) -> 0.48283194 | DA10: =AVERAGE(BJ10,BP10,BV10) -> 0.9861697 | DB10: =_xlfn.STDEV.P(BJ10,BP10,BV10) -> 0.0024330261
A11: 0.75 | B11: 0.25 | D11: =A11*$F$4/$F$1 -> 0.72148633 | E11: -55.257828 | F11: =(F$4+E11)/F$4 -> 0.96517586 | G11: {=INDEX(D$9:D$400,MATCH(MIN(ABS($A11-D$9:D$400)),ABS($A11-D$9:D$400),0))} -> 0.72148633 | H11: =VLOOKUP(G11,D$9:F$400,3) -> 0.96517586 | J11: =$A11*L$4/$F$1 -> 0.71713007 | K11: -50.675641 | L11: =(L$4+K11)/L$4 -> 0.96786961 | M11: {=INDEX(J$9:J$400,MATCH(MIN(ABS($A11-J$9:J$400)),ABS($A11-J$9:J$400),0))} -> 0.71713007 | N11: =VLOOKUP(M11,J$9:L$400,3) -> 0.96786961 | P11: =$A11*R$4/$F$1 -> 0.70815054 | Q11: -48.689884 | R11: =(R$4+Q11)/R$4 -> 0.9687372 | S11: {=INDEX(P$9:P$400,MATCH(MIN(ABS($A11-P$9:P$400)),ABS($A11-P$9:P$400),0))} -> 0.70815054 | T11: =VLOOKUP(S11,P$9:R$400,3) -> 0.9687372 | V11: =$A11*X$4/$F$1 -> 0.72652036 | W11: -37.789109 | X11: =(X$4+W11)/X$4 -> 0.97634987 | Y11: {=INDEX(V$9:V$400,MATCH(MIN(ABS($A11-V$9:V$400)),ABS($A11-V$9:V$400),0))} -> 0.72652036 | Z11: =VLOOKUP(Y11,V$9:X$400,3) -> 0.97634987 | AB11: =$A11*AD$4/$F$1 -> 0.7106666 | AC11: -40.665202 | AD11: =(AD$4+AC11)/AD$4 -> 0.97398213 | AE11: {=INDEX(AB$9:AB$400,MATCH(MIN(ABS($A11-AB$9:AB$400)),ABS($A11-AB$9:AB$400),0))} -> 0.7106666 | AF11: =VLOOKUP(AE11,AB$9:AD$400,3) -> 0.97398213 | AH11: =$A11*AJ$4/$F$1 -> 0.72180657 | AI11: -37.948227 | AJ11: =(AJ$4+AI11)/AJ$4 -> 0.97609518 | AK11: {=INDEX(AH$9:AH$400,MATCH(MIN(ABS($A11-AH$9:AH$400)),ABS($A11-AH$9:AH$400),0))} -> 0.72180657 | AL11: =VLOOKUP(AK11,AH$9:AJ$400,3) -> 0.97609518 | AN11: =$A11*AP$4/$F$1 -> 0.72846705 | AO11: -48.889017 | AP11: =(AP$4+AO11)/AP$4 -> 0.96948481 | AQ11: {=INDEX(AN$9:AN$400,MATCH(MIN(ABS($A11-AN$9:AN$400)),ABS($A11-AN$9:AN$400),0))} -> 0.72846705 | AR11: =VLOOKUP(AQ11,AN$9:AP$400,3) -> 0.96948481 | AT11: =$A11*AV$4/$F$1 -> 0.73172713 | AU11: -44.800843 | AV11: =(AV$4+AU11)/AV$4 -> 0.97216112 | AW11: {=INDEX(AT$9:AT$400,MATCH(MIN(ABS($A11-AT$9:AT$400)),ABS($A11-AT$9:AT$400),0))} -> 0.73172713 | AX11: =VLOOKUP(AW11,AT$9:AV$400,3) -> 0.97216112 | AZ11: =$A11*BB$4/$F$1 -> 0.72026268 | BA11: -47.07578 | BB11: =(BB$4+BA11)/BB$4 -> 0.97028188 | BC11: {=INDEX(AZ$9:AZ$400,MATCH(MIN(ABS($A11-AZ$9:AZ$400)),ABS($A11-AZ$9:AZ$400),0))} -> 0.72026268 | BD11: =VLOOKUP(BC11,AZ$9:BB$400,3) -> 0.97028188 | BF11: =$A11*BH$4/$F$1 -> 0.7234056 | BG11: -34.99868 | BH11: =(BH$4+BG11)/BH$4 -> 0.97800193 | BI11: {=INDEX(BF$9:BF$400,MATCH(MIN(ABS($A11-BF$9:BF$400)),ABS($A11-BF$9:BF$400),0))} -> 0.7234056 | BJ11: =VLOOKUP(BI11,BF$9:BH$400,3) -> 0.97800193 | BL11: =$A11*BN$4/$F$1 -> 0.72527311 | BM11: -33.783593 | BN11: =(BN$4+BM11)/BN$4 -> 0.97882034 | BO11: {=INDEX(BL$9:BL$400,MATCH(MIN(ABS($A11-BL$9:BL$400)),ABS($A11-BL$9:BL$400),0))} -> 0.72527311 | BP11: =VLOOKUP(BO11,BL$9:BN$400,3) -> 0.97882034 | BR11: =$A11*BT$4/$F$1 -> 0.724065 | BS11: -42.027197 | BT11: =(BT$4+BS11)/BT$4 -> 0.97360829 | BU11: {=INDEX(BR$9:BR$400,MATCH(MIN(ABS($A11-BR$9:BR$400)),ABS($A11-BR$9:BR$400),0))} -> 0.724065 | BV11: =VLOOKUP(BU11,BR$9:BT$400,3) -> 0.97360829 | CI11: =AVERAGE(G11,M11,S11,Y11,AE11,AK11,AQ11,AW11,BC11,BI11,BO11,BU11) -> 0.72158009 | CJ11: =AVERAGE(H11,N11,T11,Z11,AF11,AL11,AR11,AX11,BD11,BJ11,BP11,BV11) -> 0.97254735 | CK11: =_xlfn.STDEV.P(H11,N11,T11,Z11,AF11,AL11,AR11,AX11,BD11,BJ11,BP11,BV11) -> 0.0041304908 | CN11: =AVERAGE(G11,M11,S11) -> 0.71558898 | CO11: =AVERAGE(H11,N11,T11) -> 0.96726089 | CP11: =_xlfn.STDEV.P(H11,N11,T11) -> 0.0015162877 | CR11: =AVERAGE(Y11,AE11,AK11) -> 0.71966451 | CS11: =AVERAGE(Z11,AF11,AL11) -> 0.97547573 | CT11: =_xlfn.STDEV.P(Z11,AF11,AL11) -> 0.001061239 | CV11: =AVERAGE(AQ11,AW11,BC11) -> 0.72681895 | CW11: =AVERAGE(AR11,AX11,BD11) -> 0.9706426 | CX11: =_xlfn.STDEV.P(AR11,AX11,BD11) -> 0.0011219787 | CZ11: =AVERAGE(BI11,BO11,BU11) -> 0.7242479 | DA11: =AVERAGE(BJ11,BP11,BV11) -> 0.97681019 | DB11: =_xlfn.STDEV.P(BJ11,BP11,BV11) -> 0.0022886051
A12: 1 | B12: 0.25 | D12: =A12*$F$4/$F$1 -> 0.96198178 | E12: -74.780872 | F12: =(F$4+E12)/F$4 -> 0.9528722 | G12: {=INDEX(D$9:D$400,MATCH(MIN(ABS($A12-D$9:D$400)),ABS($A12-D$9:D$400),0))} -> 0.96198178 | H12: =VLOOKUP(G12,D$9:F$400,3) -> 0.9528722 | J12: =$A12*L$4/$F$1 -> 0.95617343 | K12: -69.380862 | L12: =(L$4+K12)/L$4 -> 0.95600974 | M12: {=INDEX(J$9:J$400,MATCH(MIN(ABS($A12-J$9:J$400)),ABS($A12-J$9:J$400),0))} -> 0.95617343 | N12: =VLOOKUP(M12,J$9:L$400,3) -> 0.95600974 | P12: =$A12*R$4/$F$1 -> 0.94420072 | Q12: -67.320212 | R12: =(R$4+Q12)/R$4 -> 0.95677504 | S12: {=INDEX(P$9:P$400,MATCH(MIN(ABS($A12-P$9:P$400)),ABS($A12-P$9:P$400),0))} -> 0.94420072 | T12: =VLOOKUP(S12,P$9:R$400,3) -> 0.95677504 | V12: =$A12*X$4/$F$1 -> 0.96869381 | W12: -51.67475 | X12: =(X$4+W12)/X$4 -> 0.9676596 | Y12: {=INDEX(V$9:V$400,MATCH(MIN(ABS($A12-V$9:V$400)),ABS($A12-V$9:V$400),0))} -> 0.96869381 | Z12: =VLOOKUP(Y12,V$9:X$400,3) -> 0.9676596 | AB12: =$A12*AD$4/$F$1 -> 0.94755546 | AC12: -56.310539 | AD12: =(AD$4+AC12)/AD$4 -> 0.96397213 | AE12: {=INDEX(AB$9:AB$400,MATCH(MIN(ABS($A12-AB$9:AB$400)),ABS($A12-AB$9:AB$400),0))} -> 0.94755546 | AF12: =VLOOKUP(AE12,AB$9:AD$400,3) -> 0.96397213 | AH12: =$A12*AJ$4/$F$1 -> 0.96240876 | AI12: -52.293064 | AJ12: =(AJ$4+AI12)/AJ$4 -> 0.96705891 | AK12: {=INDEX(AH$9:AH$400,MATCH(MIN(ABS($A12-AH$9:AH$400)),ABS($A12-AH$9:AH$400),0))} -> 0.96240876 | AL12: =VLOOKUP(AK12,AH$9:AJ$400,3) -> 0.96705891 | AN12: =$A12*AP$4/$F$1 -> 0.9712894 | AO12: -67.368492 | AP12: =(AP$4+AO12)/AP$4 -> 0.95795042 | AQ12: {=INDEX(AN$9:AN$400,MATCH(MIN(ABS($A12-AN$9:AN$400)),ABS($A12-AN$9:AN$400),0))} -> 0.9712894 | AR12: =VLOOKUP(AQ12,AN$9:AP$400,3) -> 0.95795042 | AT12: =$A12*AV$4/$F$1 -> 0.97563617 | AU12: -63.080371 | AV12: =(AV$4+AU12)/AV$4 -> 0.96080237 | AW12: {=INDEX(AT$9:AT$400,MATCH(MIN(ABS($A12-AT$9:AT$400)),ABS($A12-AT$9:AT$400),0))} -> 0.97563617 | AX12: =VLOOKUP(AW12,AT$9:AV$400,3) -> 0.96080237 | AZ12: =$A12*BB$4/$F$1 -> 0.96035025 | BA12: -65.414547 | BB12: =(BB$4+BA12)/BB$4 -> 0.95870493 | BC12: {=INDEX(AZ$9:AZ$400,MATCH(MIN(ABS($A12-AZ$9:AZ$400)),ABS($A12-AZ$9:AZ$400),0))} -> 0.96035025 | BD12: =VLOOKUP(BC12,AZ$9:BB$400,3) -> 0.95870493 | BF12: =$A12*BH$4/$F$1 -> 0.9645408 | BG12: -50.371368 | BH12: =(BH$4+BG12)/BH$4 -> 0.96833958 | BI12: {=INDEX(BF$9:BF$400,MATCH(MIN(ABS($A12-BF$9:BF$400)),ABS($A12-BF$9:BF$400),0))} -> 0.9645408 | BJ12: =VLOOKUP(BI12,BF$9:BH$400,3) -> 0.96833958 | BL12: =$A12*BN$4/$F$1 -> 0.96703081 | BM12: -47.833863 | BN12: =(BN$4+BM12)/BN$4 -> 0.97001192 | BO12: {=INDEX(BL$9:BL$400,MATCH(MIN(ABS($A12-BL$9:BL$400)),ABS($A12-BL$9:BL$400),0))} -> 0.96703081 | BP12: =VLOOKUP(BO12,BL$9:BN$400,3) -> 0.97001192 | BR12: =$A12*BT$4/$F$1 -> 0.96542 | BS12: -58.27012 | BT12: =(BT$4+BS12)/BT$4 -> 0.96340826 | BU12: {=INDEX(BR$9:BR$400,MATCH(MIN(ABS($A12-BR$9:BR$400)),ABS($A12-BR$9:BR$400),0))} -> 0.96542 | BV12: =VLOOKUP(BU12,BR$9:BT$400,3) -> 0.96340826 | CI12: =AVERAGE(G12,M12,S12,Y12,AE12,AK12,AQ12,AW12,BC12,BI12,BO12,BU12) -> 0.96210678 | CJ12: =AVERAGE(H12,N12,T12,Z12,AF12,AL12,AR12,AX12,BD12,BJ12,BP12,BV12) -> 0.96196376 | CK12: =_xlfn.STDEV.P(H12,N12,T12,Z12,AF12,AL12,AR12,AX12,BD12,BJ12,BP12,BV12) -> 0.0053467486 | CN12: =AVERAGE(G12,M12,S12) -> 0.95411864 | CO12: =AVERAGE(H12,N12,T12) -> 0.95521899 | CP12: =_xlfn.STDEV.P(H12,N12,T12) -> 0.0016885884 | CR12: =AVERAGE(Y12,AE12,AK12) -> 0.95955268 | CS12: =AVERAGE(Z12,AF12,AL12) -> 0.96623022 | CT12: =_xlfn.STDEV.P(Z12,AF12,AL12) -> 0.0016154266 | CV12: =AVERAGE(AQ12,AW12,BC12) -> 0.96909194 | CW12: =AVERAGE(AR12,AX12,BD12) -> 0.95915257 | CX12: =_xlfn.STDEV.P(AR12,AX12,BD12) -> 0.0012065623 | CZ12: =AVERAGE(BI12,BO12,BU12) -> 0.96566387 | DA12: =AVERAGE(BJ12,BP12,BV12) -> 0.96725325 | DB12: =_xlfn.STDEV.P(BJ12,BP12,BV12) -> 0.0028032343
A13: 1.25 | B13: 0.25 | D13: =A13*$F$4/$F$1 -> 1.2024772 | E13: -94.190197 | F13: =(F$4+E13)/F$4 -> 0.94064021 | G13: {=INDEX(D$9:D$400,MATCH(MIN(ABS($A13-D$9:D$400)),ABS($A13-D$9:D$400),0))} -> 1.2024772 | H13: =VLOOKUP(G13,D$9:F$400,3) -> 0.94064021 | J13: =$A13*L$4/$F$1 -> 1.1952168 | K13: -88.494244 | L13: =(L$4+K13)/L$4 -> 0.94389109 | M13: {=INDEX(J$9:J$400,MATCH(MIN(ABS($A13-J$9:J$400)),ABS($A13-J$9:J$400),0))} -> 1.1952168 | N13: =VLOOKUP(M13,J$9:L$400,3) -> 0.94389109 | P13: =$A13*R$4/$F$1 -> 1.1802509 | Q13: -86.064446 | R13: =(R$4+Q13)/R$4 -> 0.94473974 | S13: {=INDEX(P$9:P$400,MATCH(MIN(ABS($A13-P$9:P$400)),ABS($A13-P$9:P$400),0))} -> 1.1802509 | T13: =VLOOKUP(S13,P$9:R$400,3) -> 0.94473974 | V13: =$A13*X$4/$F$1 -> 1.2108673 | W13: -66.677163 | X13: =(X$4+W13)/X$4 -> 0.95827041 | Y13: {=INDEX(V$9:V$400,MATCH(MIN(ABS($A13-V$9:V$400)),ABS($A13-V$9:V$400),0))} -> 1.2108673 | Z13: =VLOOKUP(Y13,V$9:X$400,3) -> 0.95827041 | AB13: =$A13*AD$4/$F$1 -> 1.1844443 | AC13: -71.070048 | AD13: =(AD$4+AC13)/AD$4 -> 0.9545289 | AE13: {=INDEX(AB$9:AB$400,MATCH(MIN(ABS($A13-AB$9:AB$400)),ABS($A13-AB$9:AB$400),0))} -> 1.1844443 | AF13: =VLOOKUP(AE13,AB$9:AD$400,3) -> 0.9545289 | AH13: =$A13*AJ$4/$F$1 -> 1.2030109 | AI13: -66.252972 | AJ13: =(AJ$4+AI13)/AJ$4 -> 0.95826511 | AK13: {=INDEX(AH$9:AH$400,MATCH(MIN(ABS($A13-AH$9:AH$400)),ABS($A13-AH$9:AH$400),0))} -> 1.2030109 | AL13: =VLOOKUP(AK13,AH$9:AJ$400,3) -> 0.95826511 | AN13: =$A13*AP$4/$F$1 -> 1.2141117 | AO13: -86.302779 | AP13: =(AP$4+AO13)/AP$4 -> 0.94613215 | AQ13: {=INDEX(AN$9:AN$400,MATCH(MIN(ABS($A13-AN$9:AN$400)),ABS($A13-AN$9:AN$400),0))} -> 1.2141117 | AR13: =VLOOKUP(AQ13,AN$9:AP$400,3) -> 0.94613215 | AT13: =$A13*AV$4/$F$1 -> 1.2195452 | AU13: -81.600111 | AV13: =(AV$4+AU13)/AV$4 -> 0.94929435 | AW13: {=INDEX(AT$9:AT$400,MATCH(MIN(ABS($A13-AT$9:AT$400)),ABS($A13-AT$9:AT$400),0))} -> 1.2195452 | AX13: =VLOOKUP(AW13,AT$9:AV$400,3) -> 0.94929435 | AZ13: =$A13*BB$4/$F$1 -> 1.2004378 | BA13: -83.441089 | BB13: =(BB$4+BA13)/BB$4 -> 0.94732509 | BC13: {=INDEX(AZ$9:AZ$400,MATCH(MIN(ABS($A13-AZ$9:AZ$400)),ABS($A13-AZ$9:AZ$400),0))} -> 1.2004378 | BD13: =VLOOKUP(BC13,AZ$9:BB$400,3) -> 0.94732509 | BF13: =$A13*BH$4/$F$1 -> 1.205676 | BG13: -67.121768 | BH13: =(BH$4+BG13)/BH$4 -> 0.95781129 | BI13: {=INDEX(BF$9:BF$400,MATCH(MIN(ABS($A13-BF$9:BF$400)),ABS($A13-BF$9:BF$400),0))} -> 1.205676 | BJ13: =VLOOKUP(BI13,BF$9:BH$400,3) -> 0.95781129 | BL13: =$A13*BN$4/$F$1 -> 1.2087885 | BM13: -63.917669 | BN13: =(BN$4+BM13)/BN$4 -> 0.95992864 | BO13: {=INDEX(BL$9:BL$400,MATCH(MIN(ABS($A13-BL$9:BL$400)),ABS($A13-BL$9:BL$400),0))} -> 1.2087885 | BP13: =VLOOKUP(BO13,BL$9:BN$400,3) -> 0.95992864 | BR13: =$A13*BT$4/$F$1 -> 1.206775 | BS13: -73.908507 | BT13: =(BT$4+BS13)/BT$4 -> 0.95358786 | BU13: {=INDEX(BR$9:BR$400,MATCH(MIN(ABS($A13-BR$9:BR$400)),ABS($A13-BR$9:BR$400),0))} -> 1.206775 | BV13: =VLOOKUP(BU13,BR$9:BT$400,3) -> 0.95358786 | CI13: =AVERAGE(G13,M13,S13,Y13,AE13,AK13,AQ13,AW13,BC13,BI13,BO13,BU13) -> 1.2026335 | CJ13: =AVERAGE(H13,N13,T13,Z13,AF13,AL13,AR13,AX13,BD13,BJ13,BP13,BV13) -> 0.95120124 | CK13: =_xlfn.STDEV.P(H13,N13,T13,Z13,AF13,AL13,AR13,AX13,BD13,BJ13,BP13,BV13) -> 0.0063743103 | CN13: =AVERAGE(G13,M13,S13) -> 1.1926483 | CO13: =AVERAGE(H13,N13,T13) -> 0.94309035 | CP13: =_xlfn.STDEV.P(H13,N13,T13) -> 0.0017668094 | CR13: =AVERAGE(Y13,AE13,AK13) -> 1.1994408 | CS13: =AVERAGE(Z13,AF13,AL13) -> 0.95702147 | CT13: =_xlfn.STDEV.P(Z13,AF13,AL13) -> 0.0017625173 | CV13: =AVERAGE(AQ13,AW13,BC13) -> 1.2113649 | CW13: =AVERAGE(AR13,AX13,BD13) -> 0.94758387 | CX13: =_xlfn.STDEV.P(AR13,AX13,BD13) -> 0.0013038657 | CZ13: =AVERAGE(BI13,BO13,BU13) -> 1.2070798 | DA13: =AVERAGE(BJ13,BP13,BV13) -> 0.95710926 | DB13: =_xlfn.STDEV.P(BJ13,BP13,BV13) -> 0.0026357804
A14: 1.5 | B14: 0.25 | D14: =A14*$F$4/$F$1 -> 1.4429727 | E14: -113.53646 | F14: =(F$4+E14)/F$4 -> 0.92844796 | G14: {=INDEX(D$9:D$400,MATCH(MIN(ABS($A14-D$9:D$400)),ABS($A14-D$9:D$400),0))} -> 1.4429727 | H14: =VLOOKUP(G14,D$9:F$400,3) -> 0.92844796 | J14: =$A14*L$4/$F$1 -> 1.4342601 | K14: -108.01134 | L14: =(L$4+K14)/L$4 -> 0.93151647 | M14: {=INDEX(J$9:J$400,MATCH(MIN(ABS($A14-J$9:J$400)),ABS($A14-J$9:J$400),0))} -> 1.4342601 | N14: =VLOOKUP(M14,J$9:L$400,3) -> 0.93151647 | P14: =$A14*R$4/$F$1 -> 1.4163011 | Q14: -104.91463 | R14: =(R$4+Q14)/R$4 -> 0.93263641 | S14: {=INDEX(P$9:P$400,MATCH(MIN(ABS($A14-P$9:P$400)),ABS($A14-P$9:P$400),0))} -> 1.4163011 | T14: =VLOOKUP(S14,P$9:R$400,3) -> 0.93263641 | V14: =$A14*X$4/$F$1 -> 1.4530407 | W14: -81.593849 | X14: =(X$4+W14)/X$4 -> 0.94893488 | Y14: {=INDEX(V$9:V$400,MATCH(MIN(ABS($A14-V$9:V$400)),ABS($A14-V$9:V$400),0))} -> 1.4530407 | Z14: =VLOOKUP(Y14,V$9:X$400,3) -> 0.94893488 | AB14: =$A14*AD$4/$F$1 -> 1.4213332 | AC14: -86.36014 | AD14: =(AD$4+AC14)/AD$4 -> 0.9447462 | AE14: {=INDEX(AB$9:AB$400,MATCH(MIN(ABS($A14-AB$9:AB$400)),ABS($A14-AB$9:AB$400),0))} -> 1.4213332 | AF14: =VLOOKUP(AE14,AB$9:AD$400,3) -> 0.9447462 | AH14: =$A14*AJ$4/$F$1 -> 1.4436131 | AI14: -80.391975 | AJ14: =(AJ$4+AI14)/AJ$4 -> 0.94935849 | AK14: {=INDEX(AH$9:AH$400,MATCH(MIN(ABS($A14-AH$9:AH$400)),ABS($A14-AH$9:AH$400),0))} -> 1.4436131 | AL14: =VLOOKUP(AK14,AH$9:AJ$400,3) -> 0.94935849 | AN14: =$A14*AP$4/$F$1 -> 1.4569341 | AO14: -105.90485 | AP14: =(AP$4+AO14)/AP$4 -> 0.93389707 | AQ14: {=INDEX(AN$9:AN$400,MATCH(MIN(ABS($A14-AN$9:AN$400)),ABS($A14-AN$9:AN$400),0))} -> 1.4569341 | AR14: =VLOOKUP(AQ14,AN$9:AP$400,3) -> 0.93389707 | AT14: =$A14*AV$4/$F$1 -> 1.4634543 | AU14: -100.3754 | AV14: =(AV$4+AU14)/AV$4 -> 0.93762754 | AW14: {=INDEX(AT$9:AT$400,MATCH(MIN(ABS($A14-AT$9:AT$400)),ABS($A14-AT$9:AT$400),0))} -> 1.4634543 | AX14: =VLOOKUP(AW14,AT$9:AV$400,3) -> 0.93762754 | AZ14: =$A14*BB$4/$F$1 -> 1.4405254 | BA14: -102.09797 | BB14: =(BB$4+BA14)/BB$4 -> 0.93554733 | BC14: {=INDEX(AZ$9:AZ$400,MATCH(MIN(ABS($A14-AZ$9:AZ$400)),ABS($A14-AZ$9:AZ$400),0))} -> 1.4405254 | BD14: =VLOOKUP(BC14,AZ$9:BB$400,3) -> 0.93554733 | BF14: =$A14*BH$4/$F$1 -> 1.4468112 | BG14: -82.35237 | BH14: =(BH$4+BG14)/BH$4 -> 0.94823825 | BI14: {=INDEX(BF$9:BF$400,MATCH(MIN(ABS($A14-BF$9:BF$400)),ABS($A14-BF$9:BF$400),0))} -> 1.4468112 | BJ14: =VLOOKUP(BI14,BF$9:BH$400,3) -> 0.94823825 | BL14: =$A14*BN$4/$F$1 -> 1.4505462 | BM14: -80.940906 | BN14: =(BN$4+BM14)/BN$4 -> 0.94925641 | BO14: {=INDEX(BL$9:BL$400,MATCH(MIN(ABS($A14-BL$9:BL$400)),ABS($A14-BL$9:BL$400),0))} -> 1.4505462 | BP14: =VLOOKUP(BO14,BL$9:BN$400,3) -> 0.94925641 | BR14: =$A14*BT$4/$F$1 -> 1.44813 | BS14: -88.613786 | BT14: =(BT$4+BS14)/BT$4 -> 0.94435342 | BU14: {=INDEX(BR$9:BR$400,MATCH(MIN(ABS($A14-BR$9:BR$400)),ABS($A14-BR$9:BR$400),0))} -> 1.44813 | BV14: =VLOOKUP(BU14,BR$9:BT$400,3) -> 0.94435342 | CI14: =AVERAGE(G14,M14,S14,Y14,AE14,AK14,AQ14,AW14,BC14,BI14,BO14,BU14) -> 1.4431602 | CJ14: =AVERAGE(H14,N14,T14,Z14,AF14,AL14,AR14,AX14,BD14,BJ14,BP14,BV14) -> 0.94038003 | CK14: =_xlfn.STDEV.P(H14,N14,T14,Z14,AF14,AL14,AR14,AX14,BD14,BJ14,BP14,BV14) -> 0.0075445988 | CN14: =AVERAGE(G14,M14,S14) -> 1.431178 | CO14: =AVERAGE(H14,N14,T14) -> 0.93086695 | CP14: =_xlfn.STDEV.P(H14,N14,T14) -> 0.0017705327 | CR14: =AVERAGE(Y14,AE14,AK14) -> 1.439329 | CS14: =AVERAGE(Z14,AF14,AL14) -> 0.94767986 | CT14: =_xlfn.STDEV.P(Z14,AF14,AL14) -> 0.0020816069 | CV14: =AVERAGE(AQ14,AW14,BC14) -> 1.4536379 | CW14: =AVERAGE(AR14,AX14,BD14) -> 0.93569065 | CX14: =_xlfn.STDEV.P(AR14,AX14,BD14) -> 0.0015263232 | CZ14: =AVERAGE(BI14,BO14,BU14) -> 1.4484958 | DA14: =AVERAGE(BJ14,BP14,BV14) -> 0.94728269 | DB14: =_xlfn.STDEV.P(BJ14,BP14,BV14) -> 0.0021126022
A15: 1.75 | B15: 0.25 | D15: =A15*$F$4/$F$1 -> 1.6834681 | E15: -132.63751 | F15: =(F$4+E15)/F$4 -> 0.91641026 | G15: {=INDEX(D$9:D$400,MATCH(MIN(ABS($A15-D$9:D$400)),ABS($A15-D$9:D$400),0))} -> 1.6834681 | H15: =VLOOKUP(G15,D$9:F$400,3) -> 0.91641026 | J15: =$A15*L$4/$F$1 -> 1.6733035 | K15: -125.77168 | L15: =(L$4+K15)/L$4 -> 0.9202557 | M15: {=INDEX(J$9:J$400,MATCH(MIN(ABS($A15-J$9:J$400)),ABS($A15-J$9:J$400),0))} -> 1.6733035 | N15: =VLOOKUP(M15,J$9:L$400,3) -> 0.9202557 | P15: =$A15*R$4/$F$1 -> 1.6523513 | Q15: -123.31158 | R15: =(R$4+Q15)/R$4 -> 0.9208241 | S15: {=INDEX(P$9:P$400,MATCH(MIN(ABS($A15-P$9:P$400)),ABS($A15-P$9:P$400),0))} -> 1.6523513 | T15: =VLOOKUP(S15,P$9:R$400,3) -> 0.9208241 | V15: =$A15*X$4/$F$1 -> 1.6952142 | W15: -96.98501 | X15: =(X$4+W15)/X$4 -> 0.93930239 | Y15: {=INDEX(V$9:V$400,MATCH(MIN(ABS($A15-V$9:V$400)),ABS($A15-V$9:V$400),0))} -> 1.6952142 | Z15: =VLOOKUP(Y15,V$9:X$400,3) -> 0.93930239 | AB15: =$A15*AD$4/$F$1 -> 1.6582221 | AC15: -100.43433 | AD15: =(AD$4+AC15)/AD$4 -> 0.93574143 | AE15: {=INDEX(AB$9:AB$400,MATCH(MIN(ABS($A15-AB$9:AB$400)),ABS($A15-AB$9:AB$400),0))} -> 1.6582221 | AF15: =VLOOKUP(AE15,AB$9:AD$400,3) -> 0.93574143 | AH15: =$A15*AJ$4/$F$1 -> 1.6842153 | AI15: -95.103516 | AJ15: =(AJ$4+AI15)/AJ$4 -> 0.94009122 | AK15: {=INDEX(AH$9:AH$400,MATCH(MIN(ABS($A15-AH$9:AH$400)),ABS($A15-AH$9:AH$400),0))} -> 1.6842153 | AL15: =VLOOKUP(AK15,AH$9:AJ$400,3) -> 0.94009122 | AN15: =$A15*AP$4/$F$1 -> 1.6997564 | AO15: -125.09256 | AP15: =(AP$4+AO15)/AP$4 -> 0.92192063 | AQ15: {=INDEX(AN$9:AN$400,MATCH(MIN(ABS($A15-AN$9:AN$400)),ABS($A15-AN$9:AN$400),0))} -> 1.6997564 | AR15: =VLOOKUP(AQ15,AN$9:AP$400,3) -> 0.92192063 | AT15: =$A15*AV$4/$F$1 -> 1.7073633 | AU15: -119.28089 | AV15: =(AV$4+AU15)/AV$4 -> 0.92587982 | AW15: {=INDEX(AT$9:AT$400,MATCH(MIN(ABS($A15-AT$9:AT$400)),ABS($A15-AT$9:AT$400),0))} -> 1.7073633 | AX15: =VLOOKUP(AW15,AT$9:AV$400,3) -> 0.92587982 | AZ15: =$A15*BB$4/$F$1 -> 1.6806129 | BA15: -120.36748 | BB15: =(BB$4+BA15)/BB$4 -> 0.9240141 | BC15: {=INDEX(AZ$9:AZ$400,MATCH(MIN(ABS($A15-AZ$9:AZ$400)),ABS($A15-AZ$9:AZ$400),0))} -> 1.6806129 | BD15: =VLOOKUP(BC15,AZ$9:BB$400,3) -> 0.9240141 | BF15: =$A15*BH$4/$F$1 -> 1.6879464 | BG15: -97.948988 | BH15: =(BH$4+BG15)/BH$4 -> 0.93843515 | BI15: {=INDEX(BF$9:BF$400,MATCH(MIN(ABS($A15-BF$9:BF$400)),ABS($A15-BF$9:BF$400),0))} -> 1.6879464 | BJ15: =VLOOKUP(BI15,BF$9:BH$400,3) -> 0.93843515 | BL15: =$A15*BN$4/$F$1 -> 1.6923039 | BM15: -96.997909 | BN15: =(BN$4+BM15)/BN$4 -> 0.93918992 | BO15: {=INDEX(BL$9:BL$400,MATCH(MIN(ABS($A15-BL$9:BL$400)),ABS($A15-BL$9:BL$400),0))} -> 1.6923039 | BP15: =VLOOKUP(BO15,BL$9:BN$400,3) -> 0.93918992 | BR15: =$A15*BT$4/$F$1 -> 1.689485 | BS15: -104.17828 | BT15: =(BT$4+BS15)/BT$4 -> 0.93457942 | BU15: {=INDEX(BR$9:BR$400,MATCH(MIN(ABS($A15-BR$9:BR$400)),ABS($A15-BR$9:BR$400),0))} -> 1.689485 | BV15: =VLOOKUP(BU15,BR$9:BT$400,3) -> 0.93457942 | CI15: =AVERAGE(G15,M15,S15,Y15,AE15,AK15,AQ15,AW15,BC15,BI15,BO15,BU15) -> 1.6836869 | CJ15: =AVERAGE(H15,N15,T15,Z15,AF15,AL15,AR15,AX15,BD15,BJ15,BP15,BV15) -> 0.92972035 | CK15: =_xlfn.STDEV.P(H15,N15,T15,Z15,AF15,AL15,AR15,AX15,BD15,BJ15,BP15,BV15) -> 0.0085580525 | CN15: =AVERAGE(G15,M15,S15) -> 1.6697076 | CO15: =AVERAGE(H15,N15,T15) -> 0.91916335 | CP15: =_xlfn.STDEV.P(H15,N15,T15) -> 0.0019605136 | CR15: =AVERAGE(Y15,AE15,AK15) -> 1.6792172 | CS15: =AVERAGE(Z15,AF15,AL15) -> 0.93837835 | CT15: =_xlfn.STDEV.P(Z15,AF15,AL15) -> 0.0018921855 | CV15: =AVERAGE(AQ15,AW15,BC15) -> 1.6959109 | CW15: =AVERAGE(AR15,AX15,BD15) -> 0.92393818 | CX15: =_xlfn.STDEV.P(AR15,AX15,BD15) -> 0.0016172269 | CZ15: =AVERAGE(BI15,BO15,BU15) -> 1.6899118 | DA15: =AVERAGE(BJ15,BP15,BV15) -> 0.9374015 | DB15: =_xlfn.STDEV.P(BJ15,BP15,BV15) -> 0.0020191592
A16: 1.9997222 | B16: 0.24972222 | D16: =A16*$F$4/$F$1 -> 1.9236963 | E16: -151.62496 | F16: =(F$4+E16)/F$4 -> 0.90444414 | G16: {=INDEX(D$9:D$400,MATCH(MIN(ABS($A16-D$9:D$400)),ABS($A16-D$9:D$400),0))} -> 1.9236963 | H16: =VLOOKUP(G16,D$9:F$400,3) -> 0.90444414 | J16: =$A16*L$4/$F$1 -> 1.9120813 | K16: -142.85334 | L16: =(L$4+K16)/L$4 -> 0.90942523 | M16: {=INDEX(J$9:J$400,MATCH(MIN(ABS($A16-J$9:J$400)),ABS($A16-J$9:J$400),0))} -> 1.9120813 | N16: =VLOOKUP(M16,J$9:L$400,3) -> 0.90942523 | P16: =$A16*R$4/$F$1 -> 1.8881392 | Q16: -141.54633 | R16: =(R$4+Q16)/R$4 -> 0.90911593 | S16: {=INDEX(P$9:P$400,MATCH(MIN(ABS($A16-P$9:P$400)),ABS($A16-P$9:P$400),0))} -> 1.8881392 | T16: =VLOOKUP(S16,P$9:R$400,3) -> 0.90911593 | V16: =$A16*X$4/$F$1 -> 1.9371185 | W16: -112.12099 | X16: =(X$4+W16)/X$4 -> 0.92982961 | Y16: {=INDEX(V$9:V$400,MATCH(MIN(ABS($A16-V$9:V$400)),ABS($A16-V$9:V$400),0))} -> 1.9371185 | Z16: =VLOOKUP(Y16,V$9:X$400,3) -> 0.92982961 | AB16: =$A16*AD$4/$F$1 -> 1.8948477 | AC16: -114.99214 | AD16: =(AD$4+AC16)/AD$4 -> 0.92642725 | AE16: {=INDEX(AB$9:AB$400,MATCH(MIN(ABS($A16-AB$9:AB$400)),ABS($A16-AB$9:AB$400),0))} -> 1.8948477 | AF16: =VLOOKUP(AE16,AB$9:AD$400,3) -> 0.92642725 | AH16: =$A16*AJ$4/$F$1 -> 1.9245502 | AI16: -109.73973 | AJ16: =(AJ$4+AI16)/AJ$4 -> 0.9308714 | AK16: {=INDEX(AH$9:AH$400,MATCH(MIN(ABS($A16-AH$9:AH$400)),ABS($A16-AH$9:AH$400),0))} -> 1.9245502 | AL16: =VLOOKUP(AK16,AH$9:AJ$400,3) -> 0.9308714 | AN16: =$A16*AP$4/$F$1 -> 1.942309 | AO16: -144.17025 | AP16: =(AP$4+AO16)/AP$4 -> 0.91001285 | AQ16: {=INDEX(AN$9:AN$400,MATCH(MIN(ABS($A16-AN$9:AN$400)),ABS($A16-AN$9:AN$400),0))} -> 1.942309 | AR16: =VLOOKUP(AQ16,AN$9:AP$400,3) -> 0.91001285 | AT16: =$A16*AV$4/$F$1 -> 1.9510013 | AU16: -137.63694 | AV16: =(AV$4+AU16)/AV$4 -> 0.91447352 | AW16: {=INDEX(AT$9:AT$400,MATCH(MIN(ABS($A16-AT$9:AT$400)),ABS($A16-AT$9:AT$400),0))} -> 1.9510013 | AX16: =VLOOKUP(AW16,AT$9:AV$400,3) -> 0.91447352 | AZ16: =$A16*BB$4/$F$1 -> 1.9204337 | BA16: -138.65878 | BB16: =(BB$4+BA16)/BB$4 -> 0.91246712 | BC16: {=INDEX(AZ$9:AZ$400,MATCH(MIN(ABS($A16-AZ$9:AZ$400)),ABS($A16-AZ$9:AZ$400),0))} -> 1.9204337 | BD16: =VLOOKUP(BC16,AZ$9:BB$400,3) -> 0.91246712 | BF16: =$A16*BH$4/$F$1 -> 1.9288137 | BG16: -114.00793 | BH16: =(BH$4+BG16)/BH$4 -> 0.92834146 | BI16: {=INDEX(BF$9:BF$400,MATCH(MIN(ABS($A16-BF$9:BF$400)),ABS($A16-BF$9:BF$400),0))} -> 1.9288137 | BJ16: =VLOOKUP(BI16,BF$9:BH$400,3) -> 0.92834146 | BL16: =$A16*BN$4/$F$1 -> 1.933793 | BM16: -112.49434 | BN16: =(BN$4+BM16)/BN$4 -> 0.92947488 | BO16: {=INDEX(BL$9:BL$400,MATCH(MIN(ABS($A16-BL$9:BL$400)),ABS($A16-BL$9:BL$400),0))} -> 1.933793 | BP16: =VLOOKUP(BO16,BL$9:BN$400,3) -> 0.92947488 | BR16: =$A16*BT$4/$F$1 -> 1.9305718 | BS16: -118.71329 | BT16: =(BT$4+BS16)/BT$4 -> 0.92545191 | BU16: {=INDEX(BR$9:BR$400,MATCH(MIN(ABS($A16-BR$9:BR$400)),ABS($A16-BR$9:BR$400),0))} -> 1.9305718 | BV16: =VLOOKUP(BU16,BR$9:BT$400,3) -> 0.92545191 | CI16: =AVERAGE(G16,M16,S16,Y16,AE16,AK16,AQ16,AW16,BC16,BI16,BO16,BU16) -> 1.9239463 | CJ16: =AVERAGE(H16,N16,T16,Z16,AF16,AL16,AR16,AX16,BD16,BJ16,BP16,BV16) -> 0.91919461 | CK16: =_xlfn.STDEV.P(H16,N16,T16,Z16,AF16,AL16,AR16,AX16,BD16,BJ16,BP16,BV16) -> 0.0095599581 | CN16: =AVERAGE(G16,M16,S16) -> 1.9079723 | CO16: =AVERAGE(H16,N16,T16) -> 0.90766177 | CP16: =_xlfn.STDEV.P(H16,N16,T16) -> 0.0022787096 | CR16: =AVERAGE(Y16,AE16,AK16) -> 1.9188388 | CS16: =AVERAGE(Z16,AF16,AL16) -> 0.92904275 | CT16: =_xlfn.STDEV.P(Z16,AF16,AL16) -> 0.0018977126 | CV16: =AVERAGE(AQ16,AW16,BC16) -> 1.9379147 | CW16: =AVERAGE(AR16,AX16,BD16) -> 0.91231783 | CX16: =_xlfn.STDEV.P(AR16,AX16,BD16) -> 0.0018241183 | CZ16: =AVERAGE(BI16,BO16,BU16) -> 1.9310595 | DA16: =AVERAGE(BJ16,BP16,BV16) -> 0.92775608 | DB16: =_xlfn.STDEV.P(BJ16,BP16,BV16) -> 0.0016937304
A17: 2.25 | B17: 0.25027778 | D17: =A17*$F$4/$F$1 -> 2.164459 | E17: -170.02021 | F17: =(F$4+E17)/F$4 -> 0.89285123 | G17: {=INDEX(D$9:D$400,MATCH(MIN(ABS($A17-D$9:D$400)),ABS($A17-D$9:D$400),0))} -> 2.164459 | H17: =VLOOKUP(G17,D$9:F$400,3) -> 0.89285123 | J17: =$A17*L$4/$F$1 -> 2.1513902 | K17: -159.9536 | L17: =(L$4+K17)/L$4 -> 0.89858298 | M17: {=INDEX(J$9:J$400,MATCH(MIN(ABS($A17-J$9:J$400)),ABS($A17-J$9:J$400),0))} -> 2.1513902 | N17: =VLOOKUP(M17,J$9:L$400,3) -> 0.89858298 | P17: =$A17*R$4/$F$1 -> 2.1244516 | Q17: -159.6457 | R17: =(R$4+Q17)/R$4 -> 0.89749469 | S17: {=INDEX(P$9:P$400,MATCH(MIN(ABS($A17-P$9:P$400)),ABS($A17-P$9:P$400),0))} -> 2.3605018 | T17: =VLOOKUP(S17,P$9:R$400,3) -> 0.8863918 | V17: =$A17*X$4/$F$1 -> 2.1795611 | W17: -125.62239 | X17: =(X$4+W17)/X$4 -> 0.92137982 | Y17: {=INDEX(V$9:V$400,MATCH(MIN(ABS($A17-V$9:V$400)),ABS($A17-V$9:V$400),0))} -> 2.1795611 | Z17: =VLOOKUP(Y17,V$9:X$400,3) -> 0.92137982 | AB17: =$A17*AD$4/$F$1 -> 2.1319998 | AC17: -130.16325 | AD17: =(AD$4+AC17)/AD$4 -> 0.91672067 | AE17: {=INDEX(AB$9:AB$400,MATCH(MIN(ABS($A17-AB$9:AB$400)),ABS($A17-AB$9:AB$400),0))} -> 2.1319998 | AF17: =VLOOKUP(AE17,AB$9:AD$400,3) -> 0.91672067 | AH17: =$A17*AJ$4/$F$1 -> 2.1654197 | AI17: -125.59271 | AJ17: =(AJ$4+AI17)/AJ$4 -> 0.92088509 | AK17: {=INDEX(AH$9:AH$400,MATCH(MIN(ABS($A17-AH$9:AH$400)),ABS($A17-AH$9:AH$400),0))} -> 2.1654197 | AL17: =VLOOKUP(AK17,AH$9:AJ$400,3) -> 0.92088509 | AN17: =$A17*AP$4/$F$1 -> 2.1854011 | AO17: -163.31638 | AP17: =(AP$4+AO17)/AP$4 -> 0.89806236 | AQ17: {=INDEX(AN$9:AN$400,MATCH(MIN(ABS($A17-AN$9:AN$400)),ABS($A17-AN$9:AN$400),0))} -> 2.1854011 | AR17: =VLOOKUP(AQ17,AN$9:AP$400,3) -> 0.89806236 | AT17: =$A17*AV$4/$F$1 -> 2.1951814 | AU17: -156.29901 | AV17: =(AV$4+AU17)/AV$4 -> 0.90287706 | AW17: {=INDEX(AT$9:AT$400,MATCH(MIN(ABS($A17-AT$9:AT$400)),ABS($A17-AT$9:AT$400),0))} -> 2.1951814 | AX17: =VLOOKUP(AW17,AT$9:AV$400,3) -> 0.90287706 | AZ17: =$A17*BB$4/$F$1 -> 2.1607881 | BA17: -156.90004 | BB17: =(BB$4+BA17)/BB$4 -> 0.90095173 | BC17: {=INDEX(AZ$9:AZ$400,MATCH(MIN(ABS($A17-AZ$9:AZ$400)),ABS($A17-AZ$9:AZ$400),0))} -> 2.1607881 | BD17: =VLOOKUP(BC17,AZ$9:BB$400,3) -> 0.90095173 | BF17: =$A17*BH$4/$F$1 -> 2.1702168 | BG17: -129.22 | BH17: =(BH$4+BG17)/BH$4 -> 0.91878007 | BI17: {=INDEX(BF$9:BF$400,MATCH(MIN(ABS($A17-BF$9:BF$400)),ABS($A17-BF$9:BF$400),0))} -> 2.1702168 | BJ17: =VLOOKUP(BI17,BF$9:BH$400,3) -> 0.91878007 | BL17: =$A17*BN$4/$F$1 -> 2.1758193 | BM17: -127.65756 | BN17: =(BN$4+BM17)/BN$4 -> 0.91996873 | BO17: {=INDEX(BL$9:BL$400,MATCH(MIN(ABS($A17-BL$9:BL$400)),ABS($A17-BL$9:BL$400),0))} -> 2.1758193 | BP17: =VLOOKUP(BO17,BL$9:BN$400,3) -> 0.91996873 | BR17: =$A17*BT$4/$F$1 -> 2.172195 | BS17: -133.07754 | BT17: =(BT$4+BS17)/BT$4 -> 0.91643162 | BU17: {=INDEX(BR$9:BR$400,MATCH(MIN(ABS($A17-BR$9:BR$400)),ABS($A17-BR$9:BR$400),0))} -> 2.172195 | BV17: =VLOOKUP(BU17,BR$9:BT$400,3) -> 0.91643162 | CI17: =AVERAGE(G17,M17,S17,Y17,AE17,AK17,AQ17,AW17,BC17,BI17,BO17,BU17) -> 2.1844111 | CJ17: =AVERAGE(H17,N17,T17,Z17,AF17,AL17,AR17,AX17,BD17,BJ17,BP17,BV17) -> 0.9078236 | CK17: =_xlfn.STDEV.P(H17,N17,T17,Z17,AF17,AL17,AR17,AX17,BD17,BJ17,BP17,BV17) -> 0.011940944 | CN17: =AVERAGE(G17,M17,S17) -> 2.2254503 | CO17: =AVERAGE(H17,N17,T17) -> 0.89260867 | CP17: =_xlfn.STDEV.P(H17,N17,T17) -> 0.0049799851 | CR17: =AVERAGE(Y17,AE17,AK17) -> 2.1589935 | CS17: =AVERAGE(Z17,AF17,AL17) -> 0.91966186 | CT17: =_xlfn.STDEV.P(Z17,AF17,AL17) -> 0.0020895203 | CV17: =AVERAGE(AQ17,AW17,BC17) -> 2.1804569 | CW17: =AVERAGE(AR17,AX17,BD17) -> 0.90063038 | CX17: =_xlfn.STDEV.P(AR17,AX17,BD17) -> 0.0019786844 | CZ17: =AVERAGE(BI17,BO17,BU17) -> 2.1727437 | DA17: =AVERAGE(BJ17,BP17,BV17) -> 0.91839347 | DB17: =_xlfn.STDEV.P(BJ17,BP17,BV17) -> 0.0014696651
A18: 2.5 | B18: 0.25 | D18: =A18*$F$4/$F$1 -> 2.4049544 | E18: -187.77248 | F18: =(F$4+E18)/F$4 -> 0.88166354 | G18: {=INDEX(D$9:D$400,MATCH(MIN(ABS($A18-D$9:D$400)),ABS($A18-D$9:D$400),0))} -> 2.4049544 | H18: =VLOOKUP(G18,D$9:F$400,3) -> 0.88166354 | J18: =$A18*L$4/$F$1 -> 2.3904336 | K18: -177.17741 | L18: =(L$4+K18)/L$4 -> 0.88766239 | M18: {=INDEX(J$9:J$400,MATCH(MIN(ABS($A18-J$9:J$400)),ABS($A18-J$9:J$400),0))} -> 2.3904336 | N18: =VLOOKUP(M18,J$9:L$400,3) -> 0.88766239 | P18: =$A18*R$4/$F$1 -> 2.3605018 | Q18: -176.93776 | R18: =(R$4+Q18)/R$4 -> 0.8863918 | S18: {=INDEX(P$9:P$400,MATCH(MIN(ABS($A18-P$9:P$400)),ABS($A18-P$9:P$400),0))} -> 2.596552 | T18: =VLOOKUP(S18,P$9:R$400,3) -> 0.87547121 | V18: =$A18*X$4/$F$1 -> 2.4217345 | W18: -139.47729 | X18: =(X$4+W18)/X$4 -> 0.9127088 | Y18: {=INDEX(V$9:V$400,MATCH(MIN(ABS($A18-V$9:V$400)),ABS($A18-V$9:V$400),0))} -> 2.4217345 | Z18: =VLOOKUP(Y18,V$9:X$400,3) -> 0.9127088 | AB18: =$A18*AD$4/$F$1 -> 2.3688887 | AC18: -145.54514 | AD18: =(AD$4+AC18)/AD$4 -> 0.90687923 | AE18: {=INDEX(AB$9:AB$400,MATCH(MIN(ABS($A18-AB$9:AB$400)),ABS($A18-AB$9:AB$400),0))} -> 2.6057775 | AF18: =VLOOKUP(AE18,AB$9:AD$400,3) -> 0.8976096 | AH18: =$A18*AJ$4/$F$1 -> 2.4060219 | AI18: -140.70083 | AJ18: =(AJ$4+AI18)/AJ$4 -> 0.911368 | AK18: {=INDEX(AH$9:AH$400,MATCH(MIN(ABS($A18-AH$9:AH$400)),ABS($A18-AH$9:AH$400),0))} -> 2.4060219 | AL18: =VLOOKUP(AK18,AH$9:AJ$400,3) -> 0.911368 | AN18: =$A18*AP$4/$F$1 -> 2.4282235 | AO18: -182.20302 | AP18: =(AP$4+AO18)/AP$4 -> 0.88627383 | AQ18: {=INDEX(AN$9:AN$400,MATCH(MIN(ABS($A18-AN$9:AN$400)),ABS($A18-AN$9:AN$400),0))} -> 2.4282235 | AR18: =VLOOKUP(AQ18,AN$9:AP$400,3) -> 0.88627383 | AT18: =$A18*AV$4/$F$1 -> 2.4390904 | AU18: -174.42487 | AV18: =(AV$4+AU18)/AV$4 -> 0.8916138 | AW18: {=INDEX(AT$9:AT$400,MATCH(MIN(ABS($A18-AT$9:AT$400)),ABS($A18-AT$9:AT$400),0))} -> 2.4390904 | AX18: =VLOOKUP(AW18,AT$9:AV$400,3) -> 0.8916138 | AZ18: =$A18*BB$4/$F$1 -> 2.4008756 | BA18: -174.35173 | BB18: =(BB$4+BA18)/BB$4 -> 0.88993478 | BC18: {=INDEX(AZ$9:AZ$400,MATCH(MIN(ABS($A18-AZ$9:AZ$400)),ABS($A18-AZ$9:AZ$400),0))} -> 2.4008756 | BD18: =VLOOKUP(BC18,AZ$9:BB$400,3) -> 0.88993478 | BF18: =$A18*BH$4/$F$1 -> 2.411352 | BG18: -143.86554 | BH18: =(BH$4+BG18)/BH$4 -> 0.90957476 | BI18: {=INDEX(BF$9:BF$400,MATCH(MIN(ABS($A18-BF$9:BF$400)),ABS($A18-BF$9:BF$400),0))} -> 2.411352 | BJ18: =VLOOKUP(BI18,BF$9:BH$400,3) -> 0.90957476 | BL18: =$A18*BN$4/$F$1 -> 2.417577 | BM18: -143.73974 | BN18: =(BN$4+BM18)/BN$4 -> 0.90988647 | BO18: {=INDEX(BL$9:BL$400,MATCH(MIN(ABS($A18-BL$9:BL$400)),ABS($A18-BL$9:BL$400),0))} -> 2.417577 | BP18: =VLOOKUP(BO18,BL$9:BN$400,3) -> 0.90988647 | BR18: =$A18*BT$4/$F$1 -> 2.41355 | BS18: -146.10954 | BT18: =(BT$4+BS18)/BT$4 -> 0.90824795 | BU18: {=INDEX(BR$9:BR$400,MATCH(MIN(ABS($A18-BR$9:BR$400)),ABS($A18-BR$9:BR$400),0))} -> 2.41355 | BV18: =VLOOKUP(BU18,BR$9:BT$400,3) -> 0.90824795 | CI18: =AVERAGE(G18,M18,S18,Y18,AE18,AK18,AQ18,AW18,BC18,BI18,BO18,BU18) -> 2.4446785 | CJ18: =AVERAGE(H18,N18,T18,Z18,AF18,AL18,AR18,AX18,BD18,BJ18,BP18,BV18) -> 0.89683459 | CK18: =_xlfn.STDEV.P(H18,N18,T18,Z18,AF18,AL18,AR18,AX18,BD18,BJ18,BP18,BV18) -> 0.012529356 | CN18: =AVERAGE(G18,M18,S18) -> 2.46398 | CO18: =AVERAGE(H18,N18,T18) -> 0.88159905 | CP18: =_xlfn.STDEV.P(H18,N18,T18) -> 0.0049772404 | CR18: =AVERAGE(Y18,AE18,AK18) -> 2.4778446 | CS18: =AVERAGE(Z18,AF18,AL18) -> 0.9072288 | CT18: =_xlfn.STDEV.P(Z18,AF18,AL18) -> 0.0068237927 | CV18: =AVERAGE(AQ18,AW18,BC18) -> 2.4227298 | CW18: =AVERAGE(AR18,AX18,BD18) -> 0.88927414 | CX18: =_xlfn.STDEV.P(AR18,AX18,BD18) -> 0.0022295204 | CZ18: =AVERAGE(BI18,BO18,BU18) -> 2.4141597 | DA18: =AVERAGE(BJ18,BP18,BV18) -> 0.90923639 | DB18: =_xlfn.STDEV.P(BJ18,BP18,BV18) -> 0.00071042431
A19: 2.75 | B19: 0.25 | D19: =A19*$F$4/$F$1 -> 2.6454499 | E19: -204.50625 | F19: =(F$4+E19)/F$4 -> 0.87111772 | G19: {=INDEX(D$9:D$400,MATCH(MIN(ABS($A19-D$9:D$400)),ABS($A19-D$9:D$400),0))} -> 2.6454499 | H19: =VLOOKUP(G19,D$9:F$400,3) -> 0.87111772 | J19: =$A19*L$4/$F$1 -> 2.6294769 | K19: -194.33704 | L19: =(L$4+K19)/L$4 -> 0.8767825 | M19: {=INDEX(J$9:J$400,MATCH(MIN(ABS($A19-J$9:J$400)),ABS($A19-J$9:J$400),0))} -> 2.8682547 | N19: =VLOOKUP(M19,J$9:L$400,3) -> 0.86622473 | P19: =$A19*R$4/$F$1 -> 2.596552 | Q19: -193.94591 | R19: =(R$4+Q19)/R$4 -> 0.87547121 | S19: {=INDEX(P$9:P$400,MATCH(MIN(ABS($A19-P$9:P$400)),ABS($A19-P$9:P$400),0))} -> 2.8323399 | T19: =VLOOKUP(S19,P$9:R$400,3) -> 0.86505011 | V19: =$A19*X$4/$F$1 -> 2.663908 | W19: -154.62749 | X19: =(X$4+W19)/X$4 -> 0.90322712 | Y19: {=INDEX(V$9:V$400,MATCH(MIN(ABS($A19-V$9:V$400)),ABS($A19-V$9:V$400),0))} -> 2.663908 | Z19: =VLOOKUP(Y19,V$9:X$400,3) -> 0.90322712 | AB19: =$A19*AD$4/$F$1 -> 2.6057775 | AC19: -160.03332 | AD19: =(AD$4+AC19)/AD$4 -> 0.8976096 | AE19: {=INDEX(AB$9:AB$400,MATCH(MIN(ABS($A19-AB$9:AB$400)),ABS($A19-AB$9:AB$400),0))} -> 2.8424032 | AF19: =VLOOKUP(AE19,AB$9:AD$400,3) -> 0.88804252 | AH19: =$A19*AJ$4/$F$1 -> 2.6466241 | AI19: -156.65119 | AJ19: =(AJ$4+AI19)/AJ$4 -> 0.90132035 | AK19: {=INDEX(AH$9:AH$400,MATCH(MIN(ABS($A19-AH$9:AH$400)),ABS($A19-AH$9:AH$400),0))} -> 2.6466241 | AL19: =VLOOKUP(AK19,AH$9:AJ$400,3) -> 0.90132035 | AN19: =$A19*AP$4/$F$1 -> 2.6710458 | AO19: -200.85776 | AP19: =(AP$4+AO19)/AP$4 -> 0.87463005 | AQ19: {=INDEX(AN$9:AN$400,MATCH(MIN(ABS($A19-AN$9:AN$400)),ABS($A19-AN$9:AN$400),0))} -> 2.6710458 | AR19: =VLOOKUP(AQ19,AN$9:AP$400,3) -> 0.87463005 | AT19: =$A19*AV$4/$F$1 -> 2.6829995 | AU19: -192.34846 | AV19: =(AV$4+AU19)/AV$4 -> 0.88047622 | AW19: {=INDEX(AT$9:AT$400,MATCH(MIN(ABS($A19-AT$9:AT$400)),ABS($A19-AT$9:AT$400),0))} -> 2.6829995 | AX19: =VLOOKUP(AW19,AT$9:AV$400,3) -> 0.88047622 | AZ19: =$A19*BB$4/$F$1 -> 2.6409632 | BA19: -192.22535 | BB19: =(BB$4+BA19)/BB$4 -> 0.87865148 | BC19: {=INDEX(AZ$9:AZ$400,MATCH(MIN(ABS($A19-AZ$9:AZ$400)),ABS($A19-AZ$9:AZ$400),0))} -> 2.6409632 | BD19: =VLOOKUP(BC19,AZ$9:BB$400,3) -> 0.87865148 | BF19: =$A19*BH$4/$F$1 -> 2.6524872 | BG19: -157.61273 | BH19: =(BH$4+BG19)/BH$4 -> 0.90093411 | BI19: {=INDEX(BF$9:BF$400,MATCH(MIN(ABS($A19-BF$9:BF$400)),ABS($A19-BF$9:BF$400),0))} -> 2.6524872 | BJ19: =VLOOKUP(BI19,BF$9:BH$400,3) -> 0.90093411 | BL19: =$A19*BN$4/$F$1 -> 2.6593347 | BM19: -159.56987 | BN19: =(BN$4+BM19)/BN$4 -> 0.89996222 | BO19: {=INDEX(BL$9:BL$400,MATCH(MIN(ABS($A19-BL$9:BL$400)),ABS($A19-BL$9:BL$400),0))} -> 2.6593347 | BP19: =VLOOKUP(BO19,BL$9:BN$400,3) -> 0.89996222 | BR19: =$A19*BT$4/$F$1 -> 2.654905 | BS19: -161.58148 | BT19: =(BT$4+BS19)/BT$4 -> 0.89853207 | BU19: {=INDEX(BR$9:BR$400,MATCH(MIN(ABS($A19-BR$9:BR$400)),ABS($A19-BR$9:BR$400),0))} -> 2.654905 | BV19: =VLOOKUP(BU19,BR$9:BT$400,3) -> 0.89853207 | CI19: =AVERAGE(G19,M19,S19,Y19,AE19,AK19,AQ19,AW19,BC19,BI19,BO19,BU19) -> 2.7050596 | CJ19: =AVERAGE(H19,N19,T19,Z19,AF19,AL19,AR19,AX19,BD19,BJ19,BP19,BV19) -> 0.88568072 | CK19: =_xlfn.STDEV.P(H19,N19,T19,Z19,AF19,AL19,AR19,AX19,BD19,BJ19,BP19,BV19) -> 0.014067367 | CN19: =AVERAGE(G19,M19,S19) -> 2.7820148 | CO19: =AVERAGE(H19,N19,T19) -> 0.86746418 | CP19: =_xlfn.STDEV.P(H19,N19,T19) -> 0.0026275655 | CR19: =AVERAGE(Y19,AE19,AK19) -> 2.7176451 | CS19: =AVERAGE(Z19,AF19,AL19) -> 0.89753 | CT19: =_xlfn.STDEV.P(Z19,AF19,AL19) -> 0.0067536702 | CV19: =AVERAGE(AQ19,AW19,BC19) -> 2.6650028 | CW19: =AVERAGE(AR19,AX19,BD19) -> 0.87791925 | CX19: =_xlfn.STDEV.P(AR19,AX19,BD19) -> 0.0024422065 | CZ19: =AVERAGE(BI19,BO19,BU19) -> 2.6555756 | DA19: =AVERAGE(BJ19,BP19,BV19) -> 0.89980947 | DB19: =_xlfn.STDEV.P(BJ19,BP19,BV19) -> 0.00098655602
A20: 2.9997222 | B20: 0.24972222 | D20: =A20*$F$4/$F$1 -> 2.8856781 | E20: -221.24002 | F20: =(F$4+E20)/F$4 -> 0.86057189 | G20: {=INDEX(D$9:D$400,MATCH(MIN(ABS($A20-D$9:D$400)),ABS($A20-D$9:D$400),0))} -> 2.8856781 | H20: =VLOOKUP(G20,D$9:F$400,3) -> 0.86057189 | J20: =$A20*L$4/$F$1 -> 2.8682547 | K20: -210.98862 | L20: =(L$4+K20)/L$4 -> 0.86622473 | M20: {=INDEX(J$9:J$400,MATCH(MIN(ABS($A20-J$9:J$400)),ABS($A20-J$9:J$400),0))} -> 3.1075637 | N20: =VLOOKUP(M20,J$9:L$400,3) -> 0.85570944 | P20: =$A20*R$4/$F$1 -> 2.8323399 | Q20: -210.17612 | R20: =(R$4+Q20)/R$4 -> 0.86505011 | S20: {=INDEX(P$9:P$400,MATCH(MIN(ABS($A20-P$9:P$400)),ABS($A20-P$9:P$400),0))} -> 3.0686523 | T20: =VLOOKUP(S20,P$9:R$400,3) -> 0.85421367 | V20: =$A20*X$4/$F$1 -> 2.9058124 | W20: -170.76158 | X20: =(X$4+W20)/X$4 -> 0.89312968 | Y20: {=INDEX(V$9:V$400,MATCH(MIN(ABS($A20-V$9:V$400)),ABS($A20-V$9:V$400),0))} -> 2.9058124 | Z20: =VLOOKUP(Y20,V$9:X$400,3) -> 0.89312968 | AB20: =$A20*AD$4/$F$1 -> 2.8424032 | AC20: -174.98639 | AD20: =(AD$4+AC20)/AD$4 -> 0.88804252 | AE20: {=INDEX(AB$9:AB$400,MATCH(MIN(ABS($A20-AB$9:AB$400)),ABS($A20-AB$9:AB$400),0))} -> 3.0795553 | AF20: =VLOOKUP(AE20,AB$9:AD$400,3) -> 0.87811562 | AH20: =$A20*AJ$4/$F$1 -> 2.8869589 | AI20: -172.80926 | AJ20: =(AJ$4+AI20)/AJ$4 -> 0.89114185 | AK20: {=INDEX(AH$9:AH$400,MATCH(MIN(ABS($A20-AH$9:AH$400)),ABS($A20-AH$9:AH$400),0))} -> 2.8869589 | AL20: =VLOOKUP(AK20,AH$9:AJ$400,3) -> 0.89114185 | AN20: =$A20*AP$4/$F$1 -> 2.9135984 | AO20: -218.84072 | AP20: =(AP$4+AO20)/AP$4 -> 0.86340557 | AQ20: {=INDEX(AN$9:AN$400,MATCH(MIN(ABS($A20-AN$9:AN$400)),ABS($A20-AN$9:AN$400),0))} -> 2.9135984 | AR20: =VLOOKUP(AQ20,AN$9:AP$400,3) -> 0.86340557 | AT20: =$A20*AV$4/$F$1 -> 2.9266375 | AU20: -210.27844 | AV20: =(AV$4+AU20)/AV$4 -> 0.86933468 | AW20: {=INDEX(AT$9:AT$400,MATCH(MIN(ABS($A20-AT$9:AT$400)),ABS($A20-AT$9:AT$400),0))} -> 2.9266375 | AX20: =VLOOKUP(AW20,AT$9:AV$400,3) -> 0.86933468 | AZ20: =$A20*BB$4/$F$1 -> 2.880784 | BA20: -209.29205 | BB20: =(BB$4+BA20)/BB$4 -> 0.86787757 | BC20: {=INDEX(AZ$9:AZ$400,MATCH(MIN(ABS($A20-AZ$9:AZ$400)),ABS($A20-AZ$9:AZ$400),0))} -> 2.880784 | BD20: =VLOOKUP(BC20,AZ$9:BB$400,3) -> 0.86787757 | BF20: =$A20*BH$4/$F$1 -> 2.8933545 | BG20: -172.5802 | BH20: =(BH$4+BG20)/BH$4 -> 0.89152645 | BI20: {=INDEX(BF$9:BF$400,MATCH(MIN(ABS($A20-BF$9:BF$400)),ABS($A20-BF$9:BF$400),0))} -> 2.8933545 | BJ20: =VLOOKUP(BI20,BF$9:BH$400,3) -> 0.89152645 | BL20: =$A20*BN$4/$F$1 -> 2.9008238 | BM20: -175.36756 | BN20: =(BN$4+BM20)/BN$4 -> 0.89005831 | BO20: {=INDEX(BL$9:BL$400,MATCH(MIN(ABS($A20-BL$9:BL$400)),ABS($A20-BL$9:BL$400),0))} -> 2.9008238 | BP20: =VLOOKUP(BO20,BL$9:BN$400,3) -> 0.89005831 | BR20: =$A20*BT$4/$F$1 -> 2.8959918 | BS20: -177.71088 | BT20: =(BT$4+BS20)/BT$4 -> 0.88840334 | BU20: {=INDEX(BR$9:BR$400,MATCH(MIN(ABS($A20-BR$9:BR$400)),ABS($A20-BR$9:BR$400),0))} -> 2.8959918 | BV20: =VLOOKUP(BU20,BR$9:BT$400,3) -> 0.88840334 | CI20: =AVERAGE(G20,M20,S20,Y20,AE20,AK20,AQ20,AW20,BC20,BI20,BO20,BU20) -> 2.9454509 | CJ20: =AVERAGE(H20,N20,T20,Z20,AF20,AL20,AR20,AX20,BD20,BJ20,BP20,BV20) -> 0.87529067 | CK20: =_xlfn.STDEV.P(H20,N20,T20,Z20,AF20,AL20,AR20,AX20,BD20,BJ20,BP20,BV20) -> 0.0144542 | CN20: =AVERAGE(G20,M20,S20) -> 3.0206314 | CO20: =AVERAGE(H20,N20,T20) -> 0.85683167 | CP20: =_xlfn.STDEV.P(H20,N20,T20) -> 0.0027143182 | CR20: =AVERAGE(Y20,AE20,AK20) -> 2.9574422 | CS20: =AVERAGE(Z20,AF20,AL20) -> 0.88746239 | CT20: =_xlfn.STDEV.P(Z20,AF20,AL20) -> 0.0066587954 | CV20: =AVERAGE(AQ20,AW20,BC20) -> 2.9070066 | CW20: =AVERAGE(AR20,AX20,BD20) -> 0.86687261 | CX20: =_xlfn.STDEV.P(AR20,AX20,BD20) -> 0.0025227005 | CZ20: =AVERAGE(BI20,BO20,BU20) -> 2.8967234 | DA20: =AVERAGE(BJ20,BP20,BV20) -> 0.88999603 | DB20: =_xlfn.STDEV.P(BJ20,BP20,BV20) -> 0.0012757659
A21: 3.25 | B21: 0.25027778 | D21: =A21*$F$4/$F$1 -> 3.1264408 | E21: -238.09813 | F21: =(F$4+E21)/F$4 -> 0.84994771 | G21: {=INDEX(D$9:D$400,MATCH(MIN(ABS($A21-D$9:D$400)),ABS($A21-D$9:D$400),0))} -> 3.3669362 | H21: =VLOOKUP(G21,D$9:F$400,3) -> 0.83820843 | J21: =$A21*L$4/$F$1 -> 3.1075637 | K21: -227.5732 | L21: =(L$4+K21)/L$4 -> 0.85570944 | M21: {=INDEX(J$9:J$400,MATCH(MIN(ABS($A21-J$9:J$400)),ABS($A21-J$9:J$400),0))} -> 3.346607 | N21: =VLOOKUP(M21,J$9:L$400,3) -> 0.84462809 | P21: =$A21*R$4/$F$1 -> 3.0686523 | Q21: -227.0532 | R21: =(R$4+Q21)/R$4 -> 0.85421367 | S21: {=INDEX(P$9:P$400,MATCH(MIN(ABS($A21-P$9:P$400)),ABS($A21-P$9:P$400),0))} -> 3.3047025 | T21: =VLOOKUP(S21,P$9:R$400,3) -> 0.84268829 | V21: =$A21*X$4/$F$1 -> 3.1482549 | W21: -186.3029 | X21: =(X$4+W21)/X$4 -> 0.88340322 | Y21: {=INDEX(V$9:V$400,MATCH(MIN(ABS($A21-V$9:V$400)),ABS($A21-V$9:V$400),0))} -> 3.1482549 | Z21: =VLOOKUP(Y21,V$9:X$400,3) -> 0.88340322 | AB21: =$A21*AD$4/$F$1 -> 3.0795553 | AC21: -190.50185 | AD21: =(AD$4+AC21)/AD$4 -> 0.87811562 | AE21: {=INDEX(AB$9:AB$400,MATCH(MIN(ABS($A21-AB$9:AB$400)),ABS($A21-AB$9:AB$400),0))} -> 3.3164441 | AF21: =VLOOKUP(AE21,AB$9:AD$400,3) -> 0.86802806 | AH21: =$A21*AJ$4/$F$1 -> 3.1278285 | AI21: -189.01543 | AJ21: =(AJ$4+AI21)/AJ$4 -> 0.88093307 | AK21: {=INDEX(AH$9:AH$400,MATCH(MIN(ABS($A21-AH$9:AH$400)),ABS($A21-AH$9:AH$400),0))} -> 3.3684306 | AL21: =VLOOKUP(AK21,AH$9:AJ$400,3) -> 0.8705175 | AN21: =$A21*AP$4/$F$1 -> 3.1566905 | AO21: -236.83094 | AP21: =(AP$4+AO21)/AP$4 -> 0.85217657 | AQ21: {=INDEX(AN$9:AN$400,MATCH(MIN(ABS($A21-AN$9:AN$400)),ABS($A21-AN$9:AN$400),0))} -> 3.1566905 | AR21: =VLOOKUP(AQ21,AN$9:AP$400,3) -> 0.85217657 | AT21: =$A21*AV$4/$F$1 -> 3.1708176 | AU21: -227.51566 | AV21: =(AV$4+AU21)/AV$4 -> 0.85862361 | AW21: {=INDEX(AT$9:AT$400,MATCH(MIN(ABS($A21-AT$9:AT$400)),ABS($A21-AT$9:AT$400),0))} -> 3.1708176 | AX21: =VLOOKUP(AW21,AT$9:AV$400,3) -> 0.85862361 | AZ21: =$A21*BB$4/$F$1 -> 3.1211383 | BA21: -225.86717 | BB21: =(BB$4+BA21)/BB$4 -> 0.85741398 | BC21: {=INDEX(AZ$9:AZ$400,MATCH(MIN(ABS($A21-AZ$9:AZ$400)),ABS($A21-AZ$9:AZ$400),0))} -> 3.3612259 | BD21: =VLOOKUP(BC21,AZ$9:BB$400,3) -> 0.84653575 | BF21: =$A21*BH$4/$F$1 -> 3.1347576 | BG21: -186.6175 | BH21: =(BH$4+BG21)/BH$4 -> 0.88270344 | BI21: {=INDEX(BF$9:BF$400,MATCH(MIN(ABS($A21-BF$9:BF$400)),ABS($A21-BF$9:BF$400),0))} -> 3.1347576 | BJ21: =VLOOKUP(BI21,BF$9:BH$400,3) -> 0.88270344 | BL21: =$A21*BN$4/$F$1 -> 3.1428501 | BM21: -191.54855 | BN21: =(BN$4+BM21)/BN$4 -> 0.87991409 | BO21: {=INDEX(BL$9:BL$400,MATCH(MIN(ABS($A21-BL$9:BL$400)),ABS($A21-BL$9:BL$400),0))} -> 3.1428501 | BP21: =VLOOKUP(BO21,BL$9:BN$400,3) -> 0.87991409 | BR21: =$A21*BT$4/$F$1 -> 3.137615 | BS21: -194.30767 | BT21: =(BT$4+BS21)/BT$4 -> 0.87798109 | BU21: {=INDEX(BR$9:BR$400,MATCH(MIN(ABS($A21-BR$9:BR$400)),ABS($A21-BR$9:BR$400),0))} -> 3.137615 | BV21: =VLOOKUP(BU21,BR$9:BT$400,3) -> 0.87798109 | CI21: =AVERAGE(G21,M21,S21,Y21,AE21,AK21,AQ21,AW21,BC21,BI21,BO21,BU21) -> 3.2462777 | CJ21: =AVERAGE(H21,N21,T21,Z21,AF21,AL21,AR21,AX21,BD21,BJ21,BP21,BV21) -> 0.86211735 | CK21: =_xlfn.STDEV.P(H21,N21,T21,Z21,AF21,AL21,AR21,AX21,BD21,BJ21,BP21,BV21) -> 0.016226439 | CN21: =AVERAGE(G21,M21,S21) -> 3.3394152 | CO21: =AVERAGE(H21,N21,T21) -> 0.8418416 | CP21: =_xlfn.STDEV.P(H21,N21,T21) -> 0.002688326 | CR21: =AVERAGE(Y21,AE21,AK21) -> 3.2777099 | CS21: =AVERAGE(Z21,AF21,AL21) -> 0.87398293 | CT21: =_xlfn.STDEV.P(Z21,AF21,AL21) -> 0.0067382348 | CV21: =AVERAGE(AQ21,AW21,BC21) -> 3.229578 | CW21: =AVERAGE(AR21,AX21,BD21) -> 0.85244531 | CX21: =_xlfn.STDEV.P(AR21,AX21,BD21) -> 0.0049385078 | CZ21: =AVERAGE(BI21,BO21,BU21) -> 3.1384076 | DA21: =AVERAGE(BJ21,BP21,BV21) -> 0.88019954 | DB21: =_xlfn.STDEV.P(BJ21,BP21,BV21) -> 0.0019384294
... A158: 51.75 | B158: 0.5 | D158: =A158*$F$4/$F$1 -> 49.782557 | E158: -594.94963 | F158: =(F$4+E158)/F$4 -> 0.62505563 | G158: {=INDEX(D$9:D$400,MATCH(MIN(ABS($A158-D$9:D$400)),ABS($A158-D$9:D$400),0))} -> 51.70652 | H158: =VLOOKUP(G158,D$9:F$400,3) -> 0.62225288 | J158: =$A158*L$4/$F$1 -> 49.481975 | K158: -606.44555 | L158: =(L$4+K158)/L$4 -> 0.61548913 | M158: {=INDEX(J$9:J$400,MATCH(MIN(ABS($A158-J$9:J$400)),ABS($A158-J$9:J$400),0))} -> 51.872409 | N158: =VLOOKUP(M158,J$9:L$400,3) -> 0.61240052 | P158: =$A158*R$4/$F$1 -> 48.862387 | Q158: -617.56769 | R158: =(R$4+Q158)/R$4 -> 0.60347212 | S158: {=INDEX(P$9:P$400,MATCH(MIN(ABS($A158-P$9:P$400)),ABS($A158-P$9:P$400),0))} -> 51.694989 | T158: =VLOOKUP(S158,P$9:R$400,3) -> 0.59823914 | V158: =$A158*X$4/$F$1 -> 50.129905 | W158: -553.66349 | X158: =(X$4+W158)/X$4 -> 0.65349234 | Y158: {=INDEX(V$9:V$400,MATCH(MIN(ABS($A158-V$9:V$400)),ABS($A158-V$9:V$400),0))} -> 51.582945 | Z158: =VLOOKUP(Y158,V$9:X$400,3) -> 0.65162494 | AB158: =$A158*AD$4/$F$1 -> 49.035995 | AC158: -562.91628 | AD158: =(AD$4+AC158)/AD$4 -> 0.63984234 | AE158: {=INDEX(AB$9:AB$400,MATCH(MIN(ABS($A158-AB$9:AB$400)),ABS($A158-AB$9:AB$400),0))} -> 51.878662 | AF158: =VLOOKUP(AE158,AB$9:AD$400,3) -> 0.63597042 | AH158: =$A158*AJ$4/$F$1 -> 49.804653 | AI158: -512.74123 | AJ158: =(AJ$4+AI158)/AJ$4 -> 0.67700771 | AK158: {=INDEX(AH$9:AH$400,MATCH(MIN(ABS($A158-AH$9:AH$400)),ABS($A158-AH$9:AH$400),0))} -> 51.729471 | AL158: =VLOOKUP(AK158,AH$9:AJ$400,3) -> 0.67429938 | AN158: =$A158*AP$4/$F$1 -> 50.264226 | AO158: -621.14513 | AP158: =(AP$4+AO158)/AP$4 -> 0.61229811 | AQ158: {=INDEX(AN$9:AN$400,MATCH(MIN(ABS($A158-AN$9:AN$400)),ABS($A158-AN$9:AN$400),0))} -> 51.72116 | AR158: =VLOOKUP(AQ158,AN$9:AP$400,3) -> 0.61033986 | AT158: =$A158*AV$4/$F$1 -> 50.489172 | AU158: -616.51811 | AV158: =(AV$4+AU158)/AV$4 -> 0.61690064 | AW158: {=INDEX(AT$9:AT$400,MATCH(MIN(ABS($A158-AT$9:AT$400)),ABS($A158-AT$9:AT$400),0))} -> 51.952626 | AX158: =VLOOKUP(AW158,AT$9:AV$400,3) -> 0.61474808 | AZ158: =$A158*BB$4/$F$1 -> 49.698125 | BA158: -568.26419 | BB158: =(BB$4+BA158)/BB$4 -> 0.64126469 | BC158: {=INDEX(AZ$9:AZ$400,MATCH(MIN(ABS($A158-AZ$9:AZ$400)),ABS($A158-AZ$9:AZ$400),0))} -> 51.618826 | BD158: =VLOOKUP(BC158,AZ$9:BB$400,3) -> 0.63763565 | BF158: =$A158*BH$4/$F$1 -> 49.914986 | BG158: -574.07004 | BH158: =(BH$4+BG158)/BH$4 -> 0.63917405 | BI158: {=INDEX(BF$9:BF$400,MATCH(MIN(ABS($A158-BF$9:BF$400)),ABS($A158-BF$9:BF$400),0))} -> 51.844068 | BJ158: =VLOOKUP(BI158,BF$9:BH$400,3) -> 0.63278759 | BL158: =$A158*BN$4/$F$1 -> 50.043844 | BM158: -564.46369 | BN158: =(BN$4+BM158)/BN$4 -> 0.64612557 | BO158: {=INDEX(BL$9:BL$400,MATCH(MIN(ABS($A158-BL$9:BL$400)),ABS($A158-BL$9:BL$400),0))} -> 51.977906 | BP158: =VLOOKUP(BO158,BL$9:BN$400,3) -> 0.6391414 | BR158: =$A158*BT$4/$F$1 -> 49.960485 | BS158: -569.00449 | BT158: =(BT$4+BS158)/BT$4 -> 0.64268366 | BU158: {=INDEX(BR$9:BR$400,MATCH(MIN(ABS($A158-BR$9:BR$400)),ABS($A158-BR$9:BR$400),0))} -> 51.891325 | BV158: =VLOOKUP(BU158,BR$9:BT$400,3) -> 0.63604568 | CI158: =AVERAGE(G158,M158,S158,Y158,AE158,AK158,AQ158,AW158,BC158,BI158,BO158,BU158) -> 51.789242 | CJ158: =AVERAGE(H158,N158,T158,Z158,AF158,AL158,AR158,AX158,BD158,BJ158,BP158,BV158) -> 0.63045713 | CK158: =_xlfn.STDEV.P(H158,N158,T158,Z158,AF158,AL158,AR158,AX158,BD158,BJ158,BP158,BV158) -> 0.019678785 | CN158: =AVERAGE(G158,M158,S158) -> 51.757973 | CO158: =AVERAGE(H158,N158,T158) -> 0.61096418 | CP158: =_xlfn.STDEV.P(H158,N158,T158) -> 0.0098560401 | CR158: =AVERAGE(Y158,AE158,AK158) -> 51.730359 | CS158: =AVERAGE(Z158,AF158,AL158) -> 0.65396492 | CT158: =_xlfn.STDEV.P(Z158,AF158,AL158) -> 0.015734969 | CV158: =AVERAGE(AQ158,AW158,BC158) -> 51.764204 | CW158: =AVERAGE(AR158,AX158,BD158) -> 0.62090786 | CX158: =_xlfn.STDEV.P(AR158,AX158,BD158) -> 0.011964456 | CZ158: =AVERAGE(BI158,BO158,BU158) -> 51.904433 | DA158: =AVERAGE(BJ158,BP158,BV158) -> 0.63599155 | DB158: =_xlfn.STDEV.P(BJ158,BP158,BV158) -> 0.0025942135
A159: 52.25 | B159: 0.5 | D159: =A159*$F$4/$F$1 -> 50.263548 | E159: -596.06634 | F159: =(F$4+E159)/F$4 -> 0.62435186 | G159: {=INDEX(D$9:D$400,MATCH(MIN(ABS($A159-D$9:D$400)),ABS($A159-D$9:D$400),0))} -> 52.187511 | H159: =VLOOKUP(G159,D$9:F$400,3) -> 0.6215979 | J159: =$A159*L$4/$F$1 -> 49.960062 | K159: -607.38605 | L159: =(L$4+K159)/L$4 -> 0.61489281 | M159: {=INDEX(J$9:J$400,MATCH(MIN(ABS($A159-J$9:J$400)),ABS($A159-J$9:J$400),0))} -> 52.350495 | N159: =VLOOKUP(M159,J$9:L$400,3) -> 0.61179341 | P159: =$A159*R$4/$F$1 -> 49.334487 | Q159: -618.94384 | R159: =(R$4+Q159)/R$4 -> 0.60258853 | S159: {=INDEX(P$9:P$400,MATCH(MIN(ABS($A159-P$9:P$400)),ABS($A159-P$9:P$400),0))} -> 52.16709 | T159: =VLOOKUP(S159,P$9:R$400,3) -> 0.59740263 | V159: =$A159*X$4/$F$1 -> 50.614252 | W159: -554.67806 | X159: =(X$4+W159)/X$4 -> 0.65285737 | Y159: {=INDEX(V$9:V$400,MATCH(MIN(ABS($A159-V$9:V$400)),ABS($A159-V$9:V$400),0))} -> 52.067292 | Z159: =VLOOKUP(Y159,V$9:X$400,3) -> 0.6509837 | AB159: =$A159*AD$4/$F$1 -> 49.509773 | AC159: -563.96812 | AD159: =(AD$4+AC159)/AD$4 -> 0.63916937 | AE159: {=INDEX(AB$9:AB$400,MATCH(MIN(ABS($A159-AB$9:AB$400)),ABS($A159-AB$9:AB$400),0))} -> 52.352439 | AF159: =VLOOKUP(AE159,AB$9:AD$400,3) -> 0.63534176 | AH159: =$A159*AJ$4/$F$1 -> 50.285857 | AI159: -513.76451 | AJ159: =(AJ$4+AI159)/AJ$4 -> 0.67636311 | AK159: {=INDEX(AH$9:AH$400,MATCH(MIN(ABS($A159-AH$9:AH$400)),ABS($A159-AH$9:AH$400),0))} -> 52.210675 | AL159: =VLOOKUP(AK159,AH$9:AJ$400,3) -> 0.67366867 | AN159: =$A159*AP$4/$F$1 -> 50.749871 | AO159: -622.10893 | AP159: =(AP$4+AO159)/AP$4 -> 0.61169653 | AQ159: {=INDEX(AN$9:AN$400,MATCH(MIN(ABS($A159-AN$9:AN$400)),ABS($A159-AN$9:AN$400),0))} -> 52.206805 | AR159: =VLOOKUP(AQ159,AN$9:AP$400,3) -> 0.60974818 | AT159: =$A159*AV$4/$F$1 -> 50.97699 | AU159: -617.73245 | AV159: =(AV$4+AU159)/AV$4 -> 0.61614606 | AW159: {=INDEX(AT$9:AT$400,MATCH(MIN(ABS($A159-AT$9:AT$400)),ABS($A159-AT$9:AT$400),0))} -> 52.440444 | AX159: =VLOOKUP(AW159,AT$9:AV$400,3) -> 0.61404852 | AZ159: =$A159*BB$4/$F$1 -> 50.1783 | BA159: -569.73126 | BB159: =(BB$4+BA159)/BB$4 -> 0.64033856 | BC159: {=INDEX(AZ$9:AZ$400,MATCH(MIN(ABS($A159-AZ$9:AZ$400)),ABS($A159-AZ$9:AZ$400),0))} -> 52.099001 | BD159: =VLOOKUP(BC159,AZ$9:BB$400,3) -> 0.63672481 | BF159: =$A159*BH$4/$F$1 -> 50.397257 | BG159: -576.71676 | BH159: =(BH$4+BG159)/BH$4 -> 0.63751048 | BI159: {=INDEX(BF$9:BF$400,MATCH(MIN(ABS($A159-BF$9:BF$400)),ABS($A159-BF$9:BF$400),0))} -> 52.326338 | BJ159: =VLOOKUP(BI159,BF$9:BH$400,3) -> 0.63130027 | BL159: =$A159*BN$4/$F$1 -> 50.52736 | BM159: -567.11579 | BN159: =(BN$4+BM159)/BN$4 -> 0.64446291 | BO159: {=INDEX(BL$9:BL$400,MATCH(MIN(ABS($A159-BL$9:BL$400)),ABS($A159-BL$9:BL$400),0))} -> 52.461421 | BP159: =VLOOKUP(BO159,BL$9:BN$400,3) -> 0.63727043 | BR159: =$A159*BT$4/$F$1 -> 50.443195 | BS159: -571.54212 | BT159: =(BT$4+BS159)/BT$4 -> 0.64109011 | BU159: {=INDEX(BR$9:BR$400,MATCH(MIN(ABS($A159-BR$9:BR$400)),ABS($A159-BR$9:BR$400),0))} -> 52.374035 | BV159: =VLOOKUP(BU159,BR$9:BT$400,3) -> 0.63442696
