Workbook

Sheet Marine Impeller
A1: Marine Impeller | G1: 27 | H1: 24 | I1: 25
G2: 46 | H2: 50 | I2: 56
B4: 15 minutes mixing | O4: 30 minutes mixing | AB4: 45 minutes mixing
B5: Series 1 | E5: Series 2 | H5: Series 3 | K5: Across Series | O5: Series 1 | R5: Series 2 | U5: Series 3 | X5: Across Series | AB5: Series 1 | AE5: Series 2 | AH5: Series 3 | AK5: Across Series
B6: Time | C6: Average | D6: St. Dev. | E6: Time | F6: Average | G6: St. Dev. | H6: Time | I6: Average | J6: St. Dev. | K6: Time | L6: Average | M6: St. Dev. | O6: Time | P6: Average | Q6: St. Dev. | R6: Time | S6: Average | T6: St. Dev. | U6: Time | V6: Average | W6: St. Dev. | X6: Time | Y6: Average | Z6: St. Dev. | AB6: Time | AC6: Average | AD6: St. Dev. | AE6: Time | AF6: Average | AG6: St. Dev. | AH6: Time | AI6: Average | AJ6: St. Dev. | AK6: Time | AL6: Average | AM6: St. Dev.
A7: Settlement | D7: =AVERAGE(D15:D26) -> 0.011131965 | G7: =AVERAGE(G15:G26) -> 0.0050781379 | J7: =AVERAGE(J15:J26) -> 0.00072806497 | M7: =AVERAGE(M15:M26) -> 0.012504824 | Q7: =AVERAGE(Q15:Q23) -> 0.0019105889 | T7: =AVERAGE(T15:T23) -> 0.0004224556 | W7: =AVERAGE(W15:W23) -> 0.0025264763 | Z7: =AVERAGE(Z15:Z23) -> 0.0077638601 | AD7: =AVERAGE(AD15:AD24) -> 0.0030582171 | AG7: =AVERAGE(AG15:AG24) -> 0.0043521615 | AJ7: =AVERAGE(AJ15:AJ24) -> 0.0014737049 | AM7: =AVERAGE(AM15:AM24) -> 0.0041203561
A8: Hindered Settling | D8: =AVERAGE(D27:D45) -> 0.0078654711 | G8: =AVERAGE(G27:G45) -> 0.0054964058 | J8: =AVERAGE(J27:J45) -> 0.003530669 | M8: =AVERAGE(M27:M45) -> 0.019089054 | Q8: =AVERAGE(Q24:Q49) -> 0.019179601 | T8: =AVERAGE(T24:T49) -> 0.020396921 | W8: =AVERAGE(W24:W49) -> 0.0042009176 | Z8: =AVERAGE(Z24:Z49) -> 0.018837773 | AD8: =AVERAGE(AD25:AD55) -> 0.0065345494 | AG8: =AVERAGE(AG25:AG55) -> 0.0095623918 | AJ8: =AVERAGE(AJ25:AJ55) -> 0.0066774361 | AM8: =AVERAGE(AM25:AM55) -> 0.012593483
A9: Consolidation | D9: =AVERAGE(D46:D178) -> 0.0086541146 | G9: =AVERAGE(G46:G178) -> 0.0069906713 | J9: =AVERAGE(J46:J178) -> 0.0042197479 | M9: =AVERAGE(M46:M178) -> 0.021619244 | Q9: =AVERAGE(Q50:Q178) -> 0.019638814 | T9: =AVERAGE(T50:T178) -> 0.02153587 | W9: =AVERAGE(W50:W178) -> 0.0034411541 | Z9: =AVERAGE(Z50:Z178) -> 0.018414779 | AD9: =AVERAGE(AD56:AD178) -> 0.0086482941 | AG9: =AVERAGE(AG56:AG178) -> 0.0094988656 | AJ9: =AVERAGE(AJ56:AJ178) -> 0.0068728438 | AM9: =AVERAGE(AM56:AM178) -> 0.013338061
M11: ='[1]MA 15'!$BU$4 -> 1665.8502 | Z11: ='[1]MA 30'!$BU$4 -> 1661.4437 | AM11: ='[1]MA 45'!$BU$4 -> 1655.5838 | BB11: Settling Phase | BK11: Consolidation Phase
B12: 15 minutes mixing | O12: 30 minutes mixing | AB12: 45 minutes mixing | BB12: 15 min | BE12: 30 min | BH12: 45 min | BK12: 15 min - Power law | BO12: 30 min - Power law | BS12: 45 min - Power law
A13: Time | B13: Series 1 | E13: Series 2 | H13: Series 3 | K13: Across Series | O13: Series 1 | R13: Series 2 | U13: Series 3 | X13: Across Series | AB13: Series 1 | AE13: Series 2 | AH13: Series 3 | AK13: Across Series | BB13: Settle | BC13: Delta | BE13: Settle | BF13: Delta | BH13: Settle | BI13: Delta | BK13: Data | BL13: EQ | BM13: Delta | BO13: Data | BP13: EQ | BQ13: Delta | BS13: Data | BT13: EQ | BU13: Delta
A14: [hrs] | B14: Time | C14: Average | D14: St. Dev. | E14: Time | F14: Average | G14: St. Dev. | H14: Time | I14: Average | J14: St. Dev. | K14: Time | L14: Average | M14: St. Dev. | O14: Time | P14: Average | Q14: St. Dev. | R14: Time | S14: Average | T14: St. Dev. | U14: Time | V14: Average | W14: St. Dev. | X14: Time | Y14: Average | Z14: St. Dev. | AB14: Time | AC14: Average | AD14: St. Dev. | AE14: Time | AF14: Average | AG14: St. Dev. | AH14: Time | AI14: Average | AJ14: St. Dev. | AK14: Time | AL14: Average | AM14: St. Dev.
A15: 0.24972222 | B15: ='[1]MA 15'!BX9 -> 0.25263648 | C15: ='[1]MA 15'!BY9 -> 0.97909086 | D15: ='[1]MA 15'!BZ9 -> 0.0088174765 | E15: ='[1]MA 15'!CC9 -> 0.25167384 | F15: ='[1]MA 15'!CD9 -> 0.99012297 | G15: ='[1]MA 15'!CE9 -> 0.0044220341 | H15: ='[1]MA 15'!CH9 -> 0.25229233 | I15: ='[1]MA 15'!CI9 -> 0.98765479 | J15: ='[1]MA 15'!CJ9 -> 0.00042771893 | K15: ='[1]MA 15'!BS9 -> 0.25220089 | L15: ='[1]MA 15'!BT9 -> 0.98562287 | M15: ='[1]MA 15'!BU9 -> 0.0074056728 | O15: ='[1]MA 30'!BX9 -> 0.25123201 | P15: ='[1]MA 30'!BY9 -> 0.98590941 | Q15: ='[1]MA 30'!BZ9 -> 0.0011289204 | R15: ='[1]MA 30'!CC9 -> 0.25319956 | S15: ='[1]MA 30'!CD9 -> 0.9831127 | T15: ='[1]MA 30'!CE9 -> 0.00014244551 | U15: ='[1]MA 30'!CH9 -> 0.25016976 | V15: ='[1]MA 30'!CI9 -> 0.9906167 | W15: ='[1]MA 30'!CJ9 -> 0.0016486052 | X15: ='[1]MA 30'!BS9 -> 0.25153378 | Y15: ='[1]MA 30'!BT9 -> 0.98654627 | Z15: ='[1]MA 30'!BU9 -> 0.0033053515 | AB15: ='[1]MA 45'!BX9 -> 0.25144741 | AC15: ='[1]MA 45'!BY9 -> 0.98683452 | AD15: ='[1]MA 45'!BZ9 -> 0.00057581037 | AE15: ='[1]MA 45'!CC9 -> 0.25134697 | AF15: ='[1]MA 45'!CD9 -> 0.99001855 | AG15: ='[1]MA 45'!CE9 -> 0.0035784932 | AH15: ='[1]MA 45'!CH9 -> 0.24914546 | AI15: ='[1]MA 45'!CI9 -> 0.99045016 | AJ15: ='[1]MA 45'!CJ9 -> 0.00084011206 | AK15: ='[1]MA 45'!BS9 -> 0.25064662 | AL15: ='[1]MA 45'!BT9 -> 0.98910108 | AM15: ='[1]MA 45'!BU9 -> 0.0026858891 | BB15: =-0.0628*A15 + 1.0018 -> 0.98611744 | BC15: =(BB15-L15)*100 -> 0.04945711 | BE15: =-0.0657*A15 + 1.0023 -> 0.98589325 | BF15: =(BE15-Y15)*100 -> -0.065301852 | BH15: =-0.0645*A15 + 1.0053 -> 0.98919292 | BI15: =(BH15-AL15)*100 -> 0.0091840965 | BK15: =L15 -> 0.98562287 | BL15: =0.8243*A15^(-0.083) -> 0.92490335 | BM15: =(BK15-BL15)*100 -> 6.0719522 | BO15: =Y15 -> 0.98654627 | BP15: =0.8574*A15^(-0.085) -> 0.9647163 | BQ15: =(BO15-BP15)*100 -> 2.1829965 | BS15: =AL15 -> 0.98910108 | BT15: =0.8819*A15^(-0.087) -> 0.99504006 | BU15: =(BS15-BT15)*100 -> -0.59389874
A16: 0.5 | B16: ='[1]MA 15'!BX10 -> 0.505835 | C16: ='[1]MA 15'!BY10 -> 0.96444698 | D16: ='[1]MA 15'!BZ10 -> 0.009770666 | E16: ='[1]MA 15'!CC10 -> 0.50390759 | F16: ='[1]MA 15'!CD10 -> 0.97358277 | G16: ='[1]MA 15'!CE10 -> 0.0057474586 | H16: ='[1]MA 15'!CH10 -> 0.50514593 | I16: ='[1]MA 15'!CI10 -> 0.97467717 | J16: ='[1]MA 15'!CJ10 -> 0.00065049397 | K16: ='[1]MA 15'!BS10 -> 0.50496284 | L16: ='[1]MA 15'!BT10 -> 0.97090231 | M16: ='[1]MA 15'!BU10 -> 0.0080005845 | O16: ='[1]MA 30'!BX10 -> 0.50302294 | P16: ='[1]MA 30'!BY10 -> 0.96901253 | Q16: ='[1]MA 30'!BZ10 -> 0.0014428325 | R16: ='[1]MA 30'!CC10 -> 0.50696241 | S16: ='[1]MA 30'!CD10 -> 0.96492174 | T16: ='[1]MA 30'!CE10 -> 0.00038544791 | U16: ='[1]MA 30'!CH10 -> 0.50089607 | V16: ='[1]MA 30'!CI10 -> 0.97680472 | W16: ='[1]MA 30'!CJ10 -> 0.0023309398 | X16: ='[1]MA 30'!BS10 -> 0.50362714 | Y16: ='[1]MA 30'!BT10 -> 0.97024633 | Z16: ='[1]MA 30'!BU10 -> 0.0051816855 | AB16: ='[1]MA 45'!BX10 -> 0.50345422 | AC16: ='[1]MA 45'!BY10 -> 0.97011383 | AD16: ='[1]MA 45'!BZ10 -> 0.0013545503 | AE16: ='[1]MA 45'!CC10 -> 0.50325312 | AF16: ='[1]MA 45'!CD10 -> 0.9763445 | AG16: ='[1]MA 45'!CE10 -> 0.0060986863 | AH16: ='[1]MA 45'!CH10 -> 0.49884519 | AI16: ='[1]MA 45'!CI10 -> 0.97670617 | AJ16: ='[1]MA 45'!CJ10 -> 0.00136155 | AK16: ='[1]MA 45'!BS10 -> 0.50185084 | AL16: ='[1]MA 45'!BT10 -> 0.97438817 | AM16: ='[1]MA 45'!BU10 -> 0.0047732925 | BB16: =-0.0628*A16 + 1.0018 -> 0.9704 | BC16: =(BB16-L16)*100 -> -0.050231159 | BE16: =-0.0657*A16 + 1.0023 -> 0.96945 | BF16: =(BE16-Y16)*100 -> -0.079633126 | BH16: =-0.0645*A16 + 1.0053 -> 0.97305 | BI16: =(BH16-AL16)*100 -> -0.13381658 | BK16: =L16 -> 0.97090231 | BL16: =0.8243*A16^(-0.083) -> 0.87311367 | BM16: =(BK16-BL16)*100 -> 9.7788638 | BO16: =Y16 -> 0.97024633 | BP16: =0.8574*A16^(-0.085) -> 0.90943367 | BQ16: =(BO16-BP16)*100 -> 6.0812662 | BS16: =AL16 -> 0.97438817 | BT16: =0.8819*A16^(-0.087) -> 0.93671819 | BU16: =(BS16-BT16)*100 -> 3.7669979
A17: 0.75 | B17: ='[1]MA 15'!BX11 -> 0.7587525 | C17: ='[1]MA 15'!BY11 -> 0.94939963 | D17: ='[1]MA 15'!BZ11 -> 0.010738338 | E17: ='[1]MA 15'!CC11 -> 0.75586138 | F17: ='[1]MA 15'!CD11 -> 0.95515429 | G17: ='[1]MA 15'!CE11 -> 0.0061228176 | H17: ='[1]MA 15'!CH11 -> 0.7577189 | I17: ='[1]MA 15'!CI11 -> 0.96174219 | J17: ='[1]MA 15'!CJ11 -> 0.00053531268 | K17: ='[1]MA 15'!BS11 -> 0.75744426 | L17: ='[1]MA 15'!BT11 -> 0.95543203 | M17: ='[1]MA 15'!BU11 -> 0.0087439989 | O17: ='[1]MA 30'!BX11 -> 0.75453441 | P17: ='[1]MA 30'!BY11 -> 0.95278998 | Q17: ='[1]MA 30'!BZ11 -> 0.0021595896 | R17: ='[1]MA 30'!CC11 -> 0.76044361 | S17: ='[1]MA 30'!CD11 -> 0.94616043 | T17: ='[1]MA 30'!CE11 -> 0.00046858207 | U17: ='[1]MA 30'!CH11 -> 0.75134411 | V17: ='[1]MA 30'!CI11 -> 0.96047986 | W17: ='[1]MA 30'!CJ11 -> 0.0027492757 | X17: ='[1]MA 30'!BS11 -> 0.75544071 | Y17: ='[1]MA 30'!BT11 -> 0.95314342 | Z17: ='[1]MA 30'!BU11 -> 0.0061954927 | AB17: ='[1]MA 45'!BX11 -> 0.75518134 | AC17: ='[1]MA 45'!BY11 -> 0.95326893 | AD17: ='[1]MA 45'!BZ11 -> 0.0020872559 | AE17: ='[1]MA 45'!CC11 -> 0.75487967 | AF17: ='[1]MA 45'!CD11 -> 0.9589823 | AG17: ='[1]MA 45'!CE11 -> 0.0057034844 | AH17: ='[1]MA 45'!CH11 -> 0.74826779 | AI17: ='[1]MA 45'!CI11 -> 0.96063089 | AJ17: ='[1]MA 45'!CJ11 -> 0.0017173037 | AK17: ='[1]MA 45'!BS11 -> 0.75277627 | AL17: ='[1]MA 45'!BT11 -> 0.95762737 | AM17: ='[1]MA 45'!BU11 -> 0.0048196974 | BB17: =-0.0628*A17 + 1.0018 -> 0.9547 | BC17: =(BB17-L17)*100 -> -0.073203442 | BE17: =-0.0657*A17 + 1.0023 -> 0.953025 | BF17: =(BE17-Y17)*100 -> -0.011842476 | BH17: =-0.0645*A17 + 1.0053 -> 0.956925 | BI17: =(BH17-AL17)*100 -> -0.070237143 | BK17: =L17 -> 0.95543203 | BL17: =0.8243*A17^(-0.083) -> 0.84421918 | BM17: =(BK17-BL17)*100 -> 11.121285 | BO17: =Y17 -> 0.95314342 | BP17: =0.8574*A17^(-0.085) -> 0.87862442 | BQ17: =(BO17-BP17)*100 -> 7.4519 | BS17: =AL17 -> 0.95762737 | BT17: =0.8819*A17^(-0.087) -> 0.90425103 | BU17: =(BS17-BT17)*100 -> 5.337634
A18: 1 | B18: ='[1]MA 15'!BX12 -> 1.01167 | C18: ='[1]MA 15'!BY12 -> 0.93363683 | D18: ='[1]MA 15'!BZ12 -> 0.011584852 | E18: ='[1]MA 15'!CC12 -> 1.0078152 | F18: ='[1]MA 15'!CD12 -> 0.93624419 | G18: ='[1]MA 15'!CE12 -> 0.0053513158 | H18: ='[1]MA 15'!CH12 -> 1.0102919 | I18: ='[1]MA 15'!CI12 -> 0.9483189 | J18: ='[1]MA 15'!CJ12 -> 0.00058728631 | K18: ='[1]MA 15'!BS12 -> 1.0099257 | L18: ='[1]MA 15'!BT12 -> 0.93939997 | M18: ='[1]MA 15'!BU12 -> 0.0097623473 | O18: ='[1]MA 30'!BX12 -> 1.0060459 | P18: ='[1]MA 30'!BY12 -> 0.93740435 | Q18: ='[1]MA 30'!BZ12 -> 0.0022232707 | R18: ='[1]MA 30'!CC12 -> 1.0139248 | S18: ='[1]MA 30'!CD12 -> 0.92720383 | T18: ='[1]MA 30'!CE12 -> 0.00045980663 | U18: ='[1]MA 30'!CH12 -> 1.0017921 | V18: ='[1]MA 30'!CI12 -> 0.94386844 | W18: ='[1]MA 30'!CJ12 -> 0.0027098013 | X18: ='[1]MA 30'!BS12 -> 1.0072543 | Y18: ='[1]MA 30'!BT12 -> 0.93615887 | Z18: ='[1]MA 30'!BU12 -> 0.0071572535 | AB18: ='[1]MA 45'!BX12 -> 1.0069084 | AC18: ='[1]MA 45'!BY12 -> 0.93665945 | AD18: ='[1]MA 45'!BZ12 -> 0.0025329616 | AE18: ='[1]MA 45'!CC12 -> 1.0065062 | AF18: ='[1]MA 45'!CD12 -> 0.94099568 | AG18: ='[1]MA 45'!CE12 -> 0.0054879398 | AH18: ='[1]MA 45'!CH12 -> 0.99769038 | AI18: ='[1]MA 45'!CI12 -> 0.94388873 | AJ18: ='[1]MA 45'!CJ12 -> 0.0018935652 | AK18: ='[1]MA 45'!BS12 -> 1.0037017 | AL18: ='[1]MA 45'!BT12 -> 0.94051462 | AM18: ='[1]MA 45'!BU12 -> 0.0047115929 | BB18: =-0.0628*A18 + 1.0018 -> 0.939 | BC18: =(BB18-L18)*100 -> -0.03999722 | BE18: =-0.0657*A18 + 1.0023 -> 0.9366 | BF18: =(BE18-Y18)*100 -> 0.044112798 | BH18: =-0.0645*A18 + 1.0053 -> 0.9408 | BI18: =(BH18-AL18)*100 -> 0.028537803 | BK18: =L18 -> 0.93939997 | BL18: =0.8243*A18^(-0.083) -> 0.8243 | BM18: =(BK18-BL18)*100 -> 11.509997 | BO18: =Y18 -> 0.93615887 | BP18: =0.8574*A18^(-0.085) -> 0.8574 | BQ18: =(BO18-BP18)*100 -> 7.8758872 | BS18: =AL18 -> 0.94051462 | BT18: =0.8819*A18^(-0.087) -> 0.8819 | BU18: =(BS18-BT18)*100 -> 5.8614622
A19: 1.2497222 | B19: ='[1]MA 15'!BX13 -> 1.2643065 | C19: ='[1]MA 15'!BY13 -> 0.91749692 | D19: ='[1]MA 15'!BZ13 -> 0.012181489 | E19: ='[1]MA 15'!CC13 -> 1.259489 | F19: ='[1]MA 15'!CD13 -> 0.91684736 | G19: ='[1]MA 15'!CE13 -> 0.0044184136 | H19: ='[1]MA 15'!CH13 -> 1.2625842 | I19: ='[1]MA 15'!CI13 -> 0.93477151 | J19: ='[1]MA 15'!CJ13 -> 0.00061594906 | K19: ='[1]MA 15'!BS13 -> 1.2621266 | L19: ='[1]MA 15'!BT13 -> 0.92303859 | M19: ='[1]MA 15'!BU13 -> 0.011180239 | O19: ='[1]MA 30'!BX13 -> 1.2572779 | P19: ='[1]MA 30'!BY13 -> 0.92214531 | Q19: ='[1]MA 30'!BZ13 -> 0.0014159913 | R19: ='[1]MA 30'!CC13 -> 1.2671244 | S19: ='[1]MA 30'!CD13 -> 0.90869776 | T19: ='[1]MA 30'!CE13 -> 0.00055370984 | U19: ='[1]MA 30'!CH13 -> 1.2519619 | V19: ='[1]MA 30'!CI13 -> 0.92751055 | W19: ='[1]MA 30'!CJ13 -> 0.0027483739 | X19: ='[1]MA 30'!BS13 -> 1.2587881 | Y19: ='[1]MA 30'!BT13 -> 0.91945121 | Z19: ='[1]MA 30'!BU13 -> 0.0081181479 | AB19: ='[1]MA 45'!BX13 -> 1.2583559 | AC19: ='[1]MA 45'!BY13 -> 0.9209678 | AD19: ='[1]MA 45'!BZ13 -> 0.0026309464 | AE19: ='[1]MA 45'!CC13 -> 1.2578532 | AF19: ='[1]MA 45'!CD13 -> 0.92335517 | AG19: ='[1]MA 45'!CE13 -> 0.0048126044 | AH19: ='[1]MA 45'!CH13 -> 1.2468358 | AI19: ='[1]MA 45'!CI13 -> 0.92705452 | AJ19: ='[1]MA 45'!CJ13 -> 0.0019493155 | AK19: ='[1]MA 45'!BS13 -> 1.2543483 | AL19: ='[1]MA 45'!BT13 -> 0.9237925 | AM19: ='[1]MA 45'!BU13 -> 0.0041910135 | BB19: =-0.0628*A19 + 1.0018 -> 0.92331744 | BC19: =(BB19-L19)*100 -> 0.027885022 | BE19: =-0.0657*A19 + 1.0023 -> 0.92019325 | BF19: =(BE19-Y19)*100 -> 0.07420429 | BH19: =-0.0645*A19 + 1.0053 -> 0.92469292 | BI19: =(BH19-AL19)*100 -> 0.090041895 | BK19: =L19 -> 0.92303859 | BL19: =0.8243*A19^(-0.083) -> 0.80918865 | BM19: =(BK19-BL19)*100 -> 11.384995 | BO19: =Y19 -> 0.91945121 | BP19: =0.8574*A19^(-0.085) -> 0.84130667 | BQ19: =(BO19-BP19)*100 -> 7.8144537 | BS19: =AL19 -> 0.9237925 | BT19: =0.8819*A19^(-0.087) -> 0.86496108 | BU19: =(BS19-BT19)*100 -> 5.8831413
A20: 1.5 | B20: ='[1]MA 15'!BX14 -> 1.517505 | C20: ='[1]MA 15'!BY14 -> 0.90140159 | D20: ='[1]MA 15'!BZ14 -> 0.01275348 | E20: ='[1]MA 15'!CC14 -> 1.5117228 | F20: ='[1]MA 15'!CD14 -> 0.89815025 | G20: ='[1]MA 15'!CE14 -> 0.0035237206 | H20: ='[1]MA 15'!CH14 -> 1.5154378 | I20: ='[1]MA 15'!CI14 -> 0.92081227 | J20: ='[1]MA 15'!CJ14 -> 0.00067351562 | K20: ='[1]MA 15'!BS14 -> 1.5148885 | L20: ='[1]MA 15'!BT14 -> 0.90678804 | M20: ='[1]MA 15'!BU14 -> 0.012593989 | O20: ='[1]MA 30'!BX14 -> 1.5090688 | P20: ='[1]MA 30'!BY14 -> 0.9069966 | Q20: ='[1]MA 30'!BZ14 -> 0.0018651918 | R20: ='[1]MA 30'!CC14 -> 1.5208872 | S20: ='[1]MA 30'!CD14 -> 0.89069921 | T20: ='[1]MA 30'!CE14 -> 0.0004782989 | U20: ='[1]MA 30'!CH14 -> 1.5026882 | V20: ='[1]MA 30'!CI14 -> 0.91127809 | W20: ='[1]MA 30'!CJ14 -> 0.0026086321 | X20: ='[1]MA 30'!BS14 -> 1.5108814 | Y20: ='[1]MA 30'!BT14 -> 0.9029913 | Z20: ='[1]MA 30'!BU14 -> 0.009061299 | AB20: ='[1]MA 45'!BX14 -> 1.5103627 | AC20: ='[1]MA 45'!BY14 -> 0.90599795 | AD20: ='[1]MA 45'!BZ14 -> 0.0032662339 | AE20: ='[1]MA 45'!CC14 -> 1.5097593 | AF20: ='[1]MA 45'!CD14 -> 0.90653632 | AG20: ='[1]MA 45'!CE14 -> 0.0043237926 | AH20: ='[1]MA 45'!CH14 -> 1.4965356 | AI20: ='[1]MA 45'!CI14 -> 0.91041241 | AJ20: ='[1]MA 45'!CJ14 -> 0.0018338416 | AK20: ='[1]MA 45'!BS14 -> 1.5055525 | AL20: ='[1]MA 45'!BT14 -> 0.90764889 | AM20: ='[1]MA 45'!BU14 -> 0.0038439074 | BB20: =-0.0628*A20 + 1.0018 -> 0.9076 | BC20: =(BB20-L20)*100 -> 0.081196444 | BE20: =-0.0657*A20 + 1.0023 -> 0.90375 | BF20: =(BE20-Y20)*100 -> 0.075869917 | BH20: =-0.0645*A20 + 1.0053 -> 0.90855 | BI20: =(BH20-AL20)*100 -> 0.090110697 | BK20: =L20 -> 0.90678804 | BL20: =0.8243*A20^(-0.083) -> 0.79702093 | BM20: =(BK20-BL20)*100 -> 10.976711 | BO20: =Y20 -> 0.9029913 | BP20: =0.8574*A20^(-0.085) -> 0.82835352 | BQ20: =(BO20-BP20)*100 -> 7.4637781 | BS20: =AL20 -> 0.90764889 | BT20: =0.8819*A20^(-0.087) -> 0.85133287 | BU20: =(BS20-BT20)*100 -> 5.6316021
A21: 1.75 | B21: ='[1]MA 15'!BX15 -> 1.7704225 | C21: ='[1]MA 15'!BY15 -> 0.8846409 | D21: ='[1]MA 15'!BZ15 -> 0.012819679 | E21: ='[1]MA 15'!CC15 -> 1.7636766 | F21: ='[1]MA 15'!CD15 -> 0.88254213 | G21: ='[1]MA 15'!CE15 -> 0.00506295 | H21: ='[1]MA 15'!CH15 -> 1.7680108 | I21: ='[1]MA 15'!CI15 -> 0.90669502 | J21: ='[1]MA 15'!CJ15 -> 0.00072845484 | K21: ='[1]MA 15'!BS15 -> 1.7673699 | L21: ='[1]MA 15'!BT15 -> 0.89129268 | M21: ='[1]MA 15'!BU15 -> 0.013522308 | O21: ='[1]MA 30'!BX15 -> 1.7605803 | P21: ='[1]MA 30'!BY15 -> 0.89098969 | Q21: ='[1]MA 30'!BZ15 -> 0.0024397779 | R21: ='[1]MA 30'!CC15 -> 1.7743684 | S21: ='[1]MA 30'!CD15 -> 0.8732963 | T21: ='[1]MA 30'!CE15 -> 0.00041487883 | U21: ='[1]MA 30'!CH15 -> 1.7531363 | V21: ='[1]MA 30'!CI15 -> 0.8953165 | W21: ='[1]MA 30'!CJ15 -> 0.0025915152 | X21: ='[1]MA 30'!BS15 -> 1.762695 | Y21: ='[1]MA 30'!BT15 -> 0.88653416 | Z21: ='[1]MA 30'!BU15 -> 0.0097478682 | AB21: ='[1]MA 45'!BX15 -> 1.7620898 | AC21: ='[1]MA 45'!BY15 -> 0.89064644 | AD21: ='[1]MA 45'!BZ15 -> 0.0036916355 | AE21: ='[1]MA 45'!CC15 -> 1.7613859 | AF21: ='[1]MA 45'!CD15 -> 0.89033774 | AG21: ='[1]MA 45'!CE15 -> 0.0039225941 | AH21: ='[1]MA 45'!CH15 -> 1.7459582 | AI21: ='[1]MA 45'!CI15 -> 0.8940453 | AJ21: ='[1]MA 45'!CJ15 -> 0.0017594686 | AK21: ='[1]MA 45'!BS15 -> 1.756478 | AL21: ='[1]MA 45'!BT15 -> 0.89167649 | AM21: ='[1]MA 45'!BU15 -> 0.0036776433 | BB21: =-0.0628*A21 + 1.0018 -> 0.8919 | BC21: =(BB21-L21)*100 -> 0.060731758 | BE21: =-0.0657*A21 + 1.0023 -> 0.887325 | BF21: =(BE21-Y21)*100 -> 0.07908382 | BH21: =-0.0645*A21 + 1.0053 -> 0.892425 | BI21: =(BH21-AL21)*100 -> 0.074850865 | BK21: =L21 -> 0.89129268 | BL21: =0.8243*A21^(-0.083) -> 0.7868884 | BM21: =(BK21-BL21)*100 -> 10.440428 | BO21: =Y21 -> 0.88653416 | BP21: =0.8574*A21^(-0.085) -> 0.81757056 | BQ21: =(BO21-BP21)*100 -> 6.8963601 | BS21: =AL21 -> 0.89167649 | BT21: =0.8819*A21^(-0.087) -> 0.83999177 | BU21: =(BS21-BT21)*100 -> 5.1684719
A22: 2 | B22: ='[1]MA 15'!BX16 -> 2.02334 | C22: ='[1]MA 15'!BY16 -> 0.86732582 | D22: ='[1]MA 15'!BZ16 -> 0.012384461 | E22: ='[1]MA 15'!CC16 -> 2.0156303 | F22: ='[1]MA 15'!CD16 -> 0.86810122 | G22: ='[1]MA 15'!CE16 -> 0.0044094201 | H22: ='[1]MA 15'!CH16 -> 2.0205837 | I22: ='[1]MA 15'!CI16 -> 0.89248935 | J22: ='[1]MA 15'!CJ16 -> 0.00070965931 | K22: ='[1]MA 15'!BS16 -> 2.0198514 | L22: ='[1]MA 15'!BT16 -> 0.87597213 | M22: ='[1]MA 15'!BU16 -> 0.013938555 | O22: ='[1]MA 30'!BX16 -> 2.0120918 | P22: ='[1]MA 30'!BY16 -> 0.87473579 | Q22: ='[1]MA 30'!BZ16 -> 0.0023242977 | R22: ='[1]MA 30'!CC16 -> 2.0278496 | S22: ='[1]MA 30'!CD16 -> 0.85613153 | T22: ='[1]MA 30'!CE16 -> 0.00033276601 | U22: ='[1]MA 30'!CH16 -> 2.0035843 | V22: ='[1]MA 30'!CI16 -> 0.87974952 | W22: ='[1]MA 30'!CJ16 -> 0.002566577 | X22: ='[1]MA 30'!BS16 -> 2.0145086 | Y22: ='[1]MA 30'!BT16 -> 0.87020561 | Z22: ='[1]MA 30'!BU16 -> 0.010356782 | AB22: ='[1]MA 45'!BX16 -> 2.0138169 | AC22: ='[1]MA 45'!BY16 -> 0.87481478 | AD22: ='[1]MA 45'!BZ16 -> 0.0043419784 | AE22: ='[1]MA 45'!CC16 -> 2.0130125 | AF22: ='[1]MA 45'!CD16 -> 0.87448815 | AG22: ='[1]MA 45'!CE16 -> 0.0035048047 | AH22: ='[1]MA 45'!CH16 -> 1.9953808 | AI22: ='[1]MA 45'!CI16 -> 0.87841122 | AJ22: ='[1]MA 45'!CJ16 -> 0.0012626304 | AK22: ='[1]MA 45'!BS16 -> 2.0074034 | AL22: ='[1]MA 45'!BT16 -> 0.87590472 | AM22: ='[1]MA 45'!BU16 -> 0.0037509043 | BB22: =-0.0628*A22 + 1.0018 -> 0.8762 | BC22: =(BB22-L22)*100 -> 0.022787186 | BE22: =-0.0657*A22 + 1.0023 -> 0.8709 | BF22: =(BE22-Y22)*100 -> 0.069438682 | BH22: =-0.0645*A22 + 1.0053 -> 0.8763 | BI22: =(BH22-AL22)*100 -> 0.039528325 | BK22: =L22 -> 0.87597213 | BL22: =0.8243*A22^(-0.083) -> 0.77821538 | BM22: =(BK22-BL22)*100 -> 9.7756747 | BO22: =Y22 -> 0.87020561 | BP22: =0.8574*A22^(-0.085) -> 0.80834346 | BQ22: =(BO22-BP22)*100 -> 6.1862152 | BS22: =AL22 -> 0.87590472 | BT22: =0.8819*A22^(-0.087) -> 0.83028986 | BU22: =(BS22-BT22)*100 -> 4.5614859
A23: 2.2497222 | B23: ='[1]MA 15'!BX17 -> 2.2759765 | C23: ='[1]MA 15'!BY17 -> 0.84936442 | D23: ='[1]MA 15'!BZ17 -> 0.011608416 | E23: ='[1]MA 15'!CC17 -> 2.2673042 | F23: ='[1]MA 15'!CD17 -> 0.85283003 | G23: ='[1]MA 15'!CE17 -> 0.0047112988 | H23: ='[1]MA 15'!CH17 -> 2.2728761 | I23: ='[1]MA 15'!CI17 -> 0.87840017 | J23: ='[1]MA 15'!CJ17 -> 0.00066431554 | K23: ='[1]MA 15'!BS17 -> 2.2720522 | L23: ='[1]MA 15'!BT17 -> 0.86019821 | M23: ='[1]MA 15'!BU17 -> 0.014836502 | O23: ='[1]MA 30'!BX17 -> 2.2633238 | P23: ='[1]MA 30'!BY17 -> 0.85806479 | Q23: ='[1]MA 30'!BZ17 -> 0.002195428 | R23: ='[1]MA 30'!CC17 -> 2.2810492 | S23: ='[1]MA 30'!CD17 -> 0.83964099 | T23: ='[1]MA 30'!CE17 -> 0.00056616467 | U23: ='[1]MA 30'!CH17 -> 2.253754 | V23: ='[1]MA 30'!CI17 -> 0.86454353 | W23: ='[1]MA 30'!CJ17 -> 0.0027845664 | X23: ='[1]MA 30'!BS17 -> 2.2660423 | Y23: ='[1]MA 30'!BT17 -> 0.8540831 | Z23: ='[1]MA 30'!BU17 -> 0.010750861 | AB23: ='[1]MA 45'!BX17 -> 2.2652643 | AC23: ='[1]MA 45'!BY17 -> 0.85861804 | AD23: ='[1]MA 45'!BZ17 -> 0.0047753421 | AE23: ='[1]MA 45'!CC17 -> 2.2643594 | AF23: ='[1]MA 45'!CD17 -> 0.85888911 | AG23: ='[1]MA 45'!CE17 -> 0.0031628781 | AH23: ='[1]MA 45'!CH17 -> 2.2445262 | AI23: ='[1]MA 45'!CI17 -> 0.86371551 | AJ23: ='[1]MA 45'!CJ17 -> 0.0012925236 | AK23: ='[1]MA 45'!BS17 -> 2.25805 | AL23: ='[1]MA 45'!BT17 -> 0.86040755 | AM23: ='[1]MA 45'!BU17 -> 0.0041202304 | BB23: =-0.0628*A23 + 1.0018 -> 0.86051744 | BC23: =(BB23-L23)*100 -> 0.031923464 | BE23: =-0.0657*A23 + 1.0023 -> 0.85449325 | BF23: =(BE23-Y23)*100 -> 0.041014721 | BH23: =-0.0645*A23 + 1.0053 -> 0.86019292 | BI23: =(BH23-AL23)*100 -> -0.021463636 | BK23: =L23 -> 0.86019821 | BL23: =0.8243*A23^(-0.083) -> 0.77065252 | BM23: =(BK23-BL23)*100 -> 8.9545693 | BO23: =Y23 -> 0.8540831 | BP23: =0.8574*A23^(-0.085) -> 0.80029946 | BQ23: =(BO23-BP23)*100 -> 5.3783645 | BS23: =AL23 -> 0.86040755 | BT23: =0.8819*A23^(-0.087) -> 0.82183405 | BU23: =(BS23-BT23)*100 -> 3.8573508
A24: 2.5 | B24: ='[1]MA 15'!BX18 -> 2.529175 | C24: ='[1]MA 15'!BY18 -> 0.83143648 | D24: ='[1]MA 15'!BZ18 -> 0.010953158 | E24: ='[1]MA 15'!CC18 -> 2.5195379 | F24: ='[1]MA 15'!CD18 -> 0.83918459 | G24: ='[1]MA 15'!CE18 -> 0.0050478608 | H24: ='[1]MA 15'!CH18 -> 2.5257297 | I24: ='[1]MA 15'!CI18 -> 0.86413896 | J24: ='[1]MA 15'!CJ18 -> 0.00082041362 | K24: ='[1]MA 15'!BS18 -> 2.5248142 | L24: ='[1]MA 15'!BT18 -> 0.84492001 | M24: ='[1]MA 15'!BU18 -> 0.015601224 | O24: ='[1]MA 30'!BX18 -> 2.5151147 | P24: ='[1]MA 30'!BY18 -> 0.84130634 | Q24: ='[1]MA 30'!BZ18 -> 0.0021148189 | R24: ='[1]MA 30'!CC18 -> 2.534812 | S24: ='[1]MA 30'!CD18 -> 0.8234544 | T24: ='[1]MA 30'!CE18 -> 0.00088429908 | U24: ='[1]MA 30'!CH18 -> 2.5044804 | V24: ='[1]MA 30'!CI18 -> 0.84971938 | W24: ='[1]MA 30'!CJ18 -> 0.0029927714 | X24: ='[1]MA 30'!BS18 -> 2.5181357 | Y24: ='[1]MA 30'!BT18 -> 0.83816004 | Z24: ='[1]MA 30'!BU18 -> 0.011165195 | AB24: ='[1]MA 45'!BX18 -> 2.5172711 | AC24: ='[1]MA 45'!BY18 -> 0.84203277 | AD24: ='[1]MA 45'!BZ18 -> 0.0053254562 | AE24: ='[1]MA 45'!CC18 -> 2.5162656 | AF24: ='[1]MA 45'!CD18 -> 0.8433562 | AG24: ='[1]MA 45'!CE18 -> 0.0029263376 | AH24: ='[1]MA 45'!CH18 -> 2.494226 | AI24: ='[1]MA 45'!CI18 -> 0.84891669 | AJ24: ='[1]MA 45'!CJ18 -> 0.00082673804 | AK24: ='[1]MA 45'!BS18 -> 2.5092542 | AL24: ='[1]MA 45'!BT18 -> 0.84476855 | AM24: ='[1]MA 45'!BU18 -> 0.0046293898 | BB24: =-0.0628*A24 + 1.0018 -> 0.8448 | BC24: =(BB24-L24)*100 -> -0.012001167 | BE24: =-0.0657*A24 + 1.0023 -> 0.83805 | BF24: =(BE24-Y24)*100 -> -0.011003855 | BH24: =-0.0645*A24 + 1.0053 -> 0.84405 | BI24: =(BH24-AL24)*100 -> -0.071855323 | BK24: =L24 -> 0.84492001 | BL24: =0.8243*A24^(-0.083) -> 0.76393477 | BM24: =(BK24-BL24)*100 -> 8.0985238 | BO24: =Y24 -> 0.83816004 | BP24: =0.8574*A24^(-0.085) -> 0.79315594 | BQ24: =(BO24-BP24)*100 -> 4.5004103 | BS24: =AL24 -> 0.84476855 | BT24: =0.8819*A24^(-0.087) -> 0.81432649 | BU24: =(BS24-BT24)*100 -> 3.0442065
A25: 2.75 | B25: ='[1]MA 15'!BX19 -> 2.7820925 | C25: ='[1]MA 15'!BY19 -> 0.81364751 | D25: ='[1]MA 15'!BZ19 -> 0.010386909 | E25: ='[1]MA 15'!CC19 -> 2.7714917 | F25: ='[1]MA 15'!CD19 -> 0.82493363 | G25: ='[1]MA 15'!CE19 -> 0.0061605604 | H25: ='[1]MA 15'!CH19 -> 2.7783026 | I25: ='[1]MA 15'!CI19 -> 0.84986953 | J25: ='[1]MA 15'!CJ19 -> 0.0010183141 | K25: ='[1]MA 15'!BS19 -> 2.7772956 | L25: ='[1]MA 15'!BT19 -> 0.82948356 | M25: ='[1]MA 15'!BU19 -> 0.016672806 | O25: ='[1]MA 30'!BX19 -> 2.7666262 | P25: ='[1]MA 30'!BY19 -> 0.82534866 | Q25: ='[1]MA 30'!BZ19 -> 0.0033712883 | R25: ='[1]MA 30'!CC19 -> 2.7882932 | S25: ='[1]MA 30'!CD19 -> 0.80892823 | T25: ='[1]MA 30'!CE19 -> 0.0019855151 | U25: ='[1]MA 30'!CH19 -> 2.7549284 | V25: ='[1]MA 30'!CI19 -> 0.83531815 | W25: ='[1]MA 30'!CJ19 -> 0.0029120134 | X25: ='[1]MA 30'!BS19 -> 2.7699493 | Y25: ='[1]MA 30'!BT19 -> 0.82319835 | Z25: ='[1]MA 30'!BU19 -> 0.011238881 | AB25: ='[1]MA 45'!BX19 -> 2.7689982 | AC25: ='[1]MA 45'!BY19 -> 0.82531703 | AD25: ='[1]MA 45'!BZ19 -> 0.0056571333 | AE25: ='[1]MA 45'!CC19 -> 2.7678921 | AF25: ='[1]MA 45'!CD19 -> 0.82749493 | AG25: ='[1]MA 45'!CE19 -> 0.0014835686 | AH25: ='[1]MA 45'!CH19 -> 2.7436486 | AI25: ='[1]MA 45'!CI19 -> 0.83281037 | AJ25: ='[1]MA 45'!CJ19 -> 0.00072028973 | AK25: ='[1]MA 45'!BS19 -> 2.7601796 | AL25: ='[1]MA 45'!BT19 -> 0.82854078 | AM25: ='[1]MA 45'!BU19 -> 0.0046346053 | BB25: =-0.0628*A25 + 1.0018 -> 0.8291 | BC25: =(BB25-L25)*100 -> -0.038355721 | BE25: =-0.0657*A25 + 1.0023 -> 0.821625 | BF25: =(BE25-Y25)*100 -> -0.1573349 | BH25: =-0.0645*A25 + 1.0053 -> 0.827925 | BI25: =(BH25-AL25)*100 -> -0.061577634 | BK25: =L25 -> 0.82948356 | BL25: =0.8243*A25^(-0.083) -> 0.75791532 | BM25: =(BK25-BL25)*100 -> 7.1568236 | BO25: =Y25 -> 0.82319835 | BP25: =0.8574*A25^(-0.085) -> 0.78675625 | BQ25: =(BO25-BP25)*100 -> 3.6442102 | BS25: =AL25 -> 0.82854078 | BT25: =0.8819*A25^(-0.087) -> 0.80760202 | BU25: =(BS25-BT25)*100 -> 2.0938753
A26: 3 | B26: ='[1]MA 15'!BX20 -> 3.03501 | C26: ='[1]MA 15'!BY20 -> 0.79599318 | D26: ='[1]MA 15'!BZ20 -> 0.0095846503 | E26: ='[1]MA 15'!CC20 -> 3.0234455 | F26: ='[1]MA 15'!CD20 -> 0.80926622 | G26: ='[1]MA 15'!CE20 -> 0.0059598044 | H26: ='[1]MA 15'!CH20 -> 3.0308756 | I26: ='[1]MA 15'!CI20 -> 0.83579539 | J26: ='[1]MA 15'!CJ20 -> 0.0013053456 | K26: ='[1]MA 15'!BS20 -> 3.029777 | L26: ='[1]MA 15'!BT20 -> 0.81368493 | M26: ='[1]MA 15'!BU20 -> 0.017799665 | O26: ='[1]MA 30'!BX20 -> 3.0181377 | P26: ='[1]MA 30'!BY20 -> 0.81063771 | Q26: ='[1]MA 30'!BZ20 -> 0.0069348689 | R26: ='[1]MA 30'!CC20 -> 3.0417744 | S26: ='[1]MA 30'!CD20 -> 0.79532808 | T26: ='[1]MA 30'!CE20 -> 0.0043274397 | U26: ='[1]MA 30'!CH20 -> 3.0053764 | V26: ='[1]MA 30'!CI20 -> 0.82131072 | W26: ='[1]MA 30'!CJ20 -> 0.0029617682 | X26: ='[1]MA 30'!BS20 -> 3.0217628 | Y26: ='[1]MA 30'!BT20 -> 0.80909217 | Z26: ='[1]MA 30'!BU20 -> 0.011785908 | AB26: ='[1]MA 45'!BX20 -> 3.0207253 | AC26: ='[1]MA 45'!BY20 -> 0.80883385 | AD26: ='[1]MA 45'!BZ20 -> 0.0058668578 | AE26: ='[1]MA 45'!CC20 -> 3.0195187 | AF26: ='[1]MA 45'!CD20 -> 0.8167372 | AG26: ='[1]MA 45'!CE20 -> 0.0077140398 | AH26: ='[1]MA 45'!CH20 -> 2.9930712 | AI26: ='[1]MA 45'!CI20 -> 0.81592127 | AJ26: ='[1]MA 45'!CJ20 -> 0.0012399799 | AK26: ='[1]MA 45'!BS20 -> 3.0111051 | AL26: ='[1]MA 45'!BT20 -> 0.81383077 | AM26: ='[1]MA 45'!BU20 -> 0.0066646005 | BB26: =-0.0628*A26 + 1.0018 -> 0.8134 | BC26: =(BB26-L26)*100 -> -0.028492762 | BE26: =-0.0657*A26 + 1.0023 -> 0.8052 | BF26: =(BE26-Y26)*100 -> -0.38921699 | BH26: =-0.0645*A26 + 1.0053 -> 0.8118 | BI26: =(BH26-AL26)*100 -> -0.20307699 | BK26: =L26 -> 0.81368493 | BL26: =0.8243*A26^(-0.083) -> 0.75246142 | BM26: =(BK26-BL26)*100 -> 6.1223511 | BO26: =Y26 -> 0.80909217 | BP26: =0.8574*A26^(-0.085) -> 0.78095889 | BQ26: =(BO26-BP26)*100 -> 2.8133281 | BS26: =AL26 -> 0.81383077 | BT26: =0.8819*A26^(-0.087) -> 0.80151157 | BU26: =(BS26-BT26)*100 -> 1.2319204
... A37: 5.75 | B37: ='[1]MA 15'!BX31 -> 5.8171025 | C37: ='[1]MA 15'!BY31 -> 0.71527812 | D37: ='[1]MA 15'!BZ31 -> 0.008394945 | E37: ='[1]MA 15'!CC31 -> 5.7949372 | F37: ='[1]MA 15'!CD31 -> 0.69681862 | G37: ='[1]MA 15'!CE31 -> 0.0050002921 | H37: ='[1]MA 15'!CH31 -> 5.8091782 | I37: ='[1]MA 15'!CI31 -> 0.7420663 | J37: ='[1]MA 15'!CJ31 -> 0.0036196989 | K37: ='[1]MA 15'!BS31 -> 5.8070727 | L37: ='[1]MA 15'!BT31 -> 0.71805435 | M37: ='[1]MA 15'!BU31 -> 0.019526204 | O37: ='[1]MA 30'!BX31 -> 5.7847638 | P37: ='[1]MA 30'!BY31 -> 0.74677842 | Q37: ='[1]MA 30'!BZ31 -> 0.022174876 | R37: ='[1]MA 30'!CC31 -> 5.8300677 | S37: ='[1]MA 30'!CD31 -> 0.72710087 | T37: ='[1]MA 30'!CE31 -> 0.024610411 | U37: ='[1]MA 30'!CH31 -> 5.7603048 | V37: ='[1]MA 30'!CI31 -> 0.73495047 | W37: ='[1]MA 30'!CJ31 -> 0.0042288205 | X37: ='[1]MA 30'!BS31 -> 5.7917121 | Y37: ='[1]MA 30'!BT31 -> 0.73627659 | Z37: ='[1]MA 30'!BU31 -> 0.0209087 | AB37: ='[1]MA 45'!BX31 -> 5.7897236 | AC37: ='[1]MA 45'!BY31 -> 0.73897149 | AD37: ='[1]MA 45'!BZ31 -> 0.0066169055 | AE37: ='[1]MA 45'!CC31 -> 5.7874108 | AF37: ='[1]MA 45'!CD31 -> 0.76466283 | AG37: ='[1]MA 45'!CE31 -> 0.0096750213 | AH37: ='[1]MA 45'!CH31 -> 5.7367197 | AI37: ='[1]MA 45'!CI31 -> 0.75485854 | AJ37: ='[1]MA 45'!CJ31 -> 0.0074851177 | AK37: ='[1]MA 45'!BS31 -> 5.7712847 | AL37: ='[1]MA 45'!BT31 -> 0.75283095 | AM37: ='[1]MA 45'!BU31 -> 0.013286656 | BB37: =-0.0628*A37 + 1.0018 -> 0.6407 | BC37: =(BB37-L37)*100 -> -7.7354345 | BE37: =-0.0657*A37 + 1.0023 -> 0.624525 | BF37: =(BE37-Y37)*100 -> -11.175159 | BH37: =-0.0645*A37 + 1.0053 -> 0.634425 | BI37: =(BH37-AL37)*100 -> -11.840595 | BK37: =L37 -> 0.71805435 | BL37: =0.8243*A37^(-0.083) -> 0.71290698 | BM37: =(BK37-BL37)*100 -> 0.51473622 | BO37: =Y37 -> 0.73627659 | BP37: =0.8574*A37^(-0.085) -> 0.73894432 | BQ37: =(BO37-BP37)*100 -> -0.26677296 | BS37: =AL37 -> 0.75283095 | BT37: =0.8819*A37^(-0.087) -> 0.75740513 | BU37: =(BS37-BT37)*100 -> -0.45741737
A38: 6 | B38: ='[1]MA 15'!BX32 -> 6.07002 | C38: ='[1]MA 15'!BY32 -> 0.7124698 | D38: ='[1]MA 15'!BZ32 -> 0.0084106804 | E38: ='[1]MA 15'!CC32 -> 6.046891 | F38: ='[1]MA 15'!CD32 -> 0.69288708 | G38: ='[1]MA 15'!CE32 -> 0.0052015883 | H38: ='[1]MA 15'!CH32 -> 6.0617512 | I38: ='[1]MA 15'!CI32 -> 0.73836604 | J38: ='[1]MA 15'!CJ32 -> 0.0038525392 | K38: ='[1]MA 15'!BS32 -> 6.0595541 | L38: ='[1]MA 15'!BT32 -> 0.71457431 | M38: ='[1]MA 15'!BU32 -> 0.019608242 | O38: ='[1]MA 30'!BX32 -> 6.0362753 | P38: ='[1]MA 30'!BY32 -> 0.74420252 | Q38: ='[1]MA 30'!BZ32 -> 0.022359316 | R38: ='[1]MA 30'!CC32 -> 6.0835489 | S38: ='[1]MA 30'!CD32 -> 0.72458749 | T38: ='[1]MA 30'!CE32 -> 0.024742279 | U38: ='[1]MA 30'!CH32 -> 6.0107529 | V38: ='[1]MA 30'!CI32 -> 0.73228694 | W38: ='[1]MA 30'!CJ32 -> 0.004225182 | X38: ='[1]MA 30'!BS32 -> 6.0435257 | Y38: ='[1]MA 30'!BT32 -> 0.73369232 | Z38: ='[1]MA 30'!BU32 -> 0.021018317 | AB38: ='[1]MA 45'!BX32 -> 6.0414507 | AC38: ='[1]MA 45'!BY32 -> 0.73638237 | AD38: ='[1]MA 45'!BZ32 -> 0.0067024061 | AE38: ='[1]MA 45'!CC32 -> 6.0390374 | AF38: ='[1]MA 45'!CD32 -> 0.76232673 | AG38: ='[1]MA 45'!CE32 -> 0.0098384079 | AH38: ='[1]MA 45'!CH32 -> 5.9861423 | AI38: ='[1]MA 45'!CI32 -> 0.75246884 | AJ38: ='[1]MA 45'!CJ32 -> 0.0075337661 | AK38: ='[1]MA 45'!BS32 -> 6.0222101 | AL38: ='[1]MA 45'!BT32 -> 0.75039265 | AM38: ='[1]MA 45'!BU32 -> 0.013434968 | BB38: =-0.0628*A38 + 1.0018 -> 0.625 | BC38: =(BB38-L38)*100 -> -8.957431 | BE38: =-0.0657*A38 + 1.0023 -> 0.6081 | BF38: =(BE38-Y38)*100 -> -12.559232 | BH38: =-0.0645*A38 + 1.0053 -> 0.6183 | BI38: =(BH38-AL38)*100 -> -13.209265 | BJ38: =A38 -> 6 | BK38: =L38 -> 0.71457431 | BL38: =0.8243*A38^(-0.083) -> 0.71039312 | BM38: =(BK38-BL38)*100 -> 0.41811911 | BO38: =Y38 -> 0.73369232 | BP38: =0.8574*A38^(-0.085) -> 0.73627596 | BQ38: =(BO38-BP38)*100 -> -0.25836454 | BS38: =AL38 -> 0.75039265 | BT38: =0.8819*A38^(-0.087) -> 0.75460588 | BU38: =(BS38-BT38)*100 -> -0.42132294
A39: 6.2497222 | B39: ='[1]MA 15'!BX33 -> 6.3226565 | C39: ='[1]MA 15'!BY33 -> 0.70988364 | D39: ='[1]MA 15'!BZ33 -> 0.0085198692 | E39: ='[1]MA 15'!CC33 -> 6.2985649 | F39: ='[1]MA 15'!CD33 -> 0.68936275 | G39: ='[1]MA 15'!CE33 -> 0.0051624564 | H39: ='[1]MA 15'!CH33 -> 6.3140435 | I39: ='[1]MA 15'!CI33 -> 0.73453244 | J39: ='[1]MA 15'!CJ33 -> 0.0045118694 | K39: ='[1]MA 15'!BS33 -> 6.311755 | L39: ='[1]MA 15'!BT33 -> 0.71125961 | M39: ='[1]MA 15'!BU33 -> 0.019515687 | O39: ='[1]MA 30'!BX33 -> 6.2875073 | P39: ='[1]MA 30'!BY33 -> 0.7417663 | Q39: ='[1]MA 30'!BZ33 -> 0.022473952 | R39: ='[1]MA 30'!CC33 -> 6.3367484 | S39: ='[1]MA 30'!CD33 -> 0.72236844 | T39: ='[1]MA 30'!CE33 -> 0.025020058 | U39: ='[1]MA 30'!CH33 -> 6.2609226 | V39: ='[1]MA 30'!CI33 -> 0.72984539 | W39: ='[1]MA 30'!CJ33 -> 0.0042185601 | X39: ='[1]MA 30'!BS33 -> 6.2950595 | Y39: ='[1]MA 30'!BT33 -> 0.73132671 | Z39: ='[1]MA 30'!BU33 -> 0.021136919 | AB39: ='[1]MA 45'!BX33 -> 6.2928981 | AC39: ='[1]MA 45'!BY33 -> 0.73391136 | AD39: ='[1]MA 45'!BZ33 -> 0.0067874308 | AE39: ='[1]MA 45'!CC33 -> 6.2903844 | AF39: ='[1]MA 45'!CD33 -> 0.75986863 | AG39: ='[1]MA 45'!CE33 -> 0.0097304486 | AH39: ='[1]MA 45'!CH33 -> 6.2352878 | AI39: ='[1]MA 45'!CI33 -> 0.7501782 | AJ39: ='[1]MA 45'!CJ33 -> 0.0075679205 | AK39: ='[1]MA 45'!BS33 -> 6.2728567 | AL39: ='[1]MA 45'!BT33 -> 0.74798606 | AM39: ='[1]MA 45'!BU33 -> 0.013442747 | BB39: =-0.0628*A39 + 1.0018 -> 0.60931744 | BC39: =(BB39-L39)*100 -> -10.194216 | BE39: =-0.0657*A39 + 1.0023 -> 0.59169325 | BF39: =(BE39-Y39)*100 -> -13.963346 | BH39: =-0.0645*A39 + 1.0053 -> 0.60219292 | BI39: =(BH39-AL39)*100 -> -14.579315 | BJ39: =A39 -> 6.2497222 | BK39: =L39 -> 0.71125961 | BL39: =0.8243*A39^(-0.083) -> 0.70799283 | BM39: =(BK39-BL39)*100 -> 0.32667771 | BO39: =Y39 -> 0.73132671 | BP39: =0.8574*A39^(-0.085) -> 0.73372838 | BQ39: =(BO39-BP39)*100 -> -0.24016715 | BS39: =AL39 -> 0.74798606 | BT39: =0.8819*A39^(-0.087) -> 0.75193355 | BU39: =(BS39-BT39)*100 -> -0.39474825
A40: 6.5 | B40: ='[1]MA 15'!BX34 -> 6.575855 | C40: ='[1]MA 15'!BY34 -> 0.70754463 | D40: ='[1]MA 15'!BZ34 -> 0.008625653 | E40: ='[1]MA 15'!CC34 -> 6.5507986 | F40: ='[1]MA 15'!CD34 -> 0.68623367 | G40: ='[1]MA 15'!CE34 -> 0.0052788171 | H40: ='[1]MA 15'!CH34 -> 6.5668971 | I40: ='[1]MA 15'!CI34 -> 0.73134577 | J40: ='[1]MA 15'!CJ34 -> 0.0048638446 | K40: ='[1]MA 15'!BS34 -> 6.5645169 | L40: ='[1]MA 15'!BT34 -> 0.70837469 | M40: ='[1]MA 15'!BU34 -> 0.0195321 | O40: ='[1]MA 30'!BX34 -> 6.5392982 | P40: ='[1]MA 30'!BY34 -> 0.7395047 | Q40: ='[1]MA 30'!BZ34 -> 0.022540156 | R40: ='[1]MA 30'!CC34 -> 6.5905113 | S40: ='[1]MA 30'!CD34 -> 0.72027083 | T40: ='[1]MA 30'!CE34 -> 0.025241372 | U40: ='[1]MA 30'!CH34 -> 6.5116489 | V40: ='[1]MA 30'!CI34 -> 0.72755103 | W40: ='[1]MA 30'!CJ34 -> 0.0041990747 | X40: ='[1]MA 30'!BS34 -> 6.5471528 | Y40: ='[1]MA 30'!BT34 -> 0.72910885 | Z40: ='[1]MA 30'!BU34 -> 0.021224426 | AB40: ='[1]MA 45'!BX34 -> 6.5449049 | AC40: ='[1]MA 45'!BY34 -> 0.73154743 | AD40: ='[1]MA 45'!BZ34 -> 0.0068394061 | AE40: ='[1]MA 45'!CC34 -> 6.5422905 | AF40: ='[1]MA 45'!CD34 -> 0.75763155 | AG40: ='[1]MA 45'!CE34 -> 0.0098191422 | AH40: ='[1]MA 45'!CH34 -> 6.4849875 | AI40: ='[1]MA 45'!CI34 -> 0.74796401 | AJ40: ='[1]MA 45'!CJ34 -> 0.0075626226 | AK40: ='[1]MA 45'!BS34 -> 6.524061 | AL40: ='[1]MA 45'!BT34 -> 0.74571433 | AM40: ='[1]MA 45'!BU34 -> 0.013517501 | BB40: =-0.0628*A40 + 1.0018 -> 0.5936 | BC40: =(BB40-L40)*100 -> -11.477469 | BE40: =-0.0657*A40 + 1.0023 -> 0.57525 | BF40: =(BE40-Y40)*100 -> -15.385885 | BH40: =-0.0645*A40 + 1.0053 -> 0.58605 | BI40: =(BH40-AL40)*100 -> -15.966433 | BJ40: =A40 -> 6.5 | BK40: =L40 -> 0.70837469 | BL40: =0.8243*A40^(-0.083) -> 0.70568923 | BM40: =(BK40-BL40)*100 -> 0.26854589 | BO40: =Y40 -> 0.72910885 | BP40: =0.8574*A40^(-0.085) -> 0.73128362 | BQ40: =(BO40-BP40)*100 -> -0.21747632 | BS40: =AL40 -> 0.74571433 | BT40: =0.8819*A40^(-0.087) -> 0.74936927 | BU40: =(BS40-BT40)*100 -> -0.36549404
A41: 6.75 | B41: ='[1]MA 15'!BX35 -> 6.8287725 | C41: ='[1]MA 15'!BY35 -> 0.70538451 | D41: ='[1]MA 15'!BZ35 -> 0.0086729775 | E41: ='[1]MA 15'!CC35 -> 6.8027524 | F41: ='[1]MA 15'!CD35 -> 0.68314799 | G41: ='[1]MA 15'!CE35 -> 0.0054552946 | H41: ='[1]MA 15'!CH35 -> 6.8194701 | I41: ='[1]MA 15'!CI35 -> 0.72881018 | J41: ='[1]MA 15'!CJ35 -> 0.0055624619 | K41: ='[1]MA 15'!BS35 -> 6.8169984 | L41: ='[1]MA 15'!BT35 -> 0.70578089 | M41: ='[1]MA 15'!BU35 -> 0.019821497 | O41: ='[1]MA 30'!BX35 -> 6.7908097 | P41: ='[1]MA 30'!BY35 -> 0.73735762 | Q41: ='[1]MA 30'!BZ35 -> 0.022574502 | R41: ='[1]MA 30'!CC35 -> 6.8439925 | S41: ='[1]MA 30'!CD35 -> 0.71810356 | T41: ='[1]MA 30'!CE35 -> 0.025304203 | U41: ='[1]MA 30'!CH35 -> 6.762097 | V41: ='[1]MA 30'!CI35 -> 0.72533814 | W41: ='[1]MA 30'!CJ35 -> 0.0041853082 | X41: ='[1]MA 30'!BS35 -> 6.7989664 | Y41: ='[1]MA 30'!BT35 -> 0.72693311 | Z41: ='[1]MA 30'!BU35 -> 0.021265019 | AB41: ='[1]MA 45'!BX35 -> 6.796632 | AC41: ='[1]MA 45'!BY35 -> 0.72929363 | AD41: ='[1]MA 45'!BZ35 -> 0.0069047512 | AE41: ='[1]MA 45'!CC35 -> 6.7939171 | AF41: ='[1]MA 45'!CD35 -> 0.75543047 | AG41: ='[1]MA 45'!CE35 -> 0.0098021263 | AH41: ='[1]MA 45'!CH35 -> 6.7344101 | AI41: ='[1]MA 45'!CI35 -> 0.74587233 | AJ41: ='[1]MA 45'!CJ35 -> 0.0075741397 | AK41: ='[1]MA 45'!BS35 -> 6.7749864 | AL41: ='[1]MA 45'!BT35 -> 0.74353214 | AM41: ='[1]MA 45'!BU35 -> 0.013551222 | BJ41: =A41 -> 6.75 | BK41: =L41 -> 0.70578089 | BL41: =0.8243*A41^(-0.083) -> 0.70348216 | BM41: =(BK41-BL41)*100 -> 0.2298735 | BO41: =Y41 -> 0.72693311 | BP41: =0.8574*A41^(-0.085) -> 0.72894147 | BQ41: =(BO41-BP41)*100 -> -0.20083653 | BS41: =AL41 -> 0.74353214 | BT41: =0.8819*A41^(-0.087) -> 0.74691282 | BU41: =(BS41-BT41)*100 -> -0.33806795
A42: 7 | B42: ='[1]MA 15'!BX36 -> 7.08169 | C42: ='[1]MA 15'!BY36 -> 0.70332464 | D42: ='[1]MA 15'!BZ36 -> 0.0086847725 | E42: ='[1]MA 15'!CC36 -> 7.0547062 | F42: ='[1]MA 15'!CD36 -> 0.68025345 | G42: ='[1]MA 15'!CE36 -> 0.005589296 | H42: ='[1]MA 15'!CH36 -> 7.0720431 | I42: ='[1]MA 15'!CI36 -> 0.72586711 | J42: ='[1]MA 15'!CJ36 -> 0.0050851091 | K42: ='[1]MA 15'!BS36 -> 7.0694798 | L42: ='[1]MA 15'!BT36 -> 0.7031484 | M42: ='[1]MA 15'!BU36 -> 0.019772654 | O42: ='[1]MA 30'!BX36 -> 7.0423212 | P42: ='[1]MA 30'!BY36 -> 0.73529376 | Q42: ='[1]MA 30'!BZ36 -> 0.022573191 | R42: ='[1]MA 30'!CC36 -> 7.0974737 | S42: ='[1]MA 30'!CD36 -> 0.71607894 | T42: ='[1]MA 30'!CE36 -> 0.025424237 | U42: ='[1]MA 30'!CH36 -> 7.012545 | V42: ='[1]MA 30'!CI36 -> 0.72319274 | W42: ='[1]MA 30'!CJ36 -> 0.0041596383 | X42: ='[1]MA 30'!BS36 -> 7.05078 | Y42: ='[1]MA 30'!BT36 -> 0.72485514 | Z42: ='[1]MA 30'!BU36 -> 0.021307224 | AB42: ='[1]MA 45'!BX36 -> 7.0483591 | AC42: ='[1]MA 45'!BY36 -> 0.72713608 | AD42: ='[1]MA 45'!BZ36 -> 0.0069293946 | AE42: ='[1]MA 45'!CC36 -> 7.0455436 | AF42: ='[1]MA 45'!CD36 -> 0.75349184 | AG42: ='[1]MA 45'!CE36 -> 0.010033487 | AH42: ='[1]MA 45'!CH36 -> 6.9838327 | AI42: ='[1]MA 45'!CI36 -> 0.74383594 | AJ42: ='[1]MA 45'!CJ36 -> 0.0076096739 | AK42: ='[1]MA 45'!BS36 -> 7.0259118 | AL42: ='[1]MA 45'!BT36 -> 0.74148795 | AM42: ='[1]MA 45'!BU36 -> 0.013689132 | BJ42: =A42 -> 7 | BK42: =L42 -> 0.7031484 | BL42: =0.8243*A42^(-0.083) -> 0.70136189 | BM42: =(BK42-BL42)*100 -> 0.17865112 | BO42: =Y42 -> 0.72485514 | BP42: =0.8574*A42^(-0.085) -> 0.72669161 | BQ42: =(BO42-BP42)*100 -> -0.18364664 | BS42: =AL42 -> 0.74148795 | BT42: =0.8819*A42^(-0.087) -> 0.74455333 | BU42: =(BS42-BT42)*100 -> -0.30653842
A43: 7.25 | B43: ='[1]MA 15'!BX37 -> 7.2497983 | C43: ='[1]MA 15'!BY37 -> 0.70199226 | D43: ='[1]MA 15'!BZ37 -> 0.0094212538 | E43: ='[1]MA 15'!CC37 -> 7.30666 | F43: ='[1]MA 15'!CD37 -> 0.67747298 | G43: ='[1]MA 15'!CE37 -> 0.0058357103 | H43: ='[1]MA 15'!CH37 -> 7.324616 | I43: ='[1]MA 15'!CI37 -> 0.72355358 | J43: ='[1]MA 15'!CJ37 -> 0.0050323325 | K43: ='[1]MA 15'!BS37 -> 7.2936914 | L43: ='[1]MA 15'!BT37 -> 0.70100627 | M43: ='[1]MA 15'!BU37 -> 0.020094022 | O43: ='[1]MA 30'!BX37 -> 7.2938327 | P43: ='[1]MA 30'!BY37 -> 0.73330247 | Q43: ='[1]MA 30'!BZ37 -> 0.022641036 | R43: ='[1]MA 30'!CC37 -> 7.3509549 | S43: ='[1]MA 30'!CD37 -> 0.71412228 | T43: ='[1]MA 30'!CE37 -> 0.025589138 | U43: ='[1]MA 30'!CH37 -> 7.262993 | V43: ='[1]MA 30'!CI37 -> 0.72115542 | W43: ='[1]MA 30'!CJ37 -> 0.0041336774 | X43: ='[1]MA 30'!BS37 -> 7.3025935 | Y43: ='[1]MA 30'!BT37 -> 0.72286006 | Z43: ='[1]MA 30'!BU37 -> 0.021391636 | AB43: ='[1]MA 45'!BX37 -> 7.3000862 | AC43: ='[1]MA 45'!BY37 -> 0.72506254 | AD43: ='[1]MA 45'!BZ37 -> 0.006988007 | AE43: ='[1]MA 45'!CC37 -> 7.2971702 | AF43: ='[1]MA 45'!CD37 -> 0.75155482 | AG43: ='[1]MA 45'!CE37 -> 0.010120447 | AH43: ='[1]MA 45'!CH37 -> 7.2332553 | AI43: ='[1]MA 45'!CI37 -> 0.73992942 | AJ43: ='[1]MA 45'!CJ37 -> 0.007627463 | AK43: ='[1]MA 45'!BS37 -> 7.2768372 | AL43: ='[1]MA 45'!BT37 -> 0.73884893 | AM43: ='[1]MA 45'!BU37 -> 0.01368826 | BJ43: =A43 -> 7.25 | BK43: =L43 -> 0.70100627 | BL43: =0.8243*A43^(-0.083) -> 0.69932209 | BM43: =(BK43-BL43)*100 -> 0.16841862 | BO43: =Y43 -> 0.72286006 | BP43: =0.8574*A43^(-0.085) -> 0.72452729 | BQ43: =(BO43-BP43)*100 -> -0.16672341 | BS43: =AL43 -> 0.73884893 | BT43: =0.8819*A43^(-0.087) -> 0.74228372 | BU43: =(BS43-BT43)*100 -> -0.34347937
A44: 7.5 | B44: ='[1]MA 15'!BX38 -> 7.4179409 | C44: ='[1]MA 15'!BY38 -> 0.70072358 | D44: ='[1]MA 15'!BZ38 -> 0.0086772962 | E44: ='[1]MA 15'!CC38 -> 7.5586138 | F44: ='[1]MA 15'!CD38 -> 0.67478737 | G44: ='[1]MA 15'!CE38 -> 0.0060650789 | H44: ='[1]MA 15'!CH38 -> 7.577189 | I44: ='[1]MA 15'!CI38 -> 0.72145999 | J44: ='[1]MA 15'!CJ38 -> 0.004964164 | K44: ='[1]MA 15'!BS38 -> 7.5179146 | L44: ='[1]MA 15'!BT38 -> 0.69899032 | M44: ='[1]MA 15'!BU38 -> 0.020251723 | O44: ='[1]MA 30'!BX38 -> 7.5453441 | P44: ='[1]MA 30'!BY38 -> 0.73140027 | Q44: ='[1]MA 30'!BZ38 -> 0.022652214 | R44: ='[1]MA 30'!CC38 -> 7.6044361 | S44: ='[1]MA 30'!CD38 -> 0.71227083 | T44: ='[1]MA 30'!CE38 -> 0.025684604 | U44: ='[1]MA 30'!CH38 -> 7.5134411 | V44: ='[1]MA 30'!CI38 -> 0.71852161 | W44: ='[1]MA 30'!CJ38 -> 0.0049122341 | X44: ='[1]MA 30'!BS38 -> 7.5544071 | Y44: ='[1]MA 30'!BT38 -> 0.7207309 | Z44: ='[1]MA 30'!BU38 -> 0.021503806 | AB44: ='[1]MA 45'!BX38 -> 7.5518134 | AC44: ='[1]MA 45'!BY38 -> 0.72308311 | AD44: ='[1]MA 45'!BZ38 -> 0.0070270806 | AE44: ='[1]MA 45'!CC38 -> 7.5487967 | AF44: ='[1]MA 45'!CD38 -> 0.74960843 | AG44: ='[1]MA 45'!CE38 -> 0.010161681 | AH44: ='[1]MA 45'!CH38 -> 7.4826779 | AI44: ='[1]MA 45'!CI38 -> 0.73807367 | AJ44: ='[1]MA 45'!CJ38 -> 0.00767015 | AK44: ='[1]MA 45'!BS38 -> 7.5277627 | AL44: ='[1]MA 45'!BT38 -> 0.73692174 | AM44: ='[1]MA 45'!BU38 -> 0.013726588 | BJ44: =A44 -> 7.5 | BK44: =L44 -> 0.69899032 | BL44: =0.8243*A44^(-0.083) -> 0.69735708 | BM44: =(BK44-BL44)*100 -> 0.16332354 | BO44: =Y44 -> 0.7207309 | BP44: =0.8574*A44^(-0.085) -> 0.72244247 | BQ44: =(BO44-BP44)*100 -> -0.17115714 | BS44: =AL44 -> 0.73692174 | BT44: =0.8819*A44^(-0.087) -> 0.74009763 | BU44: =(BS44-BT44)*100 -> -0.31758893
A45: 7.75 | B45: ='[1]MA 15'!BX39 -> 7.6708584 | C45: ='[1]MA 15'!BY39 -> 0.69889684 | D45: ='[1]MA 15'!BZ39 -> 0.008696452 | E45: ='[1]MA 15'!CC39 -> 7.8105676 | F45: ='[1]MA 15'!CD39 -> 0.67231747 | G45: ='[1]MA 15'!CE39 -> 0.0062886159 | H45: ='[1]MA 15'!CH39 -> 7.829762 | I45: ='[1]MA 15'!CI39 -> 0.71888601 | J45: ='[1]MA 15'!CJ39 -> 0.0053574601 | K45: ='[1]MA 15'!BS39 -> 7.770396 | L45: ='[1]MA 15'!BT39 -> 0.69670011 | M45: ='[1]MA 15'!BU39 -> 0.020293104 | O45: ='[1]MA 30'!BX39 -> 7.7968556 | P45: ='[1]MA 30'!BY39 -> 0.72956517 | Q45: ='[1]MA 30'!BZ39 -> 0.022662475 | R45: ='[1]MA 30'!CC39 -> 7.8579173 | S45: ='[1]MA 30'!CD39 -> 0.71048908 | T45: ='[1]MA 30'!CE39 -> 0.025826287 | U45: ='[1]MA 30'!CH39 -> 7.7638891 | V45: ='[1]MA 30'!CI39 -> 0.71544745 | W45: ='[1]MA 30'!CJ39 -> 0.0040946948 | X45: ='[1]MA 30'!BS39 -> 7.8062207 | Y45: ='[1]MA 30'!BT39 -> 0.71850057 | Z45: ='[1]MA 30'!BU39 -> 0.021550578 | AB45: ='[1]MA 45'!BX39 -> 7.8035405 | AC45: ='[1]MA 45'!BY39 -> 0.72116801 | AD45: ='[1]MA 45'!BZ39 -> 0.007068747 | AE45: ='[1]MA 45'!CC39 -> 7.8004233 | AF45: ='[1]MA 45'!CD39 -> 0.74773339 | AG45: ='[1]MA 45'!CE39 -> 0.010212642 | AH45: ='[1]MA 45'!CH39 -> 7.7321005 | AI45: ='[1]MA 45'!CI39 -> 0.73632742 | AJ45: ='[1]MA 45'!CJ39 -> 0.0076771255 | AK45: ='[1]MA 45'!BS39 -> 7.7786881 | AL45: ='[1]MA 45'!BT39 -> 0.73507627 | AM45: ='[1]MA 45'!BU39 -> 0.013764826 | BJ45: =A45 -> 7.75 | BK45: =L45 -> 0.69670011 | BL45: =0.8243*A45^(-0.083) -> 0.69546177 | BM45: =(BK45-BL45)*100 -> 0.1238343 | BO45: =Y45 -> 0.71850057 | BP45: =0.8574*A45^(-0.085) -> 0.72043173 | BQ45: =(BO45-BP45)*100 -> -0.19311653 | BS45: =AL45 -> 0.73507627 | BT45: =0.8819*A45^(-0.087) -> 0.73798935 | BU45: =(BS45-BT45)*100 -> -0.29130753
A46: 8 | B46: ='[1]MA 15'!BX40 -> 7.9237759 | C46: ='[1]MA 15'!BY40 -> 0.69716633 | D46: ='[1]MA 15'!BZ40 -> 0.0086090976 | E46: ='[1]MA 15'!CC40 -> 8.0625214 | F46: ='[1]MA 15'!CD40 -> 0.66978867 | G46: ='[1]MA 15'!CE40 -> 0.0065446271 | H46: ='[1]MA 15'!CH40 -> 8.0823349 | I46: ='[1]MA 15'!CI40 -> 0.71596014 | J46: ='[1]MA 15'!CJ40 -> 0.0048857614 | K46: ='[1]MA 15'!BS40 -> 8.0228774 | L46: ='[1]MA 15'!BT40 -> 0.69430505 | M46: ='[1]MA 15'!BU40 -> 0.020157728 | O46: ='[1]MA 30'!BX40 -> 8.0483671 | P46: ='[1]MA 30'!BY40 -> 0.7277536 | Q46: ='[1]MA 30'!BZ40 -> 0.022672325 | R46: ='[1]MA 30'!CC40 -> 8.1113985 | S46: ='[1]MA 30'!CD40 -> 0.70880629 | T46: ='[1]MA 30'!CE40 -> 0.025960157 | U46: ='[1]MA 30'!CH40 -> 8.0143371 | V46: ='[1]MA 30'!CI40 -> 0.71366874 | W46: ='[1]MA 30'!CJ40 -> 0.0040235408 | X46: ='[1]MA 30'!BS40 -> 8.0580342 | Y46: ='[1]MA 30'!BT40 -> 0.71674288 | Z46: ='[1]MA 30'!BU40 -> 0.021585711 | AB46: ='[1]MA 45'!BX40 -> 8.0552676 | AC46: ='[1]MA 45'!BY40 -> 0.71933799 | AD46: ='[1]MA 45'!BZ40 -> 0.0071194641 | AE46: ='[1]MA 45'!CC40 -> 8.0520499 | AF46: ='[1]MA 45'!CD40 -> 0.74592203 | AG46: ='[1]MA 45'!CE40 -> 0.010235684 | AH46: ='[1]MA 45'!CH40 -> 7.9815231 | AI46: ='[1]MA 45'!CI40 -> 0.73454808 | AJ46: ='[1]MA 45'!CJ40 -> 0.0076399507 | AK46: ='[1]MA 45'!BS40 -> 8.0296135 | AL46: ='[1]MA 45'!BT40 -> 0.73326937 | AM46: ='[1]MA 45'!BU40 -> 0.013779613 | BJ46: =A46 -> 8 | BK46: =L46 -> 0.69430505 | BL46: =0.8243*A46^(-0.083) -> 0.69363154 | BM46: =(BK46-BL46)*100 -> 0.067351119 | BO46: =Y46 -> 0.71674288 | BP46: =0.8574*A46^(-0.085) -> 0.71849017 | BQ46: =(BO46-BP46)*100 -> -0.17472932 | BS46: =AL46 -> 0.73326937 | BT46: =0.8819*A46^(-0.087) -> 0.73595374 | BU46: =(BS46-BT46)*100 -> -0.26843672 | BX46: 15 min | CA46: 30 min | CD46: 45 min
A47: 8.25 | B47: ='[1]MA 15'!BX41 -> 8.1766934 | C47: ='[1]MA 15'!BY41 -> 0.69494361 | D47: ='[1]MA 15'!BZ41 -> 0.0086991228 | E47: ='[1]MA 15'!CC41 -> 8.3144752 | F47: ='[1]MA 15'!CD41 -> 0.66728815 | G47: ='[1]MA 15'!CE41 -> 0.0068117995 | H47: ='[1]MA 15'!CH41 -> 8.3349079 | I47: ='[1]MA 15'!CI41 -> 0.71427147 | J47: ='[1]MA 15'!CJ41 -> 0.0048596709 | K47: ='[1]MA 15'!BS41 -> 8.2753588 | L47: ='[1]MA 15'!BT41 -> 0.69216774 | M47: ='[1]MA 15'!BU41 -> 0.020501755 | O47: ='[1]MA 30'!BX41 -> 8.2998785 | P47: ='[1]MA 30'!BY41 -> 0.72604089 | Q47: ='[1]MA 30'!BZ41 -> 0.022707341 | R47: ='[1]MA 30'!CC41 -> 8.2802352 | S47: ='[1]MA 30'!CD41 -> 0.70767921 | T47: ='[1]MA 30'!CE41 -> 0.026162187 | U47: ='[1]MA 30'!CH41 -> 8.2647852 | V47: ='[1]MA 30'!CI41 -> 0.71198076 | W47: ='[1]MA 30'!CJ41 -> 0.0039705217 | X47: ='[1]MA 30'!BS41 -> 8.281633 | Y47: ='[1]MA 30'!BT41 -> 0.71523362 | Z47: ='[1]MA 30'!BU41 -> 0.02160475 | AB47: ='[1]MA 45'!BX41 -> 8.3069947 | AC47: ='[1]MA 45'!BY41 -> 0.71756695 | AD47: ='[1]MA 45'!BZ41 -> 0.0071730766 | AE47: ='[1]MA 45'!CC41 -> 8.3036764 | AF47: ='[1]MA 45'!CD41 -> 0.74422232 | AG47: ='[1]MA 45'!CE41 -> 0.010377435 | AH47: ='[1]MA 45'!CH41 -> 8.2309457 | AI47: ='[1]MA 45'!CI41 -> 0.73285609 | AJ47: ='[1]MA 45'!CJ41 -> 0.0076688075 | AK47: ='[1]MA 45'!BS41 -> 8.2805389 | AL47: ='[1]MA 45'!BT41 -> 0.73154845 | AM47: ='[1]MA 45'!BU41 -> 0.013853686 | BJ47: =A47 -> 8.25 | BK47: =L47 -> 0.69216774 | BL47: =0.8243*A47^(-0.083) -> 0.69186223 | BM47: =(BK47-BL47)*100 -> 0.030551205 | BO47: =Y47 -> 0.71523362 | BP47: =0.8574*A47^(-0.085) -> 0.71661335 | BQ47: =(BO47-BP47)*100 -> -0.13797259 | BS47: =AL47 -> 0.73154845 | BT47: =0.8819*A47^(-0.087) -> 0.73398612 | BU47: =(BS47-BT47)*100 -> -0.24376701 | BX47: mm | BY47: hrs | CA47: mm | CB47: hrs | CD47: mm | CE47: hrs
A48: 8.5 | B48: ='[1]MA 15'!BX42 -> 8.4296109 | C48: ='[1]MA 15'!BY42 -> 0.6938124 | D48: ='[1]MA 15'!BZ42 -> 0.0085247999 | E48: ='[1]MA 15'!CC42 -> 8.566429 | F48: ='[1]MA 15'!CD42 -> 0.66506657 | G48: ='[1]MA 15'!CE42 -> 0.0069724096 | H48: ='[1]MA 15'!CH42 -> 8.5874809 | I48: ='[1]MA 15'!CI42 -> 0.71268707 | J48: ='[1]MA 15'!CJ42 -> 0.0048395188 | K48: ='[1]MA 15'!BS42 -> 8.5278402 | L48: ='[1]MA 15'!BT42 -> 0.69052201 | M48: ='[1]MA 15'!BU42 -> 0.020775015 | O48: ='[1]MA 30'!BX42 -> 8.55139 | P48: ='[1]MA 30'!BY42 -> 0.72436792 | Q48: ='[1]MA 30'!BZ42 -> 0.022696112 | R48: ='[1]MA 30'!CC42 -> 8.5337164 | S48: ='[1]MA 30'!CD42 -> 0.70605353 | T48: ='[1]MA 30'!CE42 -> 0.026249937 | U48: ='[1]MA 30'!CH42 -> 8.5152332 | V48: ='[1]MA 30'!CI42 -> 0.71030873 | W48: ='[1]MA 30'!CJ42 -> 0.0039235967 | X48: ='[1]MA 30'!BS42 -> 8.5334465 | Y48: ='[1]MA 30'!BT42 -> 0.71357673 | Z48: ='[1]MA 30'!BU42 -> 0.021627878 | AB48: ='[1]MA 45'!BX42 -> 8.5587218 | AC48: ='[1]MA 45'!BY42 -> 0.71581298 | AD48: ='[1]MA 45'!BZ42 -> 0.0072076849 | AE48: ='[1]MA 45'!CC42 -> 8.555303 | AF48: ='[1]MA 45'!CD42 -> 0.74242691 | AG48: ='[1]MA 45'!CE42 -> 0.010266543 | AH48: ='[1]MA 45'!CH42 -> 8.4803683 | AI48: ='[1]MA 45'!CI42 -> 0.73122666 | AJ48: ='[1]MA 45'!CJ42 -> 0.0076673533 | AK48: ='[1]MA 45'!BS42 -> 8.5314643 | AL48: ='[1]MA 45'!BT42 -> 0.72982218 | AM48: ='[1]MA 45'!BU42 -> 0.013823294 | BJ48: =A48 -> 8.5 | BK48: =L48 -> 0.69052201 | BL48: =0.8243*A48^(-0.083) -> 0.69015006 | BM48: =(BK48-BL48)*100 -> 0.037195549 | BO48: =Y48 -> 0.71357673 | BP48: =0.8574*A48^(-0.085) -> 0.71479725 | BQ48: =(BO48-BP48)*100 -> -0.12205193 | BS48: =AL48 -> 0.72982218 | BT48: =0.8819*A48^(-0.087) -> 0.73208228 | BU48: =(BS48-BT48)*100 -> -0.2260099 | BW48: Start | BX48: =BB27 -> 0.7977 | BY48: =A27 -> 3.25 | CA48: =BE24 -> 0.83805 | CB48: =A24 -> 2.5 | CD48: =BH25 -> 0.827925 | CE48: =A25 -> 2.75
A49: 8.75 | B49: ='[1]MA 15'!BX43 -> 8.6825284 | C49: ='[1]MA 15'!BY43 -> 0.69116661 | D49: ='[1]MA 15'!BZ43 -> 0.0088455483 | E49: ='[1]MA 15'!CC43 -> 8.8183828 | F49: ='[1]MA 15'!CD43 -> 0.66290687 | G49: ='[1]MA 15'!CE43 -> 0.0071609732 | H49: ='[1]MA 15'!CH43 -> 8.8400538 | I49: ='[1]MA 15'!CI43 -> 0.71112901 | J49: ='[1]MA 15'!CJ43 -> 0.0048100001 | K49: ='[1]MA 15'!BS43 -> 8.7803217 | L49: ='[1]MA 15'!BT43 -> 0.68840083 | M49: ='[1]MA 15'!BU43 -> 0.021030304 | O49: ='[1]MA 30'!BX43 -> 8.8029015 | P49: ='[1]MA 30'!BY43 -> 0.72272546 | Q49: ='[1]MA 30'!BZ43 -> 0.022694405 | R49: ='[1]MA 30'!CC43 -> 8.7871976 | S49: ='[1]MA 30'!CD43 -> 0.70451314 | T49: ='[1]MA 30'!CE43 -> 0.026304573 | U49: ='[1]MA 30'!CH43 -> 8.7656813 | V49: ='[1]MA 30'!CI43 -> 0.70870666 | W49: ='[1]MA 30'!CJ43 -> 0.0038491578 | X49: ='[1]MA 30'!BS43 -> 8.7852601 | Y49: ='[1]MA 30'!BT43 -> 0.71198176 | Z49: ='[1]MA 30'!BU43 -> 0.021631122 | AB49: ='[1]MA 45'!BX43 -> 8.8104489 | AC49: ='[1]MA 45'!BY43 -> 0.71414635 | AD49: ='[1]MA 45'!BZ43 -> 0.0072576166 | AE49: ='[1]MA 45'!CC43 -> 8.8069295 | AF49: ='[1]MA 45'!CD43 -> 0.74089498 | AG49: ='[1]MA 45'!CE43 -> 0.010421739 | AH49: ='[1]MA 45'!CH43 -> 8.7297909 | AI49: ='[1]MA 45'!CI43 -> 0.72964809 | AJ49: ='[1]MA 45'!CJ43 -> 0.0076553197 | AK49: ='[1]MA 45'!BS43 -> 8.7823898 | AL49: ='[1]MA 45'!BT43 -> 0.72822981 | AM49: ='[1]MA 45'!BU43 -> 0.013912243 | BJ49: =A49 -> 8.75 | BK49: =L49 -> 0.68840083 | BL49: =0.8243*A49^(-0.083) -> 0.68849158 | BM49: =(BK49-BL49)*100 -> -0.0090748497 | BO49: =Y49 -> 0.71198176 | BP49: =0.8574*A49^(-0.085) -> 0.7130382 | BQ49: =(BO49-BP49)*100 -> -0.10564398 | BS49: =AL49 -> 0.72822981 | BT49: =0.8819*A49^(-0.087) -> 0.73023836 | BU49: =(BS49-BT49)*100 -> -0.20085509 | BW49: End | BX49: =BK46 -> 0.69430505 | BY49: =A46 -> 8 | CA49: =BO50 -> 0.71057922 | CB49: =A50 -> 9 | CD49: =BS56 -> 0.71806496 | CE49: =A56 -> 10.5
A50: 9 | B50: ='[1]MA 15'!BX44 -> 8.9354459 | C50: ='[1]MA 15'!BY44 -> 0.68943168 | D50: ='[1]MA 15'!BZ44 -> 0.0089317463 | E50: ='[1]MA 15'!CC44 -> 9.0703366 | F50: ='[1]MA 15'!CD44 -> 0.66085179 | G50: ='[1]MA 15'!CE44 -> 0.0073445383 | H50: ='[1]MA 15'!CH44 -> 9.0926268 | I50: ='[1]MA 15'!CI44 -> 0.70968806 | J50: ='[1]MA 15'!CJ44 -> 0.004786406 | K50: ='[1]MA 15'!BS44 -> 9.0328031 | L50: ='[1]MA 15'!BT44 -> 0.68665717 | M50: ='[1]MA 15'!BU44 -> 0.021296833 | O50: ='[1]MA 30'!BX44 -> 9.054413 | P50: ='[1]MA 30'!BY44 -> 0.7211641 | Q50: ='[1]MA 30'!BZ44 -> 0.022680193 | R50: ='[1]MA 30'!CC44 -> 8.9561472 | S50: ='[1]MA 30'!CD44 -> 0.70343337 | T50: ='[1]MA 30'!CE44 -> 0.026884504 | U50: ='[1]MA 30'!CH44 -> 9.0161293 | V50: ='[1]MA 30'!CI44 -> 0.70714018 | W50: ='[1]MA 30'!CJ44 -> 0.003792678 | X50: ='[1]MA 30'!BS44 -> 9.0088965 | Y50: ='[1]MA 30'!BT44 -> 0.71057922 | Z50: ='[1]MA 30'!BU44 -> 0.021805825 | AB50: ='[1]MA 45'!BX44 -> 9.062176 | AC50: ='[1]MA 45'!BY44 -> 0.71252321 | AD50: ='[1]MA 45'!BZ44 -> 0.0073053951 | AE50: ='[1]MA 45'!CC44 -> 9.0585561 | AF50: ='[1]MA 45'!CD44 -> 0.73942842 | AG50: ='[1]MA 45'!CE44 -> 0.010570952 | AH50: ='[1]MA 45'!CH44 -> 8.9792135 | AI50: ='[1]MA 45'!CI44 -> 0.7281107 | AJ50: ='[1]MA 45'!CJ44 -> 0.0076563616 | AK50: ='[1]MA 45'!BS44 -> 9.0333152 | AL50: ='[1]MA 45'!BT44 -> 0.72668745 | AM50: ='[1]MA 45'!BU44 -> 0.014008537 | BJ50: =A50 -> 9 | BK50: =L50 -> 0.68665717 | BL50: =0.8243*A50^(-0.083) -> 0.68688364 | BM50: =(BK50-BL50)*100 -> -0.022646452 | BO50: =Y50 -> 0.71057922 | BP50: =0.8574*A50^(-0.085) -> 0.71133285 | BQ50: =(BO50-BP50)*100 -> -0.075363567 | BS50: =AL50 -> 0.72668745 | BT50: =0.8819*A50^(-0.087) -> 0.72845083 | BU50: =(BS50-BT50)*100 -> -0.17633879
A51: 9.25 | B51: ='[1]MA 15'!BX45 -> 9.1883634 | C51: ='[1]MA 15'!BY45 -> 0.68770148 | D51: ='[1]MA 15'!BZ45 -> 0.0090194412 | E51: ='[1]MA 15'!CC45 -> 9.3222904 | F51: ='[1]MA 15'!CD45 -> 0.65884859 | G51: ='[1]MA 15'!CE45 -> 0.007510317 | H51: ='[1]MA 15'!CH45 -> 9.2607163 | I51: ='[1]MA 15'!CI45 -> 0.70871055 | J51: ='[1]MA 15'!CJ45 -> 0.0045476446 | K51: ='[1]MA 15'!BS45 -> 9.2571233 | L51: ='[1]MA 15'!BT45 -> 0.68508687 | M51: ='[1]MA 15'!BU45 -> 0.021693303 | O51: ='[1]MA 30'!BX45 -> 9.3059244 | P51: ='[1]MA 30'!BY45 -> 0.71963072 | Q51: ='[1]MA 30'!BZ45 -> 0.02268036 | R51: ='[1]MA 30'!CC45 -> 9.2096284 | S51: ='[1]MA 30'!CD45 -> 0.70193308 | T51: ='[1]MA 30'!CE45 -> 0.026916094 | U51: ='[1]MA 30'!CH45 -> 9.2665773 | V51: ='[1]MA 30'!CI45 -> 0.7056146 | W51: ='[1]MA 30'!CJ45 -> 0.0037397319 | X51: ='[1]MA 30'!BS45 -> 9.2607101 | Y51: ='[1]MA 30'!BT45 -> 0.70905947 | Z51: ='[1]MA 30'!BU45 -> 0.021811804 | AB51: ='[1]MA 45'!BX45 -> 9.3139031 | AC51: ='[1]MA 45'!BY45 -> 0.71094706 | AD51: ='[1]MA 45'!BZ45 -> 0.007338141 | AE51: ='[1]MA 45'!CC45 -> 9.3101827 | AF51: ='[1]MA 45'!CD45 -> 0.73791934 | AG51: ='[1]MA 45'!CE45 -> 0.010636394 | AH51: ='[1]MA 45'!CH45 -> 9.2286361 | AI51: ='[1]MA 45'!CI45 -> 0.72664104 | AJ51: ='[1]MA 45'!CJ45 -> 0.0076074277 | AK51: ='[1]MA 45'!BS45 -> 9.2842406 | AL51: ='[1]MA 45'!BT45 -> 0.72516915 | AM51: ='[1]MA 45'!BU45 -> 0.014045827 | BJ51: =A51 -> 9.25 | BK51: =L51 -> 0.68508687 | BL51: =0.8243*A51^(-0.083) -> 0.68532336 | BM51: =(BK51-BL51)*100 -> -0.02364862 | BO51: =Y51 -> 0.70905947 | BP51: =0.8574*A51^(-0.085) -> 0.70967815 | BQ51: =(BO51-BP51)*100 -> -0.061868037 | BS51: =AL51 -> 0.72516915 | BT51: =0.8819*A51^(-0.087) -> 0.72671648 | BU51: =(BS51-BT51)*100 -> -0.15473375 | BW51: Delta | BX51: =BX49-BX48 -> -0.10339495 | BY51: =BY49-BY48 -> 4.75 | CA51: =CA49-CA48 -> -0.12747078 | CB51: =CB49-CB48 -> 6.5 | CD51: =CD49-CD48 -> -0.10986004 | CE51: =CE49-CE48 -> 7.75
A52: 9.5 | B52: ='[1]MA 15'!BX46 -> 9.4412809 | C52: ='[1]MA 15'!BY46 -> 0.68680622 | D52: ='[1]MA 15'!BZ46 -> 0.0086954658 | E52: ='[1]MA 15'!CC46 -> 9.5742442 | F52: ='[1]MA 15'!CD46 -> 0.65700347 | G52: ='[1]MA 15'!CE46 -> 0.0076459105 | H52: ='[1]MA 15'!CH46 -> 9.5132893 | I52: ='[1]MA 15'!CI46 -> 0.70734082 | J52: ='[1]MA 15'!CJ46 -> 0.0045066981 | K52: ='[1]MA 15'!BS46 -> 9.5096048 | L52: ='[1]MA 15'!BT46 -> 0.68371684 | M52: ='[1]MA 15'!BU46 -> 0.021875574 | O52: ='[1]MA 30'!BX46 -> 9.5574359 | P52: ='[1]MA 30'!BY46 -> 0.71816147 | Q52: ='[1]MA 30'!BZ46 -> 0.02265898 | R52: ='[1]MA 30'!CC46 -> 9.4631096 | S52: ='[1]MA 30'!CD46 -> 0.7004178 | T52: ='[1]MA 30'!CE46 -> 0.026912873 | U52: ='[1]MA 30'!CH46 -> 9.5170254 | V52: ='[1]MA 30'!CI46 -> 0.70407943 | W52: ='[1]MA 30'!CJ46 -> 0.0037527313 | X52: ='[1]MA 30'!BS46 -> 9.5125236 | Y52: ='[1]MA 30'!BT46 -> 0.7075529 | Z52: ='[1]MA 30'!BU46 -> 0.021812318 | AB52: ='[1]MA 45'!BX46 -> 9.5656302 | AC52: ='[1]MA 45'!BY46 -> 0.70940656 | AD52: ='[1]MA 45'!BZ46 -> 0.0073728969 | AE52: ='[1]MA 45'!CC46 -> 9.5618092 | AF52: ='[1]MA 45'!CD46 -> 0.7363711 | AG52: ='[1]MA 45'!CE46 -> 0.010596477 | AH52: ='[1]MA 45'!CH46 -> 9.4780587 | AI52: ='[1]MA 45'!CI46 -> 0.72517641 | AJ52: ='[1]MA 45'!CJ46 -> 0.0075696336 | AK52: ='[1]MA 45'!BS46 -> 9.535166 | AL52: ='[1]MA 45'!BT46 -> 0.72365136 | AM52: ='[1]MA 45'!BU46 -> 0.014035383 | BJ52: =A52 -> 9.5 | BK52: =L52 -> 0.68371684 | BL52: =0.8243*A52^(-0.083) -> 0.6838081 | BM52: =(BK52-BL52)*100 -> -0.0091263345 | BO52: =Y52 -> 0.7075529 | BP52: =0.8574*A52^(-0.085) -> 0.70807127 | BQ52: =(BO52-BP52)*100 -> -0.051836947 | BS52: =AL52 -> 0.72365136 | BT52: =0.8819*A52^(-0.087) -> 0.72503236 | BU52: =(BS52-BT52)*100 -> -0.13810013
...

Sheet Pitched Blade Impeller (1)
A1: Pitched Blade Impeller (1) | I1: 23 | J1: 25 | K1: 26
I2: 37 | J2: 36 | K2: 36
B4: 15 minutes mixing | O4: 30 minutes mixing | AB4: 45 minutes mixing
B5: Series 1 | E5: Series 2 | H5: Series 3 | K5: Across Series | O5: Series 1 | R5: Series 2 | U5: Series 3 | X5: Across Series | AB5: Series 1 | AE5: Series 2 | AH5: Series 3 | AK5: Across Series
B6: Time | C6: Average | D6: St. Dev. | E6: Time | F6: Average | G6: St. Dev. | H6: Time | I6: Average | J6: St. Dev. | K6: Time | L6: Average | M6: St. Dev. | O6: Time | P6: Average | Q6: St. Dev. | R6: Time | S6: Average | T6: St. Dev. | U6: Time | V6: Average | W6: St. Dev. | X6: Time | Y6: Average | Z6: St. Dev. | AB6: Time | AC6: Average | AD6: St. Dev. | AE6: Time | AF6: Average | AG6: St. Dev. | AH6: Time | AI6: Average | AJ6: St. Dev. | AK6: Time | AL6: Average | AM6: St. Dev.
A7: Settlement | D7: =AVERAGE(D15:D22) -> 0.0014947222 | G7: =AVERAGE(G15:G22) -> 0.0010374969 | J7: =AVERAGE(J15:J22) -> 0.0011798541 | M7: =AVERAGE(M15:M22) -> 0.0087112248 | Q7: =AVERAGE(Q15:Q24) -> 0.001129283 | T7: =AVERAGE(T15:T24) -> 0.0032519729 | W7: =AVERAGE(W15:W24) -> 0.0033192587 | Z7: =AVERAGE(Z15:Z24) -> 0.0096605931 | AD7: =AVERAGE(AD15:AD25) -> 0.0024231901 | AG7: =AVERAGE(AG15:AG25) -> 0.0058105738 | AJ7: =AVERAGE(AJ15:AJ25) -> 0.0034361522 | AM7: =AVERAGE(AM15:AM25) -> 0.013289804
A8: Hindered Settling | D8: =AVERAGE(D23:D36) -> 0.013705695 | G8: =AVERAGE(G23:G36) -> 0.0057410278 | J8: =AVERAGE(J23:J36) -> 0.002133421 | M8: =AVERAGE(M23:M36) -> 0.012845198 | Q8: =AVERAGE(Q25:Q35) -> 0.0036320226 | T8: =AVERAGE(T25:T35) -> 0.0037351671 | W8: =AVERAGE(W25:W35) -> 0.0071028406 | Z8: =AVERAGE(Z25:Z35) -> 0.014898597 | AD8: =AVERAGE(AD26:AD35) -> 0.0025545236 | AG8: =AVERAGE(AG26:AG35) -> 0.0033654026 | AJ8: =AVERAGE(AJ26:AJ35) -> 0.0036341034 | AM8: =AVERAGE(AM26:AM35) -> 0.013337131
A9: Consolidation | D9: =AVERAGE(D37:D116) -> 0.020935556 | G9: =AVERAGE(G37:G116) -> 0.0083676538 | J9: =AVERAGE(J37:J116) -> 0.0086041019 | M9: =AVERAGE(M37:M116) -> 0.016169401 | Q9: =AVERAGE(Q36:Q116) -> 0.0045526437 | T9: =AVERAGE(T36:T116) -> 0.0052829058 | W9: =AVERAGE(W36:W116) -> 0.0082117472 | Z9: =AVERAGE(Z36:Z116) -> 0.0078470009 | AD9: =AVERAGE(AD36:AD116) -> 0.0019514401 | AG9: =AVERAGE(AG36:AG116) -> 0.0065432646 | AJ9: =AVERAGE(AJ36:AJ116) -> 0.0097196906 | AM9: =AVERAGE(AM36:AM116) -> 0.0092799951
M11: ='[1]PB1 15'!$BU$4 -> 1620.9385 | Z11: ='[1]PB1 30'!$BU$4 -> 1598.061 | AM11: ='[1]PB1 45'!$BU$4 -> 1609.0848 | BK11: Consolidation Phase
B12: 15 minutes mixing | O12: 30 minutes mixing | AB12: 45 minutes mixing | BK12: 15 min - Power law | BO12: 30 min - Power law | BS12: 45 min - Power law
A13: Time | B13: Series 1 | E13: Series 2 | H13: Series 3 | K13: Across Series | O13: Series 1 | R13: Series 2 | U13: Series 3 | X13: Across Series | AB13: Series 1 | AE13: Series 2 | AH13: Series 3 | AK13: Across Series | BB13: 15 min | BE13: 30 min | BH13: 45 min | BK13: Data | BL13: EQ | BM13: Delta | BO13: Data | BP13: EQ | BQ13: Delta | BS13: Data | BT13: EQ | BU13: Delta
