Workbook
Name biotool: #REF!
Name Concentration_DNA_table: #REF!
Name DNA_concentration: 'Sample Log'!#REF!
Name dna_log: 'Sample Log'!$A$2:$C$98
Name FluidX_data: #REF!
Name Job_number: 'Sample Log'!#REF!
Name MDU_NUMBERS: 'Sample Log'!$C$3:$C$98
Name Species: 'Sample Log'!#REF!
Name WELLS96: #REF!

Sheet Sample Log
E1: Plate nr: | G1: Plate 1
A2: Well | B2: Pos | C2: Sample ID | D2: Comment | E2: Date (DD/MM/YYYY): | G2: 43985
A3: 1 | B3: A1 | C3: Sample_1 | D3: This is a comment
A4: 2 | B4: B1 | C4: Sample_2
A5: 3 | B5: C1 | C5: Sample_3
A6: 4 | B6: D1 | C6: Sample_4
A7: 5 | B7: E1 | C7: Sample_5
A8: 6 | B8: F1 | C8: Sample_6
A9: 7 | B9: G1 | C9: Sample_7
A10: 8 | B10: H1 | C10: Sample_8
A11: 9 | B11: A2 | C11: Sample_9
A12: 10 | B12: B2 | C12: Sample_10
A13: 11 | B13: C2 | C13: Sample_11
A14: 12 | B14: D2 | C14: Sample_12
A15: 13 | B15: E2 | C15: Sample_13
... A98: 96 | B98: H12 | C98: Sample_96

Sheet Plate Dispensing Charts
A1: Extraction 1
B2: 1 | C2: 2 | D2: 3 | E2: 4 | F2: 5 | G2: 6 | H2: 7 | I2: 8 | J2: 9 | K2: 10 | L2: 11 | M2: 12
A3: A | B3: ='Sample Log'!C10 -> Sample_8 | F3: ='Sample Log'!C18 -> Sample_16 | J3: ='Sample Log'!C26 -> Sample_24
A4: B | B4: ='Sample Log'!C9 -> Sample_7 | F4: ='Sample Log'!C17 -> Sample_15 | J4: ='Sample Log'!C25 -> Sample_23
A5: C | B5: ='Sample Log'!C8 -> Sample_6 | F5: ='Sample Log'!C16 -> Sample_14 | J5: ='Sample Log'!C24 -> Sample_22
A6: D | B6: ='Sample Log'!C7 -> Sample_5 | F6: ='Sample Log'!C15 -> Sample_13 | J6: ='Sample Log'!C23 -> Sample_21
A7: E | B7: ='Sample Log'!C6 -> Sample_4 | F7: ='Sample Log'!C14 -> Sample_12 | J7: ='Sample Log'!C22 -> Sample_20
A8: F | B8: ='Sample Log'!C5 -> Sample_3 | F8: ='Sample Log'!C13 -> Sample_11 | J8: ='Sample Log'!C21 -> Sample_19
A9: G | B9: ='Sample Log'!C4 -> Sample_2 | F9: ='Sample Log'!C12 -> Sample_10 | J9: ='Sample Log'!C20 -> Sample_18
A10: H | B10: ='Sample Log'!C3 -> Sample_1 | F10: ='Sample Log'!C11 -> Sample_9 | J10: ='Sample Log'!C19 -> Sample_17
A15: Extraction 2
B16: 1 | C16: 2 | D16: 3 | E16: 4 | F16: 5 | G16: 6 | H16: 7 | I16: 8 | J16: 9 | K16: 10 | L16: 11 | M16: 12
A17: A | B17: ='Sample Log'!C34 -> Sample_32 | F17: ='Sample Log'!C42 -> Sample_40 | J17: ='Sample Log'!C50 -> Sample_48
A18: B | B18: ='Sample Log'!C33 -> Sample_31 | F18: ='Sample Log'!C41 -> Sample_39 | J18: ='Sample Log'!C49 -> Sample_47
A19: C | B19: ='Sample Log'!C32 -> Sample_30 | F19: ='Sample Log'!C40 -> Sample_38 | J19: ='Sample Log'!C48 -> Sample_46
A20: D | B20: ='Sample Log'!C31 -> Sample_29 | F20: ='Sample Log'!C39 -> Sample_37 | J20: ='Sample Log'!C47 -> Sample_45
A21: E | B21: ='Sample Log'!C30 -> Sample_28 | F21: ='Sample Log'!C38 -> Sample_36 | J21: ='Sample Log'!C46 -> Sample_44
A22: F | B22: ='Sample Log'!C29 -> Sample_27 | F22: ='Sample Log'!C37 -> Sample_35 | J22: ='Sample Log'!C45 -> Sample_43
A23: G | B23: ='Sample Log'!C28 -> Sample_26 | F23: ='Sample Log'!C36 -> Sample_34 | J23: ='Sample Log'!C44 -> Sample_42
A24: H | B24: ='Sample Log'!C27 -> Sample_25 | F24: ='Sample Log'!C35 -> Sample_33 | J24: ='Sample Log'!C43 -> Sample_41
A27: Extraction 3
B28: 1 | C28: 2 | D28: 3 | E28: 4 | F28: 5 | G28: 6 | H28: 7 | I28: 8 | J28: 9 | K28: 10 | L28: 11 | M28: 12
A29: A | B29: ='Sample Log'!C58 -> Sample_56 | F29: ='Sample Log'!C66 -> Sample_64 | J29: ='Sample Log'!C74 -> Sample_72
A30: B | B30: ='Sample Log'!C57 -> Sample_55 | F30: ='Sample Log'!C65 -> Sample_63 | J30: ='Sample Log'!C73 -> Sample_71
A31: C | B31: ='Sample Log'!C56 -> Sample_54 | F31: ='Sample Log'!C64 -> Sample_62 | J31: ='Sample Log'!C72 -> Sample_70
A32: D | B32: ='Sample Log'!C55 -> Sample_53 | F32: ='Sample Log'!C63 -> Sample_61 | J32: ='Sample Log'!C71 -> Sample_69
A33: E | B33: ='Sample Log'!C54 -> Sample_52 | F33: ='Sample Log'!C62 -> Sample_60 | J33: ='Sample Log'!C70 -> Sample_68
A34: F | B34: ='Sample Log'!C53 -> Sample_51 | F34: ='Sample Log'!C61 -> Sample_59 | J34: ='Sample Log'!C69 -> Sample_67
A35: G | B35: ='Sample Log'!C52 -> Sample_50 | F35: ='Sample Log'!C60 -> Sample_58 | J35: ='Sample Log'!C68 -> Sample_66
A36: H | B36: ='Sample Log'!C51 -> Sample_49 | F36: ='Sample Log'!C59 -> Sample_57 | J36: ='Sample Log'!C67 -> Sample_65
A41: Extraction 4
B42: 1 | C42: 2 | D42: 3 | E42: 4 | F42: 5 | G42: 6 | H42: 7 | I42: 8 | J42: 9 | K42: 10 | L42: 11 | M42: 12
A43: A | B43: ='Sample Log'!C82 -> Sample_80 | F43: ='Sample Log'!C90 -> Sample_88 | J43: ='Sample Log'!C98 -> Sample_96
A44: B | B44: ='Sample Log'!C81 -> Sample_79 | F44: ='Sample Log'!C89 -> Sample_87 | J44: ='Sample Log'!C97 -> Sample_95
A45: C | B45: ='Sample Log'!C80 -> Sample_78 | F45: ='Sample Log'!C88 -> Sample_86 | J45: ='Sample Log'!C96 -> Sample_94
A46: D | B46: ='Sample Log'!C79 -> Sample_77 | F46: ='Sample Log'!C87 -> Sample_85 | J46: ='Sample Log'!C95 -> Sample_93
A47: E | B47: ='Sample Log'!C78 -> Sample_76 | F47: ='Sample Log'!C86 -> Sample_84 | J47: ='Sample Log'!C94 -> Sample_92
A48: F | B48: ='Sample Log'!C77 -> Sample_75 | F48: ='Sample Log'!C85 -> Sample_83 | J48: ='Sample Log'!C93 -> Sample_91
A49: G | B49: ='Sample Log'!C76 -> Sample_74 | F49: ='Sample Log'!C84 -> Sample_82 | J49: ='Sample Log'!C92 -> Sample_90
A50: H | B50: ='Sample Log'!C75 -> Sample_73 | F50: ='Sample Log'!C83 -> Sample_81 | J50: ='Sample Log'!C91 -> Sample_89
...

Sheet QuantStudio Plate Setup
A1: [Sample Setup]
A2: Well | B2: Well Position | C2: Sample Name | D2: Target Name | E2: Task | F2: Reporter | G2: Quencher | H2: Extraction date | I2: Comments
A3: 1 | B3: A1 | C3: ='Sample Log'!C10 -> Sample_8 | D3: Hu RNAse P | E3: UNKNOWN | F3: FAM | G3: NONE | H3: ='Sample Log'!$G$2 -> 43985 | I3: ='Sample Log'!D3 -> This is a comment
A4: 2 | B4: A2 | C4: ='Sample Log'!C18 -> Sample_16 | D4: Hu RNAse P | E4: UNKNOWN | F4: FAM | G4: NONE | H4: ='Sample Log'!$G$2 -> 43985 | I4: ='Sample Log'!D4 -> 0
A5: 3 | B5: A3 | C5: ='Sample Log'!C26 -> Sample_24 | D5: Hu RNAse P | E5: UNKNOWN | F5: FAM | G5: NONE | H5: ='Sample Log'!$G$2 -> 43985 | I5: ='Sample Log'!D5 -> 0
A6: 4 | B6: A4 | C6: ='Sample Log'!C34 -> Sample_32 | D6: Hu RNAse P | E6: UNKNOWN | F6: FAM | G6: NONE | H6: ='Sample Log'!$G$2 -> 43985 | I6: ='Sample Log'!D6 -> 0
A7: 5 | B7: A5 | C7: ='Sample Log'!C42 -> Sample_40 | D7: Hu RNAse P | E7: UNKNOWN | F7: FAM | G7: NONE | H7: ='Sample Log'!$G$2 -> 43985 | I7: ='Sample Log'!D7 -> 0
A8: 6 | B8: A6 | C8: ='Sample Log'!C50 -> Sample_48 | D8: Hu RNAse P | E8: UNKNOWN | F8: FAM | G8: NONE | H8: ='Sample Log'!$G$2 -> 43985 | I8: ='Sample Log'!D8 -> 0
A9: 7 | B9: A7 | C9: ='Sample Log'!C58 -> Sample_56 | D9: Hu RNAse P | E9: UNKNOWN | F9: FAM | G9: NONE | H9: ='Sample Log'!$G$2 -> 43985 | I9: ='Sample Log'!D9 -> 0
A10: 8 | B10: A8 | C10: ='Sample Log'!C66 -> Sample_64 | D10: Hu RNAse P | E10: UNKNOWN | F10: FAM | G10: NONE | H10: ='Sample Log'!$G$2 -> 43985 | I10: ='Sample Log'!D10 -> 0
A11: 9 | B11: A9 | C11: ='Sample Log'!C74 -> Sample_72 | D11: Hu RNAse P | E11: UNKNOWN | F11: FAM | G11: NONE | H11: ='Sample Log'!$G$2 -> 43985 | I11: ='Sample Log'!D11 -> 0
A12: 10 | B12: A10 | C12: ='Sample Log'!C82 -> Sample_80 | D12: Hu RNAse P | E12: UNKNOWN | F12: FAM | G12: NONE | H12: ='Sample Log'!$G$2 -> 43985 | I12: ='Sample Log'!D12 -> 0
A13: 11 | B13: A11 | C13: ='Sample Log'!C90 -> Sample_88 | D13: Hu RNAse P | E13: UNKNOWN | F13: FAM | G13: NONE | H13: ='Sample Log'!$G$2 -> 43985 | I13: ='Sample Log'!D13 -> 0
A14: 12 | B14: A12 | C14: ='Sample Log'!C98 -> Sample_96 | D14: Hu RNAse P | E14: UNKNOWN | F14: FAM | G14: NONE | H14: ='Sample Log'!$G$2 -> 43985 | I14: ='Sample Log'!D14 -> 0
A15: 13 | B15: B1 | C15: ='Sample Log'!C9 -> Sample_7 | D15: Hu RNAse P | E15: UNKNOWN | F15: FAM | G15: NONE | H15: ='Sample Log'!$G$2 -> 43985 | I15: ='Sample Log'!D15 -> 0
A16: 14 | B16: B2 | C16: ='Sample Log'!C17 -> Sample_15 | D16: Hu RNAse P | E16: UNKNOWN | F16: FAM | G16: NONE | H16: ='Sample Log'!$G$2 -> 43985 | I16: ='Sample Log'!D16 -> 0
A17: 15 | B17: B3 | C17: ='Sample Log'!C25 -> Sample_23 | D17: Hu RNAse P | E17: UNKNOWN | F17: FAM | G17: NONE | H17: ='Sample Log'!$G$2 -> 43985 | I17: ='Sample Log'!D17 -> 0
A18: 16 | B18: B4 | C18: ='Sample Log'!C33 -> Sample_31 | D18: Hu RNAse P | E18: UNKNOWN | F18: FAM | G18: NONE | H18: ='Sample Log'!$G$2 -> 43985 | I18: ='Sample Log'!D18 -> 0
A19: 17 | B19: B5 | C19: ='Sample Log'!C41 -> Sample_39 | D19: Hu RNAse P | E19: UNKNOWN | F19: FAM | G19: NONE | H19: ='Sample Log'!$G$2 -> 43985 | I19: ='Sample Log'!D19 -> 0
A20: 18 | B20: B6 | C20: ='Sample Log'!C49 -> Sample_47 | D20: Hu RNAse P | E20: UNKNOWN | F20: FAM | G20: NONE | H20: ='Sample Log'!$G$2 -> 43985 | I20: ='Sample Log'!D20 -> 0
A21: 19 | B21: B7 | C21: ='Sample Log'!C57 -> Sample_55 | D21: Hu RNAse P | E21: UNKNOWN | F21: FAM | G21: NONE | H21: ='Sample Log'!$G$2 -> 43985 | I21: ='Sample Log'!D21 -> 0
A22: 20 | B22: B8 | C22: ='Sample Log'!C65 -> Sample_63 | D22: Hu RNAse P | E22: UNKNOWN | F22: FAM | G22: NONE | H22: ='Sample Log'!$G$2 -> 43985 | I22: ='Sample Log'!D22 -> 0
A23: 21 | B23: B9 | C23: ='Sample Log'!C73 -> Sample_71 | D23: Hu RNAse P | E23: UNKNOWN | F23: FAM | G23: NONE | H23: ='Sample Log'!$G$2 -> 43985 | I23: ='Sample Log'!D23 -> 0
A24: 22 | B24: B10 | C24: ='Sample Log'!C81 -> Sample_79 | D24: Hu RNAse P | E24: UNKNOWN | F24: FAM | G24: NONE | H24: ='Sample Log'!$G$2 -> 43985 | I24: ='Sample Log'!D24 -> 0
A25: 23 | B25: B11 | C25: ='Sample Log'!C89 -> Sample_87 | D25: Hu RNAse P | E25: UNKNOWN | F25: FAM | G25: NONE | H25: ='Sample Log'!$G$2 -> 43985 | I25: ='Sample Log'!D25 -> 0
A26: 24 | B26: B12 | C26: ='Sample Log'!C97 -> Sample_95 | D26: Hu RNAse P | E26: UNKNOWN | F26: FAM | G26: NONE | H26: ='Sample Log'!$G$2 -> 43985 | I26: ='Sample Log'!D26 -> 0
A27: 25 | B27: C1 | C27: ='Sample Log'!C8 -> Sample_6 | D27: Hu RNAse P | E27: UNKNOWN | F27: FAM | G27: NONE | H27: ='Sample Log'!$G$2 -> 43985 | I27: ='Sample Log'!D27 -> 0
A28: 26 | B28: C2 | C28: ='Sample Log'!C16 -> Sample_14 | D28: Hu RNAse P | E28: UNKNOWN | F28: FAM | G28: NONE | H28: ='Sample Log'!$G$2 -> 43985 | I28: ='Sample Log'!D28 -> 0
A29: 27 | B29: C3 | C29: ='Sample Log'!C24 -> Sample_22 | D29: Hu RNAse P | E29: UNKNOWN | F29: FAM | G29: NONE | H29: ='Sample Log'!$G$2 -> 43985 | I29: ='Sample Log'!D29 -> 0
A30: 28 | B30: C4 | C30: ='Sample Log'!C32 -> Sample_30 | D30: Hu RNAse P | E30: UNKNOWN | F30: FAM | G30: NONE | H30: ='Sample Log'!$G$2 -> 43985 | I30: ='Sample Log'!D30 -> 0
A31: 29 | B31: C5 | C31: ='Sample Log'!C40 -> Sample_38 | D31: Hu RNAse P | E31: UNKNOWN | F31: FAM | G31: NONE | H31: ='Sample Log'!$G$2 -> 43985 | I31: ='Sample Log'!D31 -> 0
A32: 30 | B32: C6 | C32: ='Sample Log'!C48 -> Sample_46 | D32: Hu RNAse P | E32: UNKNOWN | F32: FAM | G32: NONE | H32: ='Sample Log'!$G$2 -> 43985 | I32: ='Sample Log'!D32 -> 0
A33: 31 | B33: C7 | C33: ='Sample Log'!C56 -> Sample_54 | D33: Hu RNAse P | E33: UNKNOWN | F33: FAM | G33: NONE | H33: ='Sample Log'!$G$2 -> 43985 | I33: ='Sample Log'!D33 -> 0
A34: 32 | B34: C8 | C34: ='Sample Log'!C64 -> Sample_62 | D34: Hu RNAse P | E34: UNKNOWN | F34: FAM | G34: NONE | H34: ='Sample Log'!$G$2 -> 43985 | I34: ='Sample Log'!D34 -> 0
A35: 33 | B35: C9 | C35: ='Sample Log'!C72 -> Sample_70 | D35: Hu RNAse P | E35: UNKNOWN | F35: FAM | G35: NONE | H35: ='Sample Log'!$G$2 -> 43985 | I35: ='Sample Log'!D35 -> 0
A36: 34 | B36: C10 | C36: ='Sample Log'!C80 -> Sample_78 | D36: Hu RNAse P | E36: UNKNOWN | F36: FAM | G36: NONE | H36: ='Sample Log'!$G$2 -> 43985 | I36: ='Sample Log'!D36 -> 0
A37: 35 | B37: C11 | C37: ='Sample Log'!C88 -> Sample_86 | D37: Hu RNAse P | E37: UNKNOWN | F37: FAM | G37: NONE | H37: ='Sample Log'!$G$2 -> 43985 | I37: ='Sample Log'!D37 -> 0
A38: 36 | B38: C12 | C38: ='Sample Log'!C96 -> Sample_94 | D38: Hu RNAse P | E38: UNKNOWN | F38: FAM | G38: NONE | H38: ='Sample Log'!$G$2 -> 43985 | I38: ='Sample Log'!D38 -> 0
A39: 37 | B39: D1 | C39: ='Sample Log'!C7 -> Sample_5 | D39: Hu RNAse P | E39: UNKNOWN | F39: FAM | G39: NONE | H39: ='Sample Log'!$G$2 -> 43985 | I39: ='Sample Log'!D39 -> 0
A40: 38 | B40: D2 | C40: ='Sample Log'!C15 -> Sample_13 | D40: Hu RNAse P | E40: UNKNOWN | F40: FAM | G40: NONE | H40: ='Sample Log'!$G$2 -> 43985 | I40: ='Sample Log'!D40 -> 0
...

Sheet Table Upload 
A1: Plate nr | B1: Row | C1: Column | D1: Sample Name | E1: Extraction date | F1: Comments
A2: ='Sample Log'!$G$1 -> Plate 1 | B2: A | C2: 1 | D2: ='Sample Log'!C10 -> Sample_8 | E2: ='Sample Log'!$G$2 -> 43985 | F2: ='Sample Log'!D3 -> This is a comment
A3: ='Sample Log'!$G$1 -> Plate 1 | B3: A | C3: 2 | D3: ='Sample Log'!C18 -> Sample_16 | E3: ='Sample Log'!$G$2 -> 43985 | F3: ='Sample Log'!D4 -> 0
A4: ='Sample Log'!$G$1 -> Plate 1 | B4: A | C4: 3 | D4: ='Sample Log'!C26 -> Sample_24 | E4: ='Sample Log'!$G$2 -> 43985 | F4: ='Sample Log'!D5 -> 0
A5: ='Sample Log'!$G$1 -> Plate 1 | B5: A | C5: 4 | D5: ='Sample Log'!C34 -> Sample_32 | E5: ='Sample Log'!$G$2 -> 43985 | F5: ='Sample Log'!D6 -> 0
A6: ='Sample Log'!$G$1 -> Plate 1 | B6: A | C6: 5 | D6: ='Sample Log'!C42 -> Sample_40 | E6: ='Sample Log'!$G$2 -> 43985 | F6: ='Sample Log'!D7 -> 0
A7: ='Sample Log'!$G$1 -> Plate 1 | B7: A | C7: 6 | D7: ='Sample Log'!C50 -> Sample_48 | E7: ='Sample Log'!$G$2 -> 43985 | F7: ='Sample Log'!D8 -> 0
A8: ='Sample Log'!$G$1 -> Plate 1 | B8: A | C8: 7 | D8: ='Sample Log'!C58 -> Sample_56 | E8: ='Sample Log'!$G$2 -> 43985 | F8: ='Sample Log'!D9 -> 0
A9: ='Sample Log'!$G$1 -> Plate 1 | B9: A | C9: 8 | D9: ='Sample Log'!C66 -> Sample_64 | E9: ='Sample Log'!$G$2 -> 43985 | F9: ='Sample Log'!D10 -> 0
A10: ='Sample Log'!$G$1 -> Plate 1 | B10: A | C10: 9 | D10: ='Sample Log'!C74 -> Sample_72 | E10: ='Sample Log'!$G$2 -> 43985 | F10: ='Sample Log'!D11 -> 0
A11: ='Sample Log'!$G$1 -> Plate 1 | B11: A | C11: 10 | D11: ='Sample Log'!C82 -> Sample_80 | E11: ='Sample Log'!$G$2 -> 43985 | F11: ='Sample Log'!D12 -> 0
A12: ='Sample Log'!$G$1 -> Plate 1 | B12: A | C12: 11 | D12: ='Sample Log'!C90 -> Sample_88 | E12: ='Sample Log'!$G$2 -> 43985 | F12: ='Sample Log'!D13 -> 0
A13: ='Sample Log'!$G$1 -> Plate 1 | B13: A | C13: 12 | D13: ='Sample Log'!C98 -> Sample_96 | E13: ='Sample Log'!$G$2 -> 43985 | F13: ='Sample Log'!D14 -> 0
A14: ='Sample Log'!$G$1 -> Plate 1 | B14: B | C14: 1 | D14: ='Sample Log'!C9 -> Sample_7 | E14: ='Sample Log'!$G$2 -> 43985 | F14: ='Sample Log'!D15 -> 0
A15: ='Sample Log'!$G$1 -> Plate 1 | B15: B | C15: 2 | D15: ='Sample Log'!C17 -> Sample_15 | E15: ='Sample Log'!$G$2 -> 43985 | F15: ='Sample Log'!D16 -> 0
A16: ='Sample Log'!$G$1 -> Plate 1 | B16: B | C16: 3 | D16: ='Sample Log'!C25 -> Sample_23 | E16: ='Sample Log'!$G$2 -> 43985 | F16: ='Sample Log'!D17 -> 0
A17: ='Sample Log'!$G$1 -> Plate 1 | B17: B | C17: 4 | D17: ='Sample Log'!C33 -> Sample_31 | E17: ='Sample Log'!$G$2 -> 43985 | F17: ='Sample Log'!D18 -> 0
A18: ='Sample Log'!$G$1 -> Plate 1 | B18: B | C18: 5 | D18: ='Sample Log'!C41 -> Sample_39 | E18: ='Sample Log'!$G$2 -> 43985 | F18: ='Sample Log'!D19 -> 0
A19: ='Sample Log'!$G$1 -> Plate 1 | B19: B | C19: 6 | D19: ='Sample Log'!C49 -> Sample_47 | E19: ='Sample Log'!$G$2 -> 43985 | F19: ='Sample Log'!D20 -> 0
A20: ='Sample Log'!$G$1 -> Plate 1 | B20: B | C20: 7 | D20: ='Sample Log'!C57 -> Sample_55 | E20: ='Sample Log'!$G$2 -> 43985 | F20: ='Sample Log'!D21 -> 0
A21: ='Sample Log'!$G$1 -> Plate 1 | B21: B | C21: 8 | D21: ='Sample Log'!C65 -> Sample_63 | E21: ='Sample Log'!$G$2 -> 43985 | F21: ='Sample Log'!D22 -> 0
A22: ='Sample Log'!$G$1 -> Plate 1 | B22: B | C22: 9 | D22: ='Sample Log'!C73 -> Sample_71 | E22: ='Sample Log'!$G$2 -> 43985 | F22: ='Sample Log'!D23 -> 0
A23: ='Sample Log'!$G$1 -> Plate 1 | B23: B | C23: 10 | D23: ='Sample Log'!C81 -> Sample_79 | E23: ='Sample Log'!$G$2 -> 43985 | F23: ='Sample Log'!D24 -> 0
A24: ='Sample Log'!$G$1 -> Plate 1 | B24: B | C24: 11 | D24: ='Sample Log'!C89 -> Sample_87 | E24: ='Sample Log'!$G$2 -> 43985 | F24: ='Sample Log'!D25 -> 0
A25: ='Sample Log'!$G$1 -> Plate 1 | B25: B | C25: 12 | D25: ='Sample Log'!C97 -> Sample_95 | E25: ='Sample Log'!$G$2 -> 43985 | F25: ='Sample Log'!D26 -> 0
A26: ='Sample Log'!$G$1 -> Plate 1 | B26: C | C26: 1 | D26: ='Sample Log'!C8 -> Sample_6 | E26: ='Sample Log'!$G$2 -> 43985 | F26: ='Sample Log'!D27 -> 0
A27: ='Sample Log'!$G$1 -> Plate 1 | B27: C | C27: 2 | D27: ='Sample Log'!C16 -> Sample_14 | E27: ='Sample Log'!$G$2 -> 43985 | F27: ='Sample Log'!D28 -> 0
A28: ='Sample Log'!$G$1 -> Plate 1 | B28: C | C28: 3 | D28: ='Sample Log'!C24 -> Sample_22 | E28: ='Sample Log'!$G$2 -> 43985 | F28: ='Sample Log'!D29 -> 0
A29: ='Sample Log'!$G$1 -> Plate 1 | B29: C | C29: 4 | D29: ='Sample Log'!C32 -> Sample_30 | E29: ='Sample Log'!$G$2 -> 43985 | F29: ='Sample Log'!D30 -> 0
A30: ='Sample Log'!$G$1 -> Plate 1 | B30: C | C30: 5 | D30: ='Sample Log'!C40 -> Sample_38 | E30: ='Sample Log'!$G$2 -> 43985 | F30: ='Sample Log'!D31 -> 0
A31: ='Sample Log'!$G$1 -> Plate 1 | B31: C | C31: 6 | D31: ='Sample Log'!C48 -> Sample_46 | E31: ='Sample Log'!$G$2 -> 43985 | F31: ='Sample Log'!D32 -> 0
A32: ='Sample Log'!$G$1 -> Plate 1 | B32: C | C32: 7 | D32: ='Sample Log'!C56 -> Sample_54 | E32: ='Sample Log'!$G$2 -> 43985 | F32: ='Sample Log'!D33 -> 0
A33: ='Sample Log'!$G$1 -> Plate 1 | B33: C | C33: 8 | D33: ='Sample Log'!C64 -> Sample_62 | E33: ='Sample Log'!$G$2 -> 43985 | F33: ='Sample Log'!D34 -> 0
A34: ='Sample Log'!$G$1 -> Plate 1 | B34: C | C34: 9 | D34: ='Sample Log'!C72 -> Sample_70 | E34: ='Sample Log'!$G$2 -> 43985 | F34: ='Sample Log'!D35 -> 0
A35: ='Sample Log'!$G$1 -> Plate 1 | B35: C | C35: 10 | D35: ='Sample Log'!C80 -> Sample_78 | E35: ='Sample Log'!$G$2 -> 43985 | F35: ='Sample Log'!D36 -> 0
A36: ='Sample Log'!$G$1 -> Plate 1 | B36: C | C36: 11 | D36: ='Sample Log'!C88 -> Sample_86 | E36: ='Sample Log'!$G$2 -> 43985 | F36: ='Sample Log'!D37 -> 0
A37: ='Sample Log'!$G$1 -> Plate 1 | B37: C | C37: 12 | D37: ='Sample Log'!C96 -> Sample_94 | E37: ='Sample Log'!$G$2 -> 43985 | F37: ='Sample Log'!D38 -> 0
A38: ='Sample Log'!$G$1 -> Plate 1 | B38: D | C38: 1 | D38: ='Sample Log'!C7 -> Sample_5 | E38: ='Sample Log'!$G$2 -> 43985 | F38: ='Sample Log'!D39 -> 0
A39: ='Sample Log'!$G$1 -> Plate 1 | B39: D | C39: 2 | D39: ='Sample Log'!C15 -> Sample_13 | E39: ='Sample Log'!$G$2 -> 43985 | F39: ='Sample Log'!D40 -> 0
A40: ='Sample Log'!$G$1 -> Plate 1 | B40: D | C40: 3 | D40: ='Sample Log'!C23 -> Sample_21 | E40: ='Sample Log'!$G$2 -> 43985 | F40: ='Sample Log'!D41 -> 0
...
