Workbook

Sheet Sequence
F3: I.S.
A4: 1 | B4: A1 | C4: Double Blank | E4: Double Blank | I4: 1
A5: 2 | B5: B1 | C5: 0 STD | D5: 0 | E5: Blank | F5: 1 | I5: =I4+12 -> 13
A6: 3 | B6: C1 | C6: 0.0025 STD | D6: 0.0025 | E6: Standard | F6: 1 | I6: =I5+12 -> 25
A7: 4 | B7: D1 | C7: 0.0050 STD | D7: 0.005 | E7: Standard | F7: 1 | I7: =I6+12 -> 37
A8: 5 | B8: E1 | C8: 0.010 STD | D8: 0.01 | E8: Standard | F8: 1 | I8: =I7+12 -> 49
A9: 6 | B9: F1 | C9: 0.025 STD | D9: 0.025 | E9: Standard | F9: 1 | I9: =I8+12 -> 61
A10: 7 | B10: G1 | C10: 0.050 STD | D10: 0.05 | E10: Standard | F10: 1 | I10: =I9+12 -> 73
A11: 8 | B11: H1 | C11: 0.100 STD | D11: 0.1 | E11: Standard | F11: 1 | I11: =I10+12 -> 85
A12: 9 | B12: A2 | C12: 0.250 STD | D12: 0.25 | E12: Standard | F12: 1 | I12: 2
A13: 10 | B13: B2 | C13: 0.500 STD | D13: 0.5 | E13: Standard | F13: 1 | I13: =I12+12 -> 14
A14: 11 | B14: C2 | C14: 1.0 STD | D14: 1 | E14: Standard | F14: 1 | I14: =I13+12 -> 26
A15: 12 | B15: D2 | C15: 2.5 STD | D15: 2.5 | E15: Standard | F15: 1 | I15: =I14+12 -> 38
A16: 13 | B16: E2 | C16: 5.0 STD | D16: 5 | E16: Standard | F16: 1 | I16: =I15+12 -> 50
A17: 14 | B17: F2 | C17: 10.0 STD | D17: 10 | E17: Standard | F17: 1 | I17: =I16+12 -> 62
A18: 15 | B18: G2 | C18: 25.0 STD | D18: 25 | E18: Standard | F18: 1 | I18: =I17+12 -> 74
A19: 16 | B19: H2 | C19: 50.0 STD | D19: 50 | E19: Standard | F19: 1 | I19: =I18+12 -> 86
A20: 17 | B20: A3 | C20: 100.0 STD | D20: 100 | E20: Standard | F20: 1 | I20: 3
A21: 18 | B21: B3 | C21: 200.0 STD | D21: 200 | E21: Standard | F21: 1 | I21: =I20+12 -> 15
A22: 19 | B22: C3 | C22: 400.0 STD | D22: 400 | E22: Standard | F22: 1 | I22: =I21+12 -> 27
A23: 20 | B23: D3 | C23: Double Blank | E23: Double Blank | I23: =I22+12 -> 39
A24: 21 | B24: E3 | C24: QC | E24: Unknown | F24: 1 | I24: =I23+12 -> 51
A25: 22 | B25: F3 | C25: Plasma 1 | E25: Unknown | F25: 1 | I25: =I24+12 -> 63
A26: 23 | B26: G3 | C26: Plasma 2 | E26: Unknown | F26: 1 | I26: =I25+12 -> 75
A27: 24 | B27: H3 | C27: Plasma 3 | E27: Unknown | F27: 1 | I27: =I26+12 -> 87
A28: 25 | B28: A4 | C28: Plasma 4 | E28: Unknown | F28: 1 | I28: 4
A29: 26 | B29: B4 | C29: Plasma 5 | E29: Unknown | F29: 1 | I29: =I28+12 -> 16
A30: 27 | B30: C4 | C30: Plasma 6 | E30: Unknown | F30: 1 | I30: =I29+12 -> 28
A31: 28 | B31: D4 | C31: Plasma 7 | E31: Unknown | F31: 1 | I31: =I30+12 -> 40
A32: 29 | B32: E4 | C32: Plasma 8 | E32: Unknown | F32: 1 | I32: =I31+12 -> 52
A33: 30 | B33: F4 | C33: Plasma 9 | E33: Unknown | F33: 1 | I33: =I32+12 -> 64
A34: 31 | B34: G4 | C34: Plasma 10 | E34: Unknown | F34: 1 | I34: =I33+12 -> 76
A35: 32 | B35: H4 | C35: Plasma 11 | E35: Unknown | F35: 1 | I35: =I34+12 -> 88
A36: 33 | B36: A5 | C36: Plasma 12 | E36: Unknown | F36: 1 | I36: 5
A37: 34 | B37: B5 | C37: Plasma 13 | E37: Unknown | F37: 1 | I37: =I36+12 -> 17
A38: 35 | B38: C5 | C38: Plasma 14 | E38: Unknown | F38: 1 | I38: =I37+12 -> 29
A39: 36 | B39: D5 | C39: Plasma 15 | E39: Unknown | F39: 1 | I39: =I38+12 -> 41
A40: 37 | B40: E5 | C40: Plasma 16 | E40: Unknown | F40: 1 | I40: =I39+12 -> 53
A41: 38 | B41: F5 | C41: Plasma 17 | E41: Unknown | F41: 1 | I41: =I40+12 -> 65
A42: 39 | B42: G5 | C42: Plasma 18 | E42: Unknown | F42: 1 | I42: =I41+12 -> 77
...

Sheet Platemap
B1: 1 | C1: 2 | D1: 3 | E1: 4 | F1: 5 | G1: 6 | H1: 7 | I1: 8 | J1: 9 | K1: 10 | L1: 11 | M1: 12
A2: A | B2: A1 | C2: A2 | D2: A3 | E2: A4 | F2: A5 | G2: A6 | H2: A7 | I2: A8 | J2: A9 | K2: A10 | L2: A11 | M2: A12
B3: =Sequence!C4 -> Double Blank | C3: =Sequence!C12 -> 0.250 STD | D3: =Sequence!C20 -> 100.0 STD | E3: =Sequence!C28 -> Plasma 4 | F3: =Sequence!C36 -> Plasma 12 | G3: =Sequence!C44 -> Plasma 20 | H3: =Sequence!C52 -> Plasma 28 | I3: =Sequence!C60 -> Plasma 36 | J3: =Sequence!C68 -> Plasma 44 | K3: =Sequence!C76 -> Plasma 52 | L3: =Sequence!C84 -> Plasma 60 | M3: =Sequence!C92 -> Plasma 68
A4: B | B4: B1 | C4: B2 | D4: B3 | E4: B4 | F4: B5 | G4: B6 | H4: B7 | I4: B8 | J4: B9 | K4: B10 | L4: B11 | M4: B12
B5: =Sequence!C5 -> 0 STD | C5: =Sequence!C13 -> 0.500 STD | D5: =Sequence!C21 -> 200.0 STD | E5: =Sequence!C29 -> Plasma 5 | F5: =Sequence!C37 -> Plasma 13 | G5: =Sequence!C45 -> Plasma 21 | H5: =Sequence!C53 -> Plasma 29 | I5: =Sequence!C61 -> Plasma 37 | J5: =Sequence!C69 -> Plasma 45 | K5: =Sequence!C77 -> Plasma 53 | L5: =Sequence!C85 -> Plasma 61 | M5: =Sequence!C93 -> Plasma 69
A6: C | B6: C1 | C6: C2 | D6: C3 | E6: C4 | F6: C5 | G6: C6 | H6: C7 | I6: C8 | J6: C9 | K6: C10 | L6: C11 | M6: C12
B7: =Sequence!C6 -> 0.0025 STD | C7: =Sequence!C14 -> 1.0 STD | D7: =Sequence!C22 -> 400.0 STD | E7: =Sequence!C30 -> Plasma 6 | F7: =Sequence!C38 -> Plasma 14 | G7: =Sequence!C46 -> Plasma 22 | H7: =Sequence!C54 -> Plasma 30 | I7: =Sequence!C62 -> Plasma 38 | J7: =Sequence!C70 -> Plasma 46 | K7: =Sequence!C78 -> Plasma 54 | L7: =Sequence!C86 -> Plasma 62 | M7: =Sequence!C94 -> Plasma 70
A8: D | B8: D1 | C8: D2 | D8: D3 | E8: D4 | F8: D5 | G8: D6 | H8: D7 | I8: D8 | J8: D9 | K8: D10 | L8: D11 | M8: D12
B9: =Sequence!C7 -> 0.0050 STD | C9: =Sequence!C15 -> 2.5 STD | D9: =Sequence!C23 -> Double Blank | E9: =Sequence!C31 -> Plasma 7 | F9: =Sequence!C39 -> Plasma 15 | G9: =Sequence!C47 -> Plasma 23 | H9: =Sequence!C55 -> Plasma 31 | I9: =Sequence!C63 -> Plasma 39 | J9: =Sequence!C71 -> Plasma 47 | K9: =Sequence!C79 -> Plasma 55 | L9: =Sequence!C87 -> Plasma 63 | M9: =Sequence!C95 -> Plasma 71
A10: E | B10: E1 | C10: E2 | D10: E3 | E10: E4 | F10: E5 | G10: E6 | H10: E7 | I10: E8 | J10: E9 | K10: E10 | L10: E11 | M10: E12
B11: =Sequence!C8 -> 0.010 STD | C11: =Sequence!C16 -> 5.0 STD | D11: =Sequence!C24 -> QC | E11: =Sequence!C32 -> Plasma 8 | F11: =Sequence!C40 -> Plasma 16 | G11: =Sequence!C48 -> Plasma 24 | H11: =Sequence!C56 -> Plasma 32 | I11: =Sequence!C64 -> Plasma 40 | J11: =Sequence!C72 -> Plasma 48 | K11: =Sequence!C80 -> Plasma 56 | L11: =Sequence!C88 -> Plasma 64 | M11: =Sequence!C96 -> Plasma 72
A12: F | B12: F1 | C12: F2 | D12: F3 | E12: F4 | F12: F5 | G12: F6 | H12: F7 | I12: F8 | J12: F9 | K12: F10 | L12: F11 | M12: F12
B13: =Sequence!C9 -> 0.025 STD | C13: =Sequence!C17 -> 10.0 STD | D13: =Sequence!C25 -> Plasma 1 | E13: =Sequence!C33 -> Plasma 9 | F13: =Sequence!C41 -> Plasma 17 | G13: =Sequence!C49 -> Plasma 25 | H13: =Sequence!C57 -> Plasma 33 | I13: =Sequence!C65 -> Plasma 41 | J13: =Sequence!C73 -> Plasma 49 | K13: =Sequence!C81 -> Plasma 57 | L13: =Sequence!C89 -> Plasma 65 | M13: =Sequence!C97 -> Plasma 73
A14: G | B14: G1 | C14: G2 | D14: G3 | E14: G4 | F14: G5 | G14: G6 | H14: G7 | I14: G8 | J14: G9 | K14: G10 | L14: G11 | M14: G12
B15: =Sequence!C10 -> 0.050 STD | C15: =Sequence!C18 -> 25.0 STD | D15: =Sequence!C26 -> Plasma 2 | E15: =Sequence!C34 -> Plasma 10 | F15: =Sequence!C42 -> Plasma 18 | G15: =Sequence!C50 -> Plasma 26 | H15: =Sequence!C58 -> Plasma 34 | I15: =Sequence!C66 -> Plasma 42 | J15: =Sequence!C74 -> Plasma 50 | K15: =Sequence!C82 -> Plasma 58 | L15: =Sequence!C90 -> Plasma 66 | M15: =Sequence!C98 -> QC
A16: H | B16: H1 | C16: H2 | D16: H3 | E16: H4 | F16: H5 | G16: H6 | H16: H7 | I16: H8 | J16: H9 | K16: H10 | L16: H11 | M16: H12
B17: =Sequence!C11 -> 0.100 STD | C17: =Sequence!C19 -> 50.0 STD | D17: =Sequence!C27 -> Plasma 3 | E17: =Sequence!C35 -> Plasma 11 | F17: =Sequence!C43 -> Plasma 19 | G17: =Sequence!C51 -> Plasma 27 | H17: =Sequence!C59 -> Plasma 35 | I17: =Sequence!C67 -> Plasma 43 | J17: =Sequence!C75 -> Plasma 51 | K17: =Sequence!C83 -> Plasma 59 | L17: =Sequence!C91 -> Plasma 67 | M17: =Sequence!C99 -> Solvent blank
