Workbook

Sheet DNA extractions
A1: Elephant Epigenetic Project
A6: Extraction date | B6: Sample ID | C6: Code | D6: Species name | E6: Tissue source | F6: Amount tissue used | G6: Extraction method | H6: Nanodrop QC (260/280) | I6: Nanodrop QC (260/230) | J6: Nanodrop Conc. (ng/µl) | K6: Qubit QC (1st) | L6: Qubit QC (2nd) | M6: Tape station QC (Size range) | N6: Agarose gel | O6: Ladder | P6: Agarose QC (approx. size range) | Q6: Total volume available (µl) | R6: Total amount DNA (ng) (NanoDrop) | S6: Total amount DNA (ng) (1st Qubit) | T6: Total amount DNA (ng) (2nd Qubit) | U6: Samples evaporated and resuspended in 10µl ddH2O in preparation for NanoPore workshop
A7: 45215 | B7: Bull3_Blood_1st | D7: Loxodonta africana | E7: Blood | F7: 500 µl | G7: Phenol/Chloroform | H7: 1.35 | I7: 0.42 | J7: 340.8 | K7: - | M7: - | N7: 1.5 | O7: Lambda DNA/ HindiIII | P7: ≥ 23 130 bp | Q7: =30-2-4 -> 24 | R7: =J7*Q7 -> 8179.2
A8: 45244 | B8: Bull3_Blood_2nd_Vortex | D8: Loxodonta africana | E8: Blood | F8: 150 µl | G8: Phenol/Chloroform | H8: 1.75 | I8: 2.24 | J8: 250.6 | K8: - | M8: - | O8: Lambda DNA/ HindiIII | P8: ≥ 23 130 bp | Q8: =30-2-4 -> 24 | R8: =J8*Q8 -> 6014.4
A9: 45244 | B9: Bull3_Blood_2nd_Invert | D9: Loxodonta africana | E9: Blood | F9: 150 µl | G9: Phenol/Chloroform | H9: 1.93 | I9: 1.1 | J9: 14.9 | K9: - | M9: - | O9: Lambda DNA/ HindiIII | P9: ≥ 23 130 bp | Q9: =30-2-4 -> 24 | R9: =J9*Q9 -> 357.6
A10: 45245 | B10: Bull3_Blood_3rd_Vortex1 | D10: Loxodonta africana | E10: Blood | F10: 100 µl | G10: Phenol/Chloroform | H10: 1.84 | I10: 2.09 | J10: 42.1 | K10: - | M10: - | N10: 0.7% gel @ 30V for 2.5h | O10: Lambda DNA/ HindiIII | P10: ≥ 23 130 bp | Q10: =30-2-4 -> 24 | R10: =J10*Q10 -> 1010.4
A11: 45245 | B11: Bull3_Blood_3rd_Vortex2 | D11: Loxodonta africana | E11: Blood | F11: 60 µl & 40 µl H2O | G11: Phenol/Chloroform | H11: 1.11 | I11: 0.9 | J11: 2.1 | K11: - | M11: - | O11: Lambda DNA/ HindiIII | P11: Not visible on gel | Q11: =30-2-4 -> 24 | R11: =J11*Q11 -> 50.4
A12: 45246 | B12: Bull3_Blood_4th_Vortex1 | D12: Loxodonta africana | E12: Blood | F12: 100 µl | G12: Phenol/Chloroform | H12: 1.85 | I12: 2.16 | J12: 241.7 | K12: - | M12: - | O12: Lambda DNA/ HindiIII | P12: ≥ 23 130 bp | Q12: =30-2-4 -> 24 | R12: =J12*Q12 -> 5800.8
A13: 45246 | B13: Bull3_Blood_4th_Vortex2 | D13: Loxodonta africana | E13: Blood | F13: 100 µl | G13: Phenol/Chloroform | H13: 1.84 | I13: 1.92 | J13: 32.2 | K13: - | M13: - | O13: Lambda DNA/ HindiIII | P13: ≥ 23 130 bp | Q13: =30-2-4 -> 24 | R13: =J13*Q13 -> 772.8
A14: 45250 | B14: Bull1_Blood_1st_Vortex1 | D14: Loxodonta africana | E14: Blood | F14: 100 µl | G14: Phenol/Chloroform | H14: 1.84 | I14: 2.35 | J14: 195.3 | K14: 111.2 | M14: - | N14: 0.7% gel @ 30V for 6h | O14: Lambda DNA/ HindiIII | P14: ≥ 23 130 bp | Q14: =30-2-4-0.5-23.5+10 -> 10 | R14: =23.5*J14 -> 4589.55 | S14: =23.5*K14 -> 2613.2
A15: 45250 | B15: Bull1_Blood_1st_Vortex2 | D15: Loxodonta africana | E15: Blood | F15: 100 µl | G15: Phenol/Chloroform | H15: 1.81 | I15: 2.39 | J15: 154.4 | K15: 104.4 | M15: 100 - 29 362bp | O15: Lambda DNA/ HindiIII | P15: ≥ 23 130 bp | Q15: =30-2-4-0.5-2.4-21.1+10-10 -> 0 | R15: =21.1*J15 -> 3257.84 | S15: =21.1*K15 -> 2202.84 | U15: Sample sent to sequencing facility
A16: 45252 | B16: Bull1_Skin_1st_S1 | D16: Loxodonta africana | E16: Skin | F16: N/A (small corner) | G16: Phenol/Chloroform | H16: 1.73 | I16: 1.35 | J16: 64.9 | K16: - | M16: - | N16: 0.7% gel @ 30V for 6h | O16: Lambda DNA/ HindiIII | P16: Not visible on gel | Q16: =30-2-4 -> 24 | R16: =J16*Q16 -> 1557.6 | S16: -
A17: 45252 | B17: Bull1_Skin_1st_S2 | D17: Loxodonta africana | E17: Skin | F17: N/A (inside ear) | G17: Phenol/Chloroform | H17: 1.92 | I17: 1.81 | J17: 63.8 | K17: - | M17: - | O17: Lambda DNA/ HindiIII | P17: ≥ 23 130 bp | Q17: =30-2-4 -> 24 | R17: =J17*Q17 -> 1531.2 | S17: -
A18: 45258 | B18: Bull1_Skin_2nd_S1 | D18: Loxodonta africana | E18: Skin | F18: N/A (inside ear) | G18: Phenol/Chloroform | H18: 1.88 | I18: 1.91 | J18: 224.1 | K18: 168.8 | M18: 100 - 26 739bp | N18: 0.7 | O18: Lambda DNA/ HindiIII | P18: ≥ 23 130 bp | Q18: =30-2-4-0.5-1.5-22+10-10 -> 0 | R18: =22*J18 -> 4930.2 | S18: =22*K18 -> 3713.6 | U18: Sample sent to sequencing facility
A19: 45258 | B19: Bull1_Skin_2nd_S2 | D19: Loxodonta africana | E19: Skin | F19: N/A (outside & piece inside ear) | G19: Phenol/Chloroform | H19: 1.53 | I19: 1.07 | J19: 439 | K19: - | M19: - | O19: Lambda DNA/ HindiIII | P19: 4 361 - 23 130 bp | Q19: =30-2-4 -> 24 | R19: =J19*Q19 -> 10536 | S19: -
A20: 45264 | B20: Bull1_Skin_3rd_S | C20: B1S | D20: Loxodonta africana | E20: Skin | F20: N/A (inside ear; larger; chopped) | G20: Phenol/Chloroform | H20: 1.81 | I20: 2.07 | J20: 733.7 | K20: 69 | L20: 848 | M20: ??? | N20: 0.7 | O20: Lambda DNA/ HindiIII | P20: ≥ 23 130 bp | Q20: =30-2-4-1-1-1-21+50-10-2-38 -> 0 | R20: =J20*Q20 -> 0 | S20: =Q20*K20 -> 0 | T20: =Q20*L20 -> 0 | U20: Sample delivered to Renate on 2024-05-28 → Sample was dry, therfore resuspended in 50 µl H20
A21: 45264 | B21: Bull2_Skin_1st_S | C21: B2S | D21: Loxodonta africana | E21: Skin | F21: N/A (inside ear; larger; chopped) | G21: Phenol/Chloroform | H21: 1.84 | I21: 2.09 | J21: 842.5 | K21: 160 | L21: 284 | M21: 100 - >60 000bp | O21: Lambda DNA/ HindiIII | P21: ≥ 23 130 bp | Q21: =30-2-4-1-1-22 -> 0 | R21: =J21*Q21 -> 0 | S21: =Q21*K21 -> 0 | T21: =Q21*L21 -> 0 | U21: Sample delivered to Renate on 2024-05-28
A22: 45271 | B22: Bull1_Blood_2nd_B1 | D22: Loxodonta africana | E22: Blood | F22: 100 µl | G22: Phenol/Chloroform | H22: 1.82 | I22: 2.34 | J22: 331.6 | K22: 108 | M22: - | O22: Lambda DNA/ HindiIII | P22: ≥ 23 130 bp | Q22: =30-2-4-1-2 -> 21 | R22: =J22*Q22 -> 6963.6 | S22: =Q22*K22 -> 2268
A23: 45271 | B23: Bull2_Blood_2nd_B1 | D23: Loxodonta africana | E23: Blood | F23: 100 µl | G23: Phenol/Chloroform | H23: 1.81 | I23: 2.23 | J23: 49.5 | K23: 18.4 | M23: - | O23: Lambda DNA/ HindiIII | P23: ≥ 23 130 bp | Q23: =30-2-4-1 -> 23 | R23: =J23*Q23 -> 1138.5 | S23: =Q23*K23 -> 423.2
A24: 45271 | B24: Bull1_Blood_2nd_B2 | D24: Loxodonta africana | E24: Blood | F24: 100 µl | G24: Phenol/Chloroform | H24: 1.81 | I24: 2.29 | J24: 639.1 | K24: 224 | M24: - | O24: Lambda DNA/ HindiIII | P24: ≥ 23 130 bp | Q24: =30-2-4-1 -> 23 | R24: =J24*Q24 -> 14699.3 | S24: =Q24*K24 -> 5152
A25: 45271 | B25: Bull2_Blood_2nd_B2 | D25: Loxodonta africana | E25: Blood | F25: 100 µl | G25: Phenol/Chloroform | H25: 1.8 | I25: 2.32 | J25: 95.8 | K25: 86 | L25: 76.4 | M25: - | O25: Lambda DNA/ HindiIII | P25: ≥ 23 130 bp | Q25: =30-2-4-1-1 -> 22 | R25: =J25*Q25 -> 2107.6 | S25: =Q25*K25 -> 1892 | T25: =Q25*L25 -> 1680.8
A26: 45314 | B26: Bull3_Dung_1st_D1 | D26: Loxodonta africana | E26: Dung | F26: 0,04 g | G26: Phenol/Chloroform | H26: 1.17 | I26: 0.45 | J26: 479.2 | K26: - | M26: - | N26: 1.5% gel @ 50V for 26min | O26: 100 bp | Q26: =30-2-4-4-20 -> 0 | R26: =20*J26*0 -> 0 | S26: - | U26: Samples were combined (40µl) and used in the bead purification reaction.
A27: 45314 | B27: Bull3_Dung_1st_D2 | D27: Loxodonta africana | E27: Dung | F27: 0,04 g | G27: Phenol/Chloroform | H27: 1.15 | I27: 0.42 | J27: 595.5 | K27: - | M27: - | O27: 100 bp | Q27: =30-2-4-4-20 -> 0 | R27: =20*J27*0 -> 0 | S27: -
A28: 45328 | B28: Bull3_Dung_2nd_A | D28: Loxodonta africana | E28: Dung | F28: 0,25 g | G28: Phenol/Chloroform | H28: 1.3 | I28: 0.63 | J28: 432.1 | K28: - | M28: - | N28: 1.5 | O28: 100 bp | Q28: =30-6-4 -> 20 | R28: =J28*Q28 -> 8642 | S28: -
A29: 45328 | B29: Bull3_Dung_2nd_I250 | D29: Loxodonta africana | E29: Dung | F29: 0,25 g | G29: Phenol/Chloroform | H29: - | I29: - | J29: - | K29: - | M29: - | N29: - | O29: - | P29: - | Q29: - | R29: - | S29: - | U29: Sample discarded during P/C extraction due to low volume
A30: 45328 | B30: Bull3_Dung_2nd_I500 | D30: Loxodonta africana | E30: Dung | F30: 0,25 g | G30: Phenol/Chloroform | H30: 1.37 | I30: 0.33 | J30: 175.2 | K30: - | M30: - | N30: 1.5 | O30: 100bp | Q30: =30-6-4 -> 20 | R30: =J30*Q30 -> 3504 | S30: -
A31: 45328 | B31: Bull3_Dung_2nd_I1000 | D31: Loxodonta africana | E31: Dung | F31: 0,25 g | G31: Phenol/Chloroform | H31: 1.59 | I31: 0.82 | J31: 94.8 | K31: - | M31: 6267bp | N31: 1.5 | O31: 100bp | Q31: =30-6-4-2 -> 18 | R31: =J31*Q31 -> 1706.4 | S31: -
A32: 45328 | B32: Bull3_Dung_2nd_I/A250 | D32: Loxodonta africana | E32: Dung | F32: 0,25 g | G32: Phenol/Chloroform | H32: 1.34 | I32: 0.62 | J32: 160.8 | K32: - | M32: - | N32: 1.5 | O32: 100bp | Q32: =30-6-4 -> 20 | R32: =J32*Q32 -> 3216 | S32: -
A33: 45328 | B33: Bull3_Dung_2nd_I/A500 | D33: Loxodonta africana | E33: Dung | F33: 0,25 g | G33: Phenol/Chloroform | H33: 1.35 | I33: 0.41 | J33: 103.6 | K33: - | M33: - | N33: 1.5 | O33: 100bp | Q33: =30-6-4 -> 20 | R33: =J33*Q33 -> 2072 | S33: -
A34: 45330 | B34: Bull3_Dung_3rd_D1_I1000 | D34: Loxodonta africana | E34: Dung | F34: 0,25 g | G34: Phenol/Chloroform | H34: 1.5 | I34: 0.61 | J34: 1254.6 | K34: - | M34: - | N34: 1.5 | O34: 100bp | Q34: =30-6 -> 24 | R34: =J34*Q34 -> 30110.4 | S34: -
A35: 45330 | B35: Bull3_Dung_3rd_D2_I1000 | D35: Loxodonta africana | E35: Dung | F35: 0,25 g | G35: Phenol/Chloroform | H35: 1.52 | I35: 0.59 | J35: 1305.5 | K35: - | M35: - | N35: 1.5 | O35: 100bp | Q35: =30-6 -> 24 | R35: =J35*Q35 -> 31332 | S35: -
A36: 45334 | B36: Bull3_Dung_4th_D1_A/Isam | D36: Loxodonta africana | E36: Dung | F36: 0,04 g | G36: Phenol/Chloroform | H36: 1.29 | I36: 0.5 | J36: 395.6 | K36: - | M36: - | N36: 1.5 | O36: 100bp | Q36: =30-6 -> 24 | R36: =J36*Q36 -> 9494.4 | S36: -
A37: 45334 | B37: Bull3_Dung_4th_D2_A/Isup | D37: Loxodonta africana | E37: Dung | F37: 0,04 g | G37: Phenol/Chloroform | H37: 1.25 | I37: 0.46 | J37: 338.9 | K37: - | M37: - | N37: 1.5 | O37: 100bp | Q37: =30-6 -> 24 | R37: =J37*Q37 -> 8133.6 | S37: -
A38: 45334 | B38: Bull3_Dung_4th_D3_A/CD2sup | D38: Loxodonta africana | E38: Dung | F38: 0,04 g | G38: Phenol/Chloroform | H38: 3.29 | I38: 0.4 | J38: 1.9 | K38: - | M38: - | N38: 1.5 | O38: 100bp | Q38: =30-6 -> 24 | R38: =J38*Q38 -> 45.6 | S38: -
A39: 45334 | B39: Bull3_Dung_4th_D4_A/I/CD2sup | D39: Loxodonta africana | E39: Dung | F39: 0,04 g | G39: Phenol/Chloroform | H39: 1.33 | I39: 0.68 | J39: 120.1 | K39: - | M39: - | N39: 1.5 | O39: 100bp | Q39: =30-6 -> 24 | R39: =J39*Q39 -> 2882.4 | S39: -
A40: 45336 | B40: Bull3_Dung_1st_D1 & D2_Bead purification | D40: Loxodonta africana | E40: Dung | F40: "Bull3_Dung_1st_D1 & Bull3_Dung_1st_D2" (2024-01-23) (40 µl) | G40: Bead purification | H40: -1.01 | I40: -7.48 | J40: 18.6 | K40: - | M40: - | N40: 1.5% gel @ 100V for 12min | O40: 100bp | Q40: =25-2-4 -> 19 | R40: =J40*Q40 -> 353.4 | S40: -
A41: 45338 | B41: Bull1_Dung_1st_D1 | D41: Loxodonta africana | E41: Dung | F41: 0.04 g | G41: Phenol/Chloroform | H41: 1.15 | I41: 0.39 | J41: 518.7 | K41: - | M41: - | N41: 1 | O41: 100bp | Q41: =20-2-18 -> 0 | R41: =18*J41*0 -> 0 | S41: - | U41: Samples were comined (D1 & D2; D3 & D4; D5 & D6) and used in gel purification (2024/02/20)
A42: 45338 | B42: Bull1_Dung_1st_D2 | D42: Loxodonta africana | E42: Dung | F42: 0.04 g | G42: Phenol/Chloroform | H42: 1.14 | I42: 0.4 | J42: 421.8 | K42: - | M42: - | O42: 100bp | Q42: =20-2-18 -> 0 | R42: =18*J42*0 -> 0 | S42: -
A43: 45338 | B43: Bull1_Dung_1st_D3 | D43: Loxodonta africana | E43: Dung | F43: 0.04 g | G43: Phenol/Chloroform | H43: 1.14 | I43: 0.4 | J43: 486.2 | K43: - | M43: - | O43: 100bp | Q43: =20-2-18 -> 0 | R43: =18*J43*0 -> 0 | S43: -
A44: 45338 | B44: Bull1_Dung_1st_D4 | D44: Loxodonta africana | E44: Dung | F44: 0.04 g | G44: Phenol/Chloroform | H44: 1.17 | I44: 0.4 | J44: 627.2 | K44: - | M44: - | O44: 100bp | Q44: =20-2-18 -> 0 | R44: =18*J44*0 -> 0 | S44: -
...

Sheet PCR
A2: Date | B2: Sample Name | C2: Organism | D2: F primer name | E2: R primer name | F2: Exp. amplicon (bp) | G2: Sample used | H2: MgCl2 (25mM) (µl) | I2: Buffer (10x) (µl) | J2: dNTPs (2.5mM) (µl) | K2: Taq (µl) | L2: F primer (10pmol) (µl) | M2: R primer (10pmol) (µl) | N2: H2O (µl) | O2: DNA (µl) | P2: Total volume (µl) | Q2: Initial denaturation | R2: Denaturation | S2: Annealing | T2: Elongation | U2: Final Elongation | V2: Amplification (Y/N) | W2: Agarose gel results
A3: 45482 | B3: P1 | C3: Plants | D3: c (A49325) | E3: h (B49466) | F3: 141 (?) | G3: ='DNA extractions'!B91 -> Bull3_Dung_Filtered2_1st_TS | H3: 2.5 | I3: 2.5 | J3: 2.5 | K3: 0.15 | L3: 0.15 | M3: 0.15 | N3: 15.05 | O3: 2 | P3: =25-4-4 -> 17 | Q3: 94°C for 1min | R3: 94°C for 30s | S3: 47°C for 30s | T3: 72°C for 30s | U3: 72°C for 7min | V3: N | W3: 1.5% gel @ 100V for 15min
B4: P2 | G4: ='DNA extractions'!B92 -> Bull3_Dung_Filtered2_1st_FF | P4: =25-4-4 -> 17 | V4: N
B5: P3 | G5: ='DNA extractions'!B98 -> Bull3_Dung_Filtered2_1st_100µm.kp | P5: =25-4-4 -> 17 | V5: Y
B6: P4 | G6: ='DNA extractions'!B94 -> Bull3_Dung_Filtered2_1st_8.0µm | P6: =25-4-4 -> 17 | V6: N
B7: P5 | G7: ='DNA extractions'!B99 -> Bull3_Dung_Filtered2_1st_1.2µm.kp | P7: =25-4-4 -> 17 | V7: Y
B8: P6 | G8: ='DNA extractions'!B96 -> Bull3_Dung_Filtered2_1st_0.22µm | P8: =25-4-4 -> 17 | V8: N
B9: P7 | G9: ='DNA extractions'!B97 -> Bull3_Dung_Filtered2_1st_filtrate | P9: =25-4-4 -> 17 | V9: N
B10: P(-) | G10: - | N10: 17.05 | O10: - | P10: =25-4-4 -> 17 | V10: N
B11: N1 | C11: Namatodes | D11: JB3 | E11: JB4.5 | F11: 366 | G11: Bull3_Dung_Filtered2_1st_TS | H11: 2.5 | I11: 2.5 | J11: 2.5 | K11: 0.15 | L11: 0.15 | M11: 0.15 | N11: 15.05 | O11: 2 | P11: =25-4-4 -> 17 | Q11: 94°C for 1min | R11: 94°C for 30s | S11: 47°C for 30s | T11: 72°C for 30s | U11: 72°C for 7min | V11: N
B12: N2 | G12: Bull3_Dung_Filtered2_1st_FF | P12: =25-4-4 -> 17 | V12: N
B13: N3 | G13: Bull3_Dung_Filtered2_1st_100µm.kp | P13: =25-4-4 -> 17 | V13: N
B14: N4 | G14: Bull3_Dung_Filtered2_1st_8.0µm | P14: =25-4-4 -> 17 | V14: N
B15: N5 | G15: Bull3_Dung_Filtered2_1st_1.2µm.kp | P15: =25-4-4 -> 17 | V15: N
B16: N6 | G16: Bull3_Dung_Filtered2_1st_0.22µm | P16: =25-4-4 -> 17 | V16: N
B17: N7 | G17: Bull3_Dung_Filtered2_1st_filtrate | P17: =25-4-4 -> 17 | V17: N
B18: N(-) | G18: - | N18: 17.05 | O18: - | P18: =25-4-4 -> 17 | V18: N
B19: B1 | C19: Bacteria | D19: 27F | E19: 337R | F19: 210 (?) | G19: Bull3_Dung_Filtered2_1st_TS | H19: 2.5 | I19: 2.5 | J19: 2.5 | K19: 0.15 | L19: 0.15 | M19: 0.15 | N19: 15.05 | O19: 2 | P19: =25-4-4 -> 17 | Q19: 94°C for 1min | R19: 94°C for 30s | S19: 47°C for 30s | T19: 72°C for 30s | U19: 72°C for 7min | V19: N
B20: B2 | G20: Bull3_Dung_Filtered2_1st_FF | P20: =25-4-4 -> 17 | V20: N
B21: B3 | G21: Bull3_Dung_Filtered2_1st_100µm.kp | P21: =25-4-4 -> 17 | V21: Y
B22: B4 | G22: Bull3_Dung_Filtered2_1st_8.0µm | P22: =25-4-4 -> 17 | V22: N
B23: B5 | G23: Bull3_Dung_Filtered2_1st_1.2µm.kp | P23: =25-4-4 -> 17 | V23: Y
B24: B6 | G24: Bull3_Dung_Filtered2_1st_0.22µm | P24: =25-4-4 -> 17 | V24: N
B25: B7 | G25: Bull3_Dung_Filtered2_1st_filtrate | P25: =25-4-4 -> 17 | V25: Y
B26: B(-) | G26: - | N26: 17.05 | O26: - | P26: =25-4-4 -> 17 | V26: Y
B27: F1 | C27: Fungi | D27: ITS1 (1761-1779) | E27: ITS4 (2390-2409) | F27: 648 (?) | G27: Bull3_Dung_Filtered2_1st_TS | H27: 2.5 | I27: 2.5 | J27: 2.5 | K27: 0.15 | L27: 0.15 | M27: 0.15 | N27: 15.05 | O27: 2 | P27: =25-4-4 -> 17 | Q27: 94°C for 1min | R27: 94°C for 30s | S27: 47°C for 30s | T27: 72°C for 30s | U27: 72°C for 7min | V27: N | W27: 1.5% gel @ 100V for 15min
B28: F2 | G28: Bull3_Dung_Filtered2_1st_FF | P28: =25-4-4 -> 17 | V28: N
B29: F3 | G29: Bull3_Dung_Filtered2_1st_100µm.kp | P29: =25-4-4 -> 17 | V29: N
B30: F4 | G30: Bull3_Dung_Filtered2_1st_8.0µm | P30: =25-4-4 -> 17 | V30: N
B31: F5 | G31: Bull3_Dung_Filtered2_1st_1.2µm.kp | P31: =25-4-4 -> 17 | V31: N
B32: F6 | G32: Bull3_Dung_Filtered2_1st_0.22µm | P32: =25-4-4 -> 17 | V32: N
B33: F7 | G33: Bull3_Dung_Filtered2_1st_filtrate | P33: =25-4-4 -> 17 | V33: N
B34: F(-) | G34: - | N34: 17.05 | O34: - | P34: =25-4-4 -> 17 | V34: N
B35: F(+) | G35: Sample received from Markus | N35: 15.05 | O35: 2 | P35: =25-4-4 -> 17 | V35: N
B36: V1 | C36: Vertebrates | D36: vertU V16S-U F | E36: vertU V16S-U R | F36: ??? | G36: Bull3_Dung_Filtered2_1st_TS | H36: 2.5 | I36: 2.5 | J36: 2.5 | K36: 0.15 | L36: 0.15 | M36: 0.15 | N36: 15.05 | O36: 2 | P36: =25-4-4 -> 17 | Q36: 94°C for 1min | R36: 94°C for 30s | S36: 47°C for 30s | T36: 72°C for 30s | U36: 72°C for 7min | V36: N
B37: V2 | G37: Bull3_Dung_Filtered2_1st_FF | P37: =25-4-4 -> 17 | V37: N
B38: V3 | G38: Bull3_Dung_Filtered2_1st_100µm.kp | P38: =25-4-4 -> 17 | V38: Y
B39: V4 | G39: Bull3_Dung_Filtered2_1st_8.0µm | P39: =25-4-4 -> 17 | V39: N
B40: V5 | G40: Bull3_Dung_Filtered2_1st_1.2µm.kp | P40: =25-4-4 -> 17 | V40: N
B41: V6 | G41: Bull3_Dung_Filtered2_1st_0.22µm | P41: =25-4-4 -> 17 | V41: N
...
